Workbook

Sheet Summary
A2: 2138 & 2026 Order Summary
A3: Particulars | B3: No Of items in bom | C3: Remarks
A4: ASSY | B4: =COUNTIF(AVL!#REF!,Summary!A4) -> #REF! | C4: Assy line
A5: DNP | B5: =COUNTIF(AVL!#REF!,Summary!A5) -> #REF! | C5: Do Not Purchase
A6: BFE | B6: =COUNTIF(AVL!#REF!,Summary!A6) -> #REF! | C6: Elta supply parts | D6: Yes | E6: No | H6: Yet to share the delivery dates
A7: Duplicate | B7: =COUNTIF(AVL!#REF!,Summary!A7) -> #REF! | C7: 2 lines merged to 1 line | D7: DD Available | E7: DD yet to receive | F7: Suppliers | G7: No of Items | H7: Remarks
A8: Ordered | B8: =COUNTIF(AVL!#REF!,Summary!A8) -> #REF! | C8: Ordered, Need to followup for the delivery dates | D8: =COUNTIFS(AVL!#REF!,Summary!D6) -> #REF! | E8: =B8-D8 -> #REF! | F8: Aran | G8: 2
A9: Production consumables | B9: =COUNTIF(AVL!#REF!,Summary!A9) -> #REF! | C9: Ordered | G9: =COUNTIFS(AVL!#REF!,Summary!$E$6,AVL!X:X,Summary!F9) -> #REF!
A10: Ordered-DNP | B10: =COUNTIF(AVL!#REF!,Summary!A10) -> #REF! | C10: Due to design change made DNP | F10: Total | G10: =SUM(G8:G9) -> #REF!
A11: Ordered-Clarification | B11: =COUNTIF(AVL!#REF!,Summary!A11) -> #REF! | C11: Gopalan
A12: Ordered-EUS | B12: =COUNTIF(AVL!#REF!,Summary!A12) -> #REF! | C12: RFMW
A13: BFE-Clarification | B13: =COUNTIF(AVL!#REF!,Summary!A13) -> #REF! | C13: 6931A550-001
A14: Total line items | B14: =SUM(B4:B13) -> #REF!
A27: Supplier | B27: No of Items | C27: Remarks | D27: PO Value Amt in USD | E27: Leadtime in weeks | F27: Required Payment | G27: Curr
A28: ASSY | B28: =COUNTIFS(AVL!X:X,Summary!A28) -> 18 | D28: =SUMIFS(AVL!#REF!,AVL!X:X,Summary!A28) -> #REF! | E28: =_xlfn.MAXIFS(AVL!#REF!,AVL!X:X,Summary!A28) -> #REF!
A29: Star Light/Huang Ling | B29: =COUNTIFS(AVL!X:X,Summary!A29) -> 10 | C29: Payment | D29: =SUMIFS(AVL!#REF!,AVL!X:X,Summary!A29) -> #REF! | E29: =_xlfn.MAXIFS(AVL!#REF!,AVL!X:X,Summary!A29) -> #REF! | F29: 168214.83 | G29: USD
A30: YAEL Y.A.D | B30: =COUNTIFS(AVL!X:X,Summary!A30) -> 1 | C30: Payment | D30: =SUMIFS(AVL!#REF!,AVL!X:X,Summary!A30) -> #REF! | E30: =_xlfn.MAXIFS(AVL!#REF!,AVL!X:X,Summary!A30) -> #REF! | F30: =D30 -> #REF! | G30: USD
A31: Phoenix | B31: =COUNTIFS(AVL!X:X,Summary!A31) -> 7 | D31: =SUMIFS(AVL!#REF!,AVL!X:X,Summary!A31) -> #REF! | E31: =_xlfn.MAXIFS(AVL!#REF!,AVL!X:X,Summary!A31) -> #REF!
A32: Rabyte Technologies LLP | B32: =COUNTIFS(AVL!X:X,Summary!A32) -> 4 | D32: =SUMIFS(AVL!#REF!,AVL!X:X,Summary!A32) -> #REF! | E32: =_xlfn.MAXIFS(AVL!#REF!,AVL!X:X,Summary!A32) -> #REF!
A33: TTI | B33: =COUNTIFS(AVL!X:X,Summary!A33) -> 0 | C33: Payment | D33: =SUMIFS(AVL!#REF!,AVL!X:X,Summary!A33) -> #REF! | E33: =_xlfn.MAXIFS(AVL!#REF!,AVL!X:X,Summary!A33) -> #REF! | F33: =D33 -> #REF! | G33: USD
A34: Consumables | B34: =COUNTIFS(AVL!X:X,Summary!A34) -> 5 | D34: =SUMIFS(AVL!#REF!,AVL!X:X,Summary!A34) -> #REF! | E34: =_xlfn.MAXIFS(AVL!#REF!,AVL!X:X,Summary!A34) -> #REF!
A35: Kaytech | B35: =COUNTIFS(AVL!X:X,Summary!A35) -> 87 | C35: Payment | D35: =SUMIFS(AVL!#REF!,AVL!X:X,Summary!A35) -> #REF! | E35: =_xlfn.MAXIFS(AVL!#REF!,AVL!X:X,Summary!A35) -> #REF! | F35: =D35 -> #REF! | G35: USD
A36: AMPHENOL Canada | B36: =COUNTIFS(AVL!X:X,Summary!A36) -> 1 | C36: Payment | D36: =SUMIFS(AVL!#REF!,AVL!X:X,Summary!A36) -> #REF! | E36: =_xlfn.MAXIFS(AVL!#REF!,AVL!X:X,Summary!A36) -> #REF! | F36: =D36 -> #REF! | G36: USD
A37: Agoran | B37: =COUNTIFS(AVL!X:X,Summary!A37) -> 1 | D37: =SUMIFS(AVL!#REF!,AVL!X:X,Summary!A37) -> #REF! | E37: =_xlfn.MAXIFS(AVL!#REF!,AVL!X:X,Summary!A37) -> #REF!
A38: DNP | B38: =COUNTIFS(AVL!X:X,Summary!A38) -> 35 | D38: =SUMIFS(AVL!#REF!,AVL!X:X,Summary!A38) -> #REF! | E38: =_xlfn.MAXIFS(AVL!#REF!,AVL!X:X,Summary!A38) -> #REF!
A39: Ackerman | B39: =COUNTIFS(AVL!X:X,Summary!A39) -> 22 | D39: =SUMIFS(AVL!#REF!,AVL!X:X,Summary!A39) -> #REF! | E39: =_xlfn.MAXIFS(AVL!#REF!,AVL!X:X,Summary!A39) -> #REF!
A40: TBD | B40: =COUNTIFS(AVL!X:X,Summary!A40) -> 0 | D40: =SUMIFS(AVL!#REF!,AVL!X:X,Summary!A40) -> #REF! | E40: =_xlfn.MAXIFS(AVL!#REF!,AVL!X:X,Summary!A40) -> #REF!
A41: Wave Mechanics | B41: =COUNTIFS(AVL!X:X,Summary!A41) -> 30 | D41: =SUMIFS(AVL!#REF!,AVL!X:X,Summary!A41) -> #REF! | E41: =_xlfn.MAXIFS(AVL!#REF!,AVL!X:X,Summary!A41) -> #REF!
A42: Simat | B42: =COUNTIFS(AVL!X:X,Summary!A42) -> 0 | C42: Payment | D42: =SUMIFS(AVL!#REF!,AVL!X:X,Summary!A42) -> #REF! | E42: =_xlfn.MAXIFS(AVL!#REF!,AVL!X:X,Summary!A42) -> #REF! | F42: =D42 -> #REF! | G42: USD
A43: REMTEC | B43: =COUNTIFS(AVL!X:X,Summary!A43) -> 1 | C43: Payment | D43: =SUMIFS(AVL!#REF!,AVL!X:X,Summary!A43) -> #REF! | E43: =_xlfn.MAXIFS(AVL!#REF!,AVL!X:X,Summary!A43) -> #REF! | F43: 71908.4 | G43: USD
A44: Chemograf | B44: =COUNTIFS(AVL!X:X,Summary!A44) -> 2 | D44: =SUMIFS(AVL!#REF!,AVL!X:X,Summary!A44) -> #REF! | E44: =_xlfn.MAXIFS(AVL!#REF!,AVL!X:X,Summary!A44) -> #REF!
A45: BFE | B45: =COUNTIFS(AVL!X:X,Summary!A45) -> 13 | D45: =SUMIFS(AVL!#REF!,AVL!X:X,Summary!A45) -> #REF! | E45: =_xlfn.MAXIFS(AVL!#REF!,AVL!X:X,Summary!A45) -> #REF!
A46: Gumiyan | B46: =COUNTIFS(AVL!X:X,Summary!A46) -> 10 | D46: =SUMIFS(AVL!#REF!,AVL!X:X,Summary!A46) -> #REF! | E46: =_xlfn.MAXIFS(AVL!#REF!,AVL!X:X,Summary!A46) -> #REF!
A47: Boardtek | B47: =COUNTIFS(AVL!X:X,Summary!A47) -> 0 | D47: =SUMIFS(AVL!#REF!,AVL!X:X,Summary!A47) -> #REF! | E47: =_xlfn.MAXIFS(AVL!#REF!,AVL!X:X,Summary!A47) -> #REF!
A48: Ascotech | B48: =COUNTIFS(AVL!X:X,Summary!A48) -> 3 | D48: =SUMIFS(AVL!#REF!,AVL!X:X,Summary!A48) -> #REF! | E48: =_xlfn.MAXIFS(AVL!#REF!,AVL!X:X,Summary!A48) -> #REF!
A49: DCX | B49: =COUNTIFS(AVL!X:X,Summary!A49) -> 9 | D49: =SUMIFS(AVL!#REF!,AVL!X:X,Summary!A49) -> #REF! | E49: =_xlfn.MAXIFS(AVL!#REF!,AVL!X:X,Summary!A49) -> #REF!
A50: DCX Chol | B50: =COUNTIFS(AVL!X:X,Summary!A50) -> 1 | D50: =SUMIFS(AVL!#REF!,AVL!X:X,Summary!A50) -> #REF! | E50: =_xlfn.MAXIFS(AVL!#REF!,AVL!X:X,Summary!A50) -> #REF!
A51: Elbatech | B51: =COUNTIFS(AVL!X:X,Summary!A51) -> 16 | D51: =SUMIFS(AVL!#REF!,AVL!X:X,Summary!A51) -> #REF! | E51: =_xlfn.MAXIFS(AVL!#REF!,AVL!X:X,Summary!A51) -> #REF!
A52: Star Light | B52: =COUNTIFS(AVL!X:X,Summary!A52) -> 0 | D52: =SUMIFS(AVL!#REF!,AVL!X:X,Summary!A52) -> #REF! | E52: =_xlfn.MAXIFS(AVL!#REF!,AVL!X:X,Summary!A52) -> #REF!
A53: Pronat | B53: =COUNTIFS(AVL!X:X,Summary!A53) -> 11 | C53: Payment | D53: =SUMIFS(AVL!#REF!,AVL!X:X,Summary!A53) -> #REF! | E53: =_xlfn.MAXIFS(AVL!#REF!,AVL!X:X,Summary!A53) -> #REF! | F53: 21884.2 | G53: USD
...

Sheet Sheet3
A1: Row Labels | B1: Sum of Open PO value
A2: A. M. Designs Pvt. Ltd.
A3: A.M. COMPONENTS (2005) LTD
A4: Ackerman Printing
A5: ACKERMAN Printing & Photoanodize LTD | B5: 480
A6: ADVANCED ELECTROMAGNETICS INC
A7: AGAM Technology | B7: 94080
A8: Agoran Ltd
A9: Air Electro, Inc. | B9: 6.8
A10: Alcoats
A11: Amar Radio
A12: AMPHENOL CANADA
A13: Andre Machining LTD
A14: Aqua Engineering Services
A15: Aran Research, Development and Models Ltd
A16: ARROW RAPAC LTD
A17: Ascotech Electronics Ltd | B17: 162279 | C17: s
A18: Aspocomp Group Plc | B18: 295517.2 | C18: s
A19: Astute Electronics Inc.
A20: Atagasthya Packaging Pvt Ltd | B20: 6877.48
A21: Avdor Technology Ltd.
A22: Avnet Asia Pte. Ltd.
A23: Avnet ASIC | B23: 5356360
A24: Caravan Oil Suppliers
A25: Chemograf LTD
A26: CIDEV GROUP LTD
A27: DCX | B27: 242452.93
A28: DCX-CHOL
A29: Digikey
A30: Divyanshi Aviation Services Pvt. Ltd
A31: EBV Elektronik Israel (2008) LTD
A32: Ecomal Israel Ltd.
A33: EIM Systems and Components (1999) Ltd. | B33: 49619 | C33: s
A34: Elbatech ltd | B34: 95909.4 | C34: s
A35: Elbatech ltd. | B35: 4297403.2 | C35: s
A36: Electro Enterprises New York LLC
A37: Elipse Engineering | B37: 5169440
A38: Fastener Technology Corp.
A39: FED-SPECS
A40: Future Electronics
...

Sheet AVL
BG1: project plan | CM1: demand
A3: S
A4: 4 | Z4: 4 | BD4: ANTENNA 2026 F\Assy | BE4: 0 | BF4: 6931A105-001 | BK4: 8 | BL4: 8 | BM4: 8 | BN4: 8 | BO4: 8 | BP4: 8 | BQ4: 8 | BR4: 8 | BS4: 8 | BT4: 8 | BU4: 8 | BV4: 8 | BW4: 6 | CJ4: ANTENNA 2026 F\Assy | CK4: 0 | CL4: 6931A105-001 | CQ4: =BK4 -> 8 | CR4: =BL4 -> 8 | CS4: =BM4 -> 8 | CT4: =BN4 -> 8 | CU4: =BO4 -> 8 | CV4: =BP4 -> 8 | CW4: =BQ4 -> 8 | CX4: =BR4 -> 8 | ... DO4: =CI4 -> 0
A5: 4 | BD5: FAN UNIT | BE5: 1 | BF5: 6931A450-001 | BK5: 8 | BL5: 8 | BM5: 8 | BN5: 8 | BO5: 8 | BP5: 8 | BQ5: 8 | BR5: 8 | BS5: 8 | BT5: 8 | BU5: 8 | BV5: 8 | BW5: 6 | CJ5: FAN UNIT | CK5: 1 | CL5: 6931A450-001 | CQ5: =BK5 -> 8 | CR5: =BL5 -> 8 | CS5: =BM5 -> 8 | CT5: =BN5 -> 8 | CU5: =BO5 -> 8 | CV5: =BP5 -> 8 | CW5: =BQ5 -> 8 | CX5: =BR5 -> 8 | ... DO5: =CI5 -> 0
A6: 4 | BD6: SMR GROUP LEFT | BE6: 1 | BF6: 6931A080-001 | BK6: 8 | BL6: 8 | BM6: 8 | BN6: 8 | BO6: 8 | BP6: 8 | BQ6: 8 | BR6: 8 | BS6: 8 | BT6: 8 | BU6: 8 | BV6: 8 | BW6: 6 | CJ6: SMR GROUP LEFT | CK6: 1 | CL6: 6931A080-001 | CQ6: =BK6 -> 8 | CR6: =BL6 -> 8 | CS6: =BM6 -> 8 | CT6: =BN6 -> 8 | CU6: =BO6 -> 8 | CV6: =BP6 -> 8 | CW6: =BQ6 -> 8 | CX6: =BR6 -> 8 | ... DO6: =CI6 -> 0
A7: 8 | BD7: RF ADAPTOR F\ASSY | BE7: 2 | BF7: 1094Y690-001 | BK7: 8 | BL7: 8 | BM7: 8 | BN7: 8 | BO7: 8 | BP7: 8 | BQ7: 8 | BR7: 8 | BS7: 8 | BT7: 8 | BU7: 8 | BV7: 8 | BW7: 6 | CJ7: RF ADAPTOR F\ASSY | CK7: 2 | CL7: 1094Y690-001 | CQ7: =BK7 -> 8 | CR7: =BL7 -> 8 | CS7: =BM7 -> 8 | CT7: =BN7 -> 8 | CU7: =BO7 -> 8 | CV7: =BP7 -> 8 | CW7: =BQ7 -> 8 | CX7: =BR7 -> 8 | ... DO7: =CI7 -> 0
A8: 4 | BD8: SMR GROUP RIGHT | BE8: 1 | BF8: 6931A090-001 | BK8: 8 | BL8: 8 | BM8: 8 | BN8: 8 | BO8: 8 | BP8: 8 | BQ8: 8 | BR8: 8 | BS8: 8 | BT8: 8 | BU8: 8 | BV8: 8 | BW8: 6 | CJ8: SMR GROUP RIGHT | CK8: 1 | CL8: 6931A090-001 | CQ8: =BK8 -> 8 | CR8: =BL8 -> 8 | CS8: =BM8 -> 8 | CT8: =BN8 -> 8 | CU8: =BO8 -> 8 | CV8: =BP8 -> 8 | CW8: =BQ8 -> 8 | CX8: =BR8 -> 8 | ... DO8: =CI8 -> 0
A9: 8 | BD9: RF ADAPTOR F\ASSY | BE9: 2 | BF9: 1094Y690-001 | BK9: 8 | BL9: 8 | BM9: 8 | BN9: 8 | BO9: 8 | BP9: 8 | BQ9: 8 | BR9: 8 | BS9: 8 | BT9: 8 | BU9: 8 | BV9: 8 | BW9: 6 | CJ9: RF ADAPTOR F\ASSY | CK9: 2 | CL9: 1094Y690-001 | CQ9: =BK9 -> 8 | CR9: =BL9 -> 8 | CS9: =BM9 -> 8 | CT9: =BN9 -> 8 | CU9: =BO9 -> 8 | CV9: =BP9 -> 8 | CW9: =BQ9 -> 8 | CX9: =BR9 -> 8 | ... DO9: =CI9 -> 0
A10: 4 | BD10: 2026 ANTENNA CONTROLLER | BE10: 2 | BF10: 6931A200-001 | BK10: 8 | BL10: 8 | BM10: 8 | BN10: 8 | BO10: 8 | BP10: 8 | BQ10: 8 | BR10: 8 | BS10: 8 | BT10: 8 | BU10: 8 | BV10: 8 | BW10: 14 | CJ10: 2026 ANTENNA CONTROLLER | CK10: 2 | CL10: 6931A200-001 | CQ10: =BK10 -> 8 | CR10: =BL10 -> 8 | CS10: =BM10 -> 8 | CT10: =BN10 -> 8 | CU10: =BO10 -> 8 | CV10: =BP10 -> 8 | CW10: =BQ10 -> 8 | CX10: =BR10 -> 8 | ... DO10: =CI10 -> 0
BD11: Antenna F\Assy | BE11: 0 | BF11: 1038B800-001 | BK11: 16 | BL11: 16 | BM11: 16 | BN11: 16 | BO11: 8 | BP11: 8 | BQ11: 8 | BR11: 8 | BS11: 8 | BT11: 8 | BU11: 8 | BV11: 8 | CJ11: Antenna F\Assy | CK11: 0 | CL11: 1038B800-001 | CQ11: =BK11 -> 16 | CR11: =BL11 -> 16 | CS11: =BM11 -> 16 | CT11: =BN11 -> 16 | CU11: =BO11 -> 8 | CV11: =BP11 -> 8 | CW11: =BQ11 -> 8 | CX11: =BR11 -> 8 | ... DO11: =CI11 -> 0
Z12: 10 | BD12: TRA F\ASSY | BE12: 1 | BF12: 1038B900-001 | BK12: 35 | BL12: 35 | BM12: 35 | BN12: 30 | BO12: 30 | BP12: 30 | BQ12: 30 | BR12: 30 | BS12: 30 | BT12: 30 | BU12: 30 | BV12: 14 | CJ12: TRA F\ASSY | CK12: 1 | CL12: 1038B900-001 | CQ12: =BK12 -> 35 | CR12: =BL12 -> 35 | CS12: =BM12 -> 35 | CT12: =BN12 -> 30 | CU12: =BO12 -> 30 | CV12: =BP12 -> 30 | CW12: =BQ12 -> 30 | CX12: =BR12 -> 30 | ... DO12: =CI12 -> 0
BD13: TRA S\ASSY | BE13: 2 | BF13: 1096M291-001 | BK13: 35 | BL13: 35 | BM13: 35 | BN13: 30 | BO13: 30 | BP13: 30 | BQ13: 30 | BR13: 30 | BS13: 30 | BT13: 30 | BU13: 30 | BV13: 14 | CJ13: TRA S\ASSY | CK13: 2 | CL13: 1096M291-001 | CQ13: =BK13 -> 35 | CR13: =BL13 -> 35 | CS13: =BM13 -> 35 | CT13: =BN13 -> 30 | CU13: =BO13 -> 30 | CV13: =BP13 -> 30 | CW13: =BQ13 -> 30 | CX13: =BR13 -> 30 | ... DO13: =CI13 -> 0
BD14: TRA PC ASSY | BE14: 3 | BF14: 1096M290-001 | BK14: 35 | BL14: 35 | BM14: 35 | BN14: 30 | BO14: 30 | BP14: 30 | BQ14: 30 | BR14: 30 | BS14: 30 | BT14: 30 | BU14: 30 | BV14: 14 | CJ14: TRA PC ASSY | CK14: 3 | CL14: 1096M290-001 | CQ14: =BK14 -> 35 | CR14: =BL14 -> 35 | CS14: =BM14 -> 35 | CT14: =BN14 -> 30 | CU14: =BO14 -> 30 | CV14: =BP14 -> 30 | CW14: =BQ14 -> 30 | CX14: =BR14 -> 30 | ... DO14: =CI14 -> 0
BD15: ANTENNA CONTROLLER PC/ASSY TRA | BE15: 3 | BF15: 1039H771-001 | BK15: 35 | BL15: 35 | BM15: 35 | BN15: 35 | BO15: 35 | BP15: 35 | BQ15: 35 | BR15: 35 | BS15: 35 | BT15: 35 | CJ15: ANTENNA CONTROLLER PC/ASSY TRA | CK15: 3 | CL15: 1039H771-001 | CQ15: =BK15 -> 35 | CR15: =BL15 -> 35 | CS15: =BM15 -> 35 | CT15: =BN15 -> 35 | CU15: =BO15 -> 35 | CV15: =BP15 -> 35 | CW15: =BQ15 -> 35 | CX15: =BR15 -> 35 | ... DO15: =CI15 -> 0
BD16: RA F\ASSY | BE16: 1 | BF16: 1038B930-001 | BK16: 43 | BL16: 35 | BM16: 30 | BN16: 30 | BO16: 30 | BP16: 30 | BQ16: 30 | BR16: 30 | BS16: 30 | BT16: 30 | BU16: 30 | CJ16: RA F\ASSY | CK16: 1 | CL16: 1038B930-001 | CQ16: =BK16 -> 43 | CR16: =BL16 -> 35 | CS16: =BM16 -> 30 | CT16: =BN16 -> 30 | CU16: =BO16 -> 30 | CV16: =BP16 -> 30 | CW16: =BQ16 -> 30 | CX16: =BR16 -> 30 | ... DO16: =CI16 -> 0
BD17: RA S\ASSY | BE17: 2 | BF17: 1096M281-001 | BK17: 43 | BL17: 35 | BM17: 30 | BN17: 30 | BO17: 30 | BP17: 30 | BQ17: 30 | BR17: 30 | BS17: 30 | BT17: 30 | BU17: 30 | CJ17: RA S\ASSY | CK17: 2 | CL17: 1096M281-001 | CQ17: =BK17 -> 43 | CR17: =BL17 -> 35 | CS17: =BM17 -> 30 | CT17: =BN17 -> 30 | CU17: =BO17 -> 30 | CV17: =BP17 -> 30 | CW17: =BQ17 -> 30 | CX17: =BR17 -> 30 | ... DO17: =CI17 -> 0
BD18: RA PC ASSY | BE18: 3 | BF18: 1096M280-001 | BK18: 43 | BL18: 35 | BM18: 30 | BN18: 30 | BO18: 30 | BP18: 30 | BQ18: 30 | BR18: 30 | BS18: 30 | BT18: 30 | BU18: 30 | CJ18: RA PC ASSY | CK18: 3 | CL18: 1096M280-001 | CQ18: =BK18 -> 43 | CR18: =BL18 -> 35 | CS18: =BM18 -> 30 | CT18: =BN18 -> 30 | CU18: =BO18 -> 30 | CV18: =BP18 -> 30 | CW18: =BQ18 -> 30 | CX18: =BR18 -> 30 | ... DO18: =CI18 -> 0
G19: ANTENNA 2026 F\Assy | H19: FAN UNIT | I19: SMR GROUP LEFT | J19: RF ADAPTOR F\ASSY | K19: SMR GROUP RIGHT | L19: RF ADAPTOR F\ASSY | M19: 2026 ANTENNA CONTROLLER | N19: Antenna F\Assy | O19: TRA F\ASSY | P19: TRA S\ASSY | Q19: TRA PC ASSY | R19: ANTENNA CONTROLLER PC/ASSY TRA | S19: RA F\ASSY | T19: RA S\ASSY | U19: RA PC ASSY | V19: ANTENNA CONTROLLER PC/ASSY TRA | W19: PLANNAR | AA19: eta | BD19: ANTENNA CONTROLLER PC/ASSY RA | BE19: 3 | BF19: 1039H771-001 | BK19: 35 | BL19: 35 | BM19: 35 | BN19: 35 | BO19: 35 | BP19: 35 | BQ19: 35 | BR19: 35 | BS19: 35 | CJ19: ANTENNA CONTROLLER PC/ASSY RA | CK19: 3 | CL19: 1039H771-001 | CQ19: =BK19 -> 35 | CR19: =BL19 -> 35 | CS19: =BM19 -> 35 | CT19: =BN19 -> 35 | CU19: =BO19 -> 35 | CV19: =BP19 -> 35 | CW19: =BQ19 -> 35 | CX19: =BR19 -> 35 | ... DO19: =CI19 -> 0
G20: 0 | H20: 1 | I20: 1 | J20: 2 | K20: 1 | L20: 2 | M20: 2 | N20: 0 | O20: 1 | P20: 2 | Q20: 3 | R20: 3 | S20: 1 | T20: 2 | U20: 3 | V20: 3 | W20: 0 | BD20: PLANNAR | BE20: 0 | BF20: 1038B850-001 | BK20: 16 | BL20: 16 | BM20: 16 | BN20: 16 | BO20: 16 | BP20: 16 | BQ20: 16 | BR20: 16 | CJ20: PLANNAR | CK20: 0 | CL20: 1038B850-001 | CQ20: =BK20 -> 16 | CR20: =BL20 -> 16 | CS20: =BM20 -> 16 | CT20: =BN20 -> 16 | CU20: =BO20 -> 16 | CV20: =BP20 -> 16 | CW20: =BQ20 -> 16 | CX20: =BR20 -> 16 | ... DO20: =CI20 -> 0
A21: # | B21: PN_ID | C21: CATALOG | D21: DESCRIPTION | E21: UOM | F21: SUG_MLAI | G21: 6931A105-001 | H21: 6931A450-001 | I21: 6931A080-001 | J21: 1094Y690-001 | K21: 6931A090-001 | L21: 1094Y690-001 | M21: 6931A200-001 | N21: 1038B800-001 | O21: 1038B900-001 | P21: 1096M291-001 | Q21: 1096M290-001 | R21: 1039H771-001 | S21: 1038B930-001 | T21: 1096M281-001 | U21: 1096M280-001 | V21: 1039H771-001 | W21: 1038B850-001 | X21: ספק | Y21: PRICE | Z21: STOCK | AA21: 46113 | AB21: 46143 | AC21: 46174 | AD21: 46204 | AE21: 46235 | AF21: 46266 | AG21: 46296 | AH21: 46327 | AI21: 46357 | AJ21: 46388 | AK21: 46419 | AL21: 46447 | AM21: 46478 | AN21: 46508 | AO21: 46539 | AP21: 46569 | AQ21: 46600 | AR21: 46631 | AS21: 46661 | AT21: 46692 | AU21: 46722 | AV21: 46753 | AW21: 46784 | AX21: 46813 | AY21: 46844 | AZ21: 46874 | BA21: 46905 | BB21: 46935 | BC21: 46966 | BD21: Description | BE21: Level | BF21: PN | BG21: 46113 | BH21: 46143 | BI21: 46174 | BJ21: 46204 | BK21: 46235 | BL21: 46266 | BM21: 46296 | BN21: 46327 | BO21: 46357 | BP21: 46388 | BQ21: 46419 | BR21: 46447 | BS21: 46478 | BT21: 46508 | BU21: 46539 | BV21: 46569 | BW21: 46600 | BX21: 46631 | BY21: 46661 | BZ21: 46692 | CA21: 46722 | CB21: 46753 | CC21: 46784 | CD21: 46813 | CE21: 46844 | CF21: 46874 | CG21: 46905 | CH21: 46935 | CI21: 46966 | CJ21: Description | CK21: Level | CL21: PN | CM21: 46113 | CN21: 46143 | CO21: 46174 | CP21: 46204 | CQ21: 46235 | CR21: 46266 | CS21: 46296 | CT21: 46327 | CU21: 46357 | CV21: 46388 | CW21: 46419 | CX21: 46447 | CY21: 46478 | CZ21: 46508 | DA21: 46539 | DB21: 46569 | DC21: 46600 | DD21: 46631 | DE21: 46661 | DF21: 46692 | DG21: 46722 | DH21: 46753 | DI21: 46784 | DJ21: 46813 | DK21: 46844 | DL21: 46874 | DM21: 46905 | DN21: 46935 | DO21: 46966
A22: 1 | B22: 1038B800-001 | C22: 410883564 | D22: ANTENNA F/ASSY | E22: EA | F22: 1 | G22: 0 | H22: 0 | I22: 0 | J22: 0 | K22: 0 | L22: 0 | M22: 0 | N22: 1 | O22: 0 | P22: 0 | Q22: 0 | R22: 0 | S22: 0 | T22: 0 | U22: 0 | V22: 0 | W22: 0 | X22: ASSY | Y22: 0 | Z22: 0 | AA22: 0 | AB22: 0 | AC22: 0 | AD22: 0 | AE22: 0 | AF22: 0 | AG22: 0 | AH22: 0 | AI22: 0 | AJ22: 0 | AK22: 0 | AL22: 0 | AM22: 0 | AN22: 0 | BK22: =SUM($Z22:AD22)-SUM($CM22:CQ22) -> -16 | BL22: =SUM($Z22:AE22)-SUM($CM22:CR22) -> -32 | BM22: =SUM($Z22:AF22)-SUM($CM22:CS22) -> -48 | BN22: =SUM($Z22:AG22)-SUM($CM22:CT22) -> -64 | BO22: =SUM($Z22:AH22)-SUM($CM22:CU22) -> -72 | BP22: =SUM($Z22:AI22)-SUM($CM22:CV22) -> -80 | BQ22: =SUM($Z22:AJ22)-SUM($CM22:CW22) -> -88 | BR22: =SUM($Z22:AK22)-SUM($CM22:CX22) -> -96 | ... CI22: =SUM($Z22:BB22)-SUM($CM22:DO22) -> -128 | CN22: {=SUMPRODUCT(TRANSPOSE(CN$4:CN$20),$G22:$W22)} -> 0 | CO22: {=SUMPRODUCT(TRANSPOSE(CO$4:CO$20),$G22:$W22)} -> 0 | CP22: {=SUMPRODUCT(TRANSPOSE(CP$4:CP$20),$G22:$W22)} -> 0 | CQ22: {=SUMPRODUCT(TRANSPOSE(CQ$4:CQ$20),$G22:$W22)} -> 16 | CR22: {=SUMPRODUCT(TRANSPOSE(CR$4:CR$20),$G22:$W22)} -> 16 | CS22: {=SUMPRODUCT(TRANSPOSE(CS$4:CS$20),$G22:$W22)} -> 16 | CT22: {=SUMPRODUCT(TRANSPOSE(CT$4:CT$20),$G22:$W22)} -> 16 | CU22: {=SUMPRODUCT(TRANSPOSE(CU$4:CU$20),$G22:$W22)} -> 8 | ... DO22: {=SUMPRODUCT(TRANSPOSE(DO$4:DO$20),$G22:$W22)} -> 0
A23: =A22+1 -> 2 | B23: 01M110-712-60F02M | C23: 418493430 | D23: CBL ASSY COAX SMA(M)-BMA(F) L=712MM | E23: EA | F23: 1 | G23: 0 | H23: 0 | I23: 0 | J23: 0 | K23: 0 | L23: 0 | M23: 0 | N23: 0 | O23: 0 | P23: 0 | Q23: 0 | R23: 0 | S23: 0 | T23: 0 | U23: 0 | V23: 0 | W23: 1 | X23: Star Light/Huang Ling | Y23: 41.1 | Z23: 231 | AA23: 0 | AB23: 0 | AC23: 0 | AD23: 0 | AE23: 0 | AF23: 0 | AG23: 0 | AH23: 0 | AI23: 0 | AJ23: 0 | AK23: 0 | AL23: 0 | AM23: 0 | AN23: 0 | BK23: =SUM($Z23:AD23)-SUM($CM23:CQ23) -> 215 | BL23: =SUM($Z23:AE23)-SUM($CM23:CR23) -> 199 | BM23: =SUM($Z23:AF23)-SUM($CM23:CS23) -> 183 | BN23: =SUM($Z23:AG23)-SUM($CM23:CT23) -> 167 | BO23: =SUM($Z23:AH23)-SUM($CM23:CU23) -> 151 | BP23: =SUM($Z23:AI23)-SUM($CM23:CV23) -> 135 | BQ23: =SUM($Z23:AJ23)-SUM($CM23:CW23) -> 119 | BR23: =SUM($Z23:AK23)-SUM($CM23:CX23) -> 103 | ... CI23: =SUM($Z23:BB23)-SUM($CM23:DO23) -> 103 | CN23: {=SUMPRODUCT(TRANSPOSE(CN$4:CN$20),$G23:$W23)} -> 0 | CO23: {=SUMPRODUCT(TRANSPOSE(CO$4:CO$20),$G23:$W23)} -> 0 | CP23: {=SUMPRODUCT(TRANSPOSE(CP$4:CP$20),$G23:$W23)} -> 0 | CQ23: {=SUMPRODUCT(TRANSPOSE(CQ$4:CQ$20),$G23:$W23)} -> 16 | CR23: {=SUMPRODUCT(TRANSPOSE(CR$4:CR$20),$G23:$W23)} -> 16 | CS23: {=SUMPRODUCT(TRANSPOSE(CS$4:CS$20),$G23:$W23)} -> 16 | CT23: {=SUMPRODUCT(TRANSPOSE(CT$4:CT$20),$G23:$W23)} -> 16 | CU23: {=SUMPRODUCT(TRANSPOSE(CU$4:CU$20),$G23:$W23)} -> 16 | ... DO23: {=SUMPRODUCT(TRANSPOSE(DO$4:DO$20),$G23:$W23)} -> 0
A24: =A23+1 -> 3 | B24: 01M129-545-01M129 | C24: 418493422 | D24: CBL ASSY COAX SMA(M)RA-SMA(M)RA L=545MM | E24: EA | F24: 1 | G24: 0 | H24: 0 | I24: 0 | J24: 0 | K24: 0 | L24: 0 | M24: 0 | N24: 0 | O24: 0 | P24: 0 | Q24: 0 | R24: 0 | S24: 0 | T24: 0 | U24: 0 | V24: 0 | W24: 2 | X24: Star Light/Huang Ling | Y24: 34.36 | Z24: 462 | AA24: 0 | AB24: 0 | AC24: 0 | AD24: 0 | AE24: 0 | AF24: 0 | AG24: 0 | AH24: 0 | AI24: 0 | AJ24: 0 | AK24: 0 | AL24: 0 | AM24: 0 | AN24: 0 | BK24: =SUM($Z24:AD24)-SUM($CM24:CQ24) -> 430 | BL24: =SUM($Z24:AE24)-SUM($CM24:CR24) -> 398 | BM24: =SUM($Z24:AF24)-SUM($CM24:CS24) -> 366 | BN24: =SUM($Z24:AG24)-SUM($CM24:CT24) -> 334 | BO24: =SUM($Z24:AH24)-SUM($CM24:CU24) -> 302 | BP24: =SUM($Z24:AI24)-SUM($CM24:CV24) -> 270 | BQ24: =SUM($Z24:AJ24)-SUM($CM24:CW24) -> 238 | BR24: =SUM($Z24:AK24)-SUM($CM24:CX24) -> 206 | ... CI24: =SUM($Z24:BB24)-SUM($CM24:DO24) -> 206 | CN24: {=SUMPRODUCT(TRANSPOSE(CN$4:CN$20),$G24:$W24)} -> 0 | CO24: {=SUMPRODUCT(TRANSPOSE(CO$4:CO$20),$G24:$W24)} -> 0 | CP24: {=SUMPRODUCT(TRANSPOSE(CP$4:CP$20),$G24:$W24)} -> 0 | CQ24: {=SUMPRODUCT(TRANSPOSE(CQ$4:CQ$20),$G24:$W24)} -> 32 | CR24: {=SUMPRODUCT(TRANSPOSE(CR$4:CR$20),$G24:$W24)} -> 32 | CS24: {=SUMPRODUCT(TRANSPOSE(CS$4:CS$20),$G24:$W24)} -> 32 | CT24: {=SUMPRODUCT(TRANSPOSE(CT$4:CT$20),$G24:$W24)} -> 32 | CU24: {=SUMPRODUCT(TRANSPOSE(CU$4:CU$20),$G24:$W24)} -> 32 | ... DO24: {=SUMPRODUCT(TRANSPOSE(DO$4:DO$20),$G24:$W24)} -> 0
A25: =A24+1 -> 4 | B25: 01M129-75.8-01M110 | C25: 418493446 | D25: CBL ASSY COAX SMA(M)RA-SMA(M) L=75.8MM | E25: EA | F25: 1 | G25: 0 | H25: 0 | I25: 0 | J25: 0 | K25: 0 | L25: 0 | M25: 0 | N25: 0 | O25: 0 | P25: 0 | Q25: 0 | R25: 0 | S25: 0 | T25: 0 | U25: 0 | V25: 0 | W25: 1 | X25: Star Light/Huang Ling | Y25: 32.53 | Z25: 231 | AA25: 0 | AB25: 0 | AC25: 0 | AD25: 0 | AE25: 0 | AF25: 0 | AG25: 0 | AH25: 0 | AI25: 0 | AJ25: 0 | AK25: 0 | AL25: 0 | AM25: 0 | AN25: 0 | BK25: =SUM($Z25:AD25)-SUM($CM25:CQ25) -> 215 | BL25: =SUM($Z25:AE25)-SUM($CM25:CR25) -> 199 | BM25: =SUM($Z25:AF25)-SUM($CM25:CS25) -> 183 | BN25: =SUM($Z25:AG25)-SUM($CM25:CT25) -> 167 | BO25: =SUM($Z25:AH25)-SUM($CM25:CU25) -> 151 | BP25: =SUM($Z25:AI25)-SUM($CM25:CV25) -> 135 | BQ25: =SUM($Z25:AJ25)-SUM($CM25:CW25) -> 119 | BR25: =SUM($Z25:AK25)-SUM($CM25:CX25) -> 103 | ... CI25: =SUM($Z25:BB25)-SUM($CM25:DO25) -> 103 | CN25: {=SUMPRODUCT(TRANSPOSE(CN$4:CN$20),$G25:$W25)} -> 0 | CO25: {=SUMPRODUCT(TRANSPOSE(CO$4:CO$20),$G25:$W25)} -> 0 | CP25: {=SUMPRODUCT(TRANSPOSE(CP$4:CP$20),$G25:$W25)} -> 0 | CQ25: {=SUMPRODUCT(TRANSPOSE(CQ$4:CQ$20),$G25:$W25)} -> 16 | CR25: {=SUMPRODUCT(TRANSPOSE(CR$4:CR$20),$G25:$W25)} -> 16 | CS25: {=SUMPRODUCT(TRANSPOSE(CS$4:CS$20),$G25:$W25)} -> 16 | CT25: {=SUMPRODUCT(TRANSPOSE(CT$4:CT$20),$G25:$W25)} -> 16 | CU25: {=SUMPRODUCT(TRANSPOSE(CU$4:CU$20),$G25:$W25)} -> 16 | ... DO25: {=SUMPRODUCT(TRANSPOSE(DO$4:DO$20),$G25:$W25)} -> 0
A26: =A25+1 -> 5 | B26: 01M12R-305-60F17K | C26: 418521484 | D26: SMA P. AU.+305+SAM J. AU | E26: EA | F26: 1 | G26: 0 | H26: 0 | I26: 0 | J26: 0 | K26: 0 | L26: 0 | M26: 0 | N26: 0 | O26: 0 | P26: 0 | Q26: 0 | R26: 0 | S26: 0 | T26: 0 | U26: 0 | V26: 0 | W26: 129 | X26: Star Light/Huang Ling | Y26: 19.95 | Z26: 29799 | AA26: 0 | AB26: 0 | AC26: 0 | AD26: 0 | AE26: 0 | AF26: 0 | AG26: 0 | AH26: 0 | AI26: 0 | AJ26: 0 | AK26: 0 | AL26: 0 | AM26: 0 | AN26: 0 | BK26: =SUM($Z26:AD26)-SUM($CM26:CQ26) -> 27735 | BL26: =SUM($Z26:AE26)-SUM($CM26:CR26) -> 25671 | BM26: =SUM($Z26:AF26)-SUM($CM26:CS26) -> 23607 | BN26: =SUM($Z26:AG26)-SUM($CM26:CT26) -> 21543 | BO26: =SUM($Z26:AH26)-SUM($CM26:CU26) -> 19479 | BP26: =SUM($Z26:AI26)-SUM($CM26:CV26) -> 17415 | BQ26: =SUM($Z26:AJ26)-SUM($CM26:CW26) -> 15351 | BR26: =SUM($Z26:AK26)-SUM($CM26:CX26) -> 13287 | ... CI26: =SUM($Z26:BB26)-SUM($CM26:DO26) -> 13287 | CN26: {=SUMPRODUCT(TRANSPOSE(CN$4:CN$20),$G26:$W26)} -> 0 | CO26: {=SUMPRODUCT(TRANSPOSE(CO$4:CO$20),$G26:$W26)} -> 0 | CP26: {=SUMPRODUCT(TRANSPOSE(CP$4:CP$20),$G26:$W26)} -> 0 | CQ26: {=SUMPRODUCT(TRANSPOSE(CQ$4:CQ$20),$G26:$W26)} -> 2064 | CR26: {=SUMPRODUCT(TRANSPOSE(CR$4:CR$20),$G26:$W26)} -> 2064 | CS26: {=SUMPRODUCT(TRANSPOSE(CS$4:CS$20),$G26:$W26)} -> 2064 | CT26: {=SUMPRODUCT(TRANSPOSE(CT$4:CT$20),$G26:$W26)} -> 2064 | CU26: {=SUMPRODUCT(TRANSPOSE(CU$4:CU$20),$G26:$W26)} -> 2064 | ... DO26: {=SUMPRODUCT(TRANSPOSE(DO$4:DO$20),$G26:$W26)} -> 0
A27: =A26+1 -> 6 | B27: 200090 | C27: N41402082 | D27: TERMINAL SOLDER LUG | E27: EA | F27: 1 | G27: 0 | H27: 0 | I27: 0 | J27: 0 | K27: 0 | L27: 0 | M27: 0 | N27: 0 | O27: 4 | P27: 0 | Q27: 0 | R27: 0 | S27: 4 | T27: 0 | U27: 0 | V27: 0 | W27: 0 | X27: YAEL Y.A.D | Y27: 0.72576 | Z27: 5000 | AA27: 0 | AB27: 0 | AC27: 0 | AD27: 0 | AE27: 0 | AF27: 0 | AG27: 0 | AH27: 0 | AI27: 0 | AJ27: 0 | AK27: 0 | AL27: 0 | AM27: 0 | AN27: 0 | BK27: =SUM($Z27:AD27)-SUM($CM27:CQ27) -> 4688 | BL27: =SUM($Z27:AE27)-SUM($CM27:CR27) -> 4408 | BM27: =SUM($Z27:AF27)-SUM($CM27:CS27) -> 4148 | BN27: =SUM($Z27:AG27)-SUM($CM27:CT27) -> 3908 | BO27: =SUM($Z27:AH27)-SUM($CM27:CU27) -> 3668 | BP27: =SUM($Z27:AI27)-SUM($CM27:CV27) -> 3428 | BQ27: =SUM($Z27:AJ27)-SUM($CM27:CW27) -> 3188 | BR27: =SUM($Z27:AK27)-SUM($CM27:CX27) -> 2948 | ... CI27: =SUM($Z27:BB27)-SUM($CM27:DO27) -> 2172 | CN27: {=SUMPRODUCT(TRANSPOSE(CN$4:CN$20),$G27:$W27)} -> 0 | CO27: {=SUMPRODUCT(TRANSPOSE(CO$4:CO$20),$G27:$W27)} -> 0 | CP27: {=SUMPRODUCT(TRANSPOSE(CP$4:CP$20),$G27:$W27)} -> 0 | CQ27: {=SUMPRODUCT(TRANSPOSE(CQ$4:CQ$20),$G27:$W27)} -> 312 | CR27: {=SUMPRODUCT(TRANSPOSE(CR$4:CR$20),$G27:$W27)} -> 280 | CS27: {=SUMPRODUCT(TRANSPOSE(CS$4:CS$20),$G27:$W27)} -> 260 | CT27: {=SUMPRODUCT(TRANSPOSE(CT$4:CT$20),$G27:$W27)} -> 240 | CU27: {=SUMPRODUCT(TRANSPOSE(CU$4:CU$20),$G27:$W27)} -> 240 | ... DO27: {=SUMPRODUCT(TRANSPOSE(DO$4:DO$20),$G27:$W27)} -> 0
A28: =A27+1 -> 7 | B28: 04021J0R7PBSTR | C28: 401225108 | D28: CHIP CAP 0.7PF +-.02PF 100V T&R | E28: EA | F28: 2 | G28: 0 | H28: 0 | I28: 0 | J28: 0 | K28: 0 | L28: 0 | M28: 0 | N28: 0 | O28: 0 | P28: 0 | Q28: 34 | R28: 0 | S28: 0 | T28: 0 | U28: 0 | V28: 0 | W28: 0 | X28: Phoenix | Y28: 0.17 | Z28: 40000 | AA28: 0 | AB28: 0 | AC28: 0 | AD28: 0 | AE28: 0 | AF28: 0 | AG28: 0 | AH28: 0 | AI28: 0 | AJ28: 0 | AK28: 0 | AL28: 0 | AM28: 0 | AN28: 0 | BK28: =SUM($Z28:AD28)-SUM($CM28:CQ28) -> 38810 | BL28: =SUM($Z28:AE28)-SUM($CM28:CR28) -> 37620 | BM28: =SUM($Z28:AF28)-SUM($CM28:CS28) -> 36430 | BN28: =SUM($Z28:AG28)-SUM($CM28:CT28) -> 35410 | BO28: =SUM($Z28:AH28)-SUM($CM28:CU28) -> 34390 | BP28: =SUM($Z28:AI28)-SUM($CM28:CV28) -> 33370 | BQ28: =SUM($Z28:AJ28)-SUM($CM28:CW28) -> 32350 | BR28: =SUM($Z28:AK28)-SUM($CM28:CX28) -> 31330 | ... CI28: =SUM($Z28:BB28)-SUM($CM28:DO28) -> 27794 | CN28: {=SUMPRODUCT(TRANSPOSE(CN$4:CN$20),$G28:$W28)} -> 0 | CO28: {=SUMPRODUCT(TRANSPOSE(CO$4:CO$20),$G28:$W28)} -> 0 | CP28: {=SUMPRODUCT(TRANSPOSE(CP$4:CP$20),$G28:$W28)} -> 0 | CQ28: {=SUMPRODUCT(TRANSPOSE(CQ$4:CQ$20),$G28:$W28)} -> 1190 | CR28: {=SUMPRODUCT(TRANSPOSE(CR$4:CR$20),$G28:$W28)} -> 1190 | CS28: {=SUMPRODUCT(TRANSPOSE(CS$4:CS$20),$G28:$W28)} -> 1190 | CT28: {=SUMPRODUCT(TRANSPOSE(CT$4:CT$20),$G28:$W28)} -> 1020 | CU28: {=SUMPRODUCT(TRANSPOSE(CU$4:CU$20),$G28:$W28)} -> 1020 | ... DO28: {=SUMPRODUCT(TRANSPOSE(DO$4:DO$20),$G28:$W28)} -> 0
A29: =A28+1 -> 8 | B29: 04025J3R3ABSTR | C29: 401225101 | D29: CHIP CAP 3.3PF +-.05PF 50V T&R | E29: EA | F29: 2 | G29: 0 | H29: 0 | I29: 0 | J29: 0 | K29: 0 | L29: 0 | M29: 0 | N29: 0 | O29: 0 | P29: 0 | Q29: 34 | R29: 0 | S29: 0 | T29: 0 | U29: 0 | V29: 0 | W29: 0 | X29: Phoenix | Y29: 0.17 | Z29: 40000 | AA29: 0 | AB29: 0 | AC29: 0 | AD29: 0 | AE29: 0 | AF29: 0 | AG29: 0 | AH29: 0 | AI29: 0 | AJ29: 0 | AK29: 0 | AL29: 0 | AM29: 0 | AN29: 0 | BK29: =SUM($Z29:AD29)-SUM($CM29:CQ29) -> 38810 | BL29: =SUM($Z29:AE29)-SUM($CM29:CR29) -> 37620 | BM29: =SUM($Z29:AF29)-SUM($CM29:CS29) -> 36430 | BN29: =SUM($Z29:AG29)-SUM($CM29:CT29) -> 35410 | BO29: =SUM($Z29:AH29)-SUM($CM29:CU29) -> 34390 | BP29: =SUM($Z29:AI29)-SUM($CM29:CV29) -> 33370 | BQ29: =SUM($Z29:AJ29)-SUM($CM29:CW29) -> 32350 | BR29: =SUM($Z29:AK29)-SUM($CM29:CX29) -> 31330 | ... CI29: =SUM($Z29:BB29)-SUM($CM29:DO29) -> 27794 | CN29: {=SUMPRODUCT(TRANSPOSE(CN$4:CN$20),$G29:$W29)} -> 0 | CO29: {=SUMPRODUCT(TRANSPOSE(CO$4:CO$20),$G29:$W29)} -> 0 | CP29: {=SUMPRODUCT(TRANSPOSE(CP$4:CP$20),$G29:$W29)} -> 0 | CQ29: {=SUMPRODUCT(TRANSPOSE(CQ$4:CQ$20),$G29:$W29)} -> 1190 | CR29: {=SUMPRODUCT(TRANSPOSE(CR$4:CR$20),$G29:$W29)} -> 1190 | CS29: {=SUMPRODUCT(TRANSPOSE(CS$4:CS$20),$G29:$W29)} -> 1190 | CT29: {=SUMPRODUCT(TRANSPOSE(CT$4:CT$20),$G29:$W29)} -> 1020 | CU29: {=SUMPRODUCT(TRANSPOSE(CU$4:CU$20),$G29:$W29)} -> 1020 | ... DO29: {=SUMPRODUCT(TRANSPOSE(DO$4:DO$20),$G29:$W29)} -> 0
A30: =A29+1 -> 9 | B30: 0440.500WR | C30: 417380164 | D30: FUSE SLOW BLOW 0.5A/63V,SMT,REEL PACK | E30: EA | F30: 2 | G30: 0 | H30: 0 | I30: 0 | J30: 0 | K30: 0 | L30: 0 | M30: 0 | N30: 0 | O30: 0 | P30: 0 | Q30: 0 | R30: 0 | S30: 0 | T30: 0 | U30: 0 | V30: 0 | W30: 0 | X30: Rabyte Technologies LLP | Y30: 0.111 | Z30: 36000 | AA30: 0 | AB30: 0 | AC30: 0 | AD30: 0 | AE30: 0 | AF30: 0 | AG30: 0 | AH30: 0 | AI30: 0 | AJ30: 0 | AK30: 0 | AL30: 0 | AM30: 0 | AN30: 0 | BK30: =SUM($Z30:AD30)-SUM($CM30:CQ30) -> 36000 | BL30: =SUM($Z30:AE30)-SUM($CM30:CR30) -> 36000 | BM30: =SUM($Z30:AF30)-SUM($CM30:CS30) -> 36000 | BN30: =SUM($Z30:AG30)-SUM($CM30:CT30) -> 36000 | BO30: =SUM($Z30:AH30)-SUM($CM30:CU30) -> 36000 | BP30: =SUM($Z30:AI30)-SUM($CM30:CV30) -> 36000 | BQ30: =SUM($Z30:AJ30)-SUM($CM30:CW30) -> 36000 | BR30: =SUM($Z30:AK30)-SUM($CM30:CX30) -> 36000 | ... CI30: =SUM($Z30:BB30)-SUM($CM30:DO30) -> 36000 | CN30: {=SUMPRODUCT(TRANSPOSE(CN$4:CN$20),$G30:$W30)} -> 0 | CO30: {=SUMPRODUCT(TRANSPOSE(CO$4:CO$20),$G30:$W30)} -> 0 | CP30: {=SUMPRODUCT(TRANSPOSE(CP$4:CP$20),$G30:$W30)} -> 0 | CQ30: {=SUMPRODUCT(TRANSPOSE(CQ$4:CQ$20),$G30:$W30)} -> 0 | CR30: {=SUMPRODUCT(TRANSPOSE(CR$4:CR$20),$G30:$W30)} -> 0 | CS30: {=SUMPRODUCT(TRANSPOSE(CS$4:CS$20),$G30:$W30)} -> 0 | CT30: {=SUMPRODUCT(TRANSPOSE(CT$4:CT$20),$G30:$W30)} -> 0 | CU30: {=SUMPRODUCT(TRANSPOSE(CU$4:CU$20),$G30:$W30)} -> 0 | ... DO30: {=SUMPRODUCT(TRANSPOSE(DO$4:DO$20),$G30:$W30)} -> 0
A31: =A30+1 -> 10 | B31: 0440001.WR | C31: 409331536 | D31: FUSE CERAMIC SMT 1A 50V T&R | E31: EA | F31: 2 | G31: 0 | H31: 0 | I31: 0 | J31: 0 | K31: 0 | L31: 0 | M31: 0 | N31: 0 | O31: 0 | P31: 0 | Q31: 35 | R31: 0 | S31: 0 | T31: 0 | U31: 35 | V31: 0 | W31: 0 | X31: Rabyte Technologies LLP | Y31: 0.111 | Z31: 39000 | AA31: 0 | AB31: 0 | AC31: 0 | AD31: 0 | AE31: 0 | AF31: 0 | AG31: 0 | AH31: 0 | AI31: 0 | AJ31: 0 | AK31: 0 | AL31: 0 | AM31: 0 | AN31: 0 | BK31: =SUM($Z31:AD31)-SUM($CM31:CQ31) -> 36270 | BL31: =SUM($Z31:AE31)-SUM($CM31:CR31) -> 33820 | BM31: =SUM($Z31:AF31)-SUM($CM31:CS31) -> 31545 | BN31: =SUM($Z31:AG31)-SUM($CM31:CT31) -> 29445 | BO31: =SUM($Z31:AH31)-SUM($CM31:CU31) -> 27345 | BP31: =SUM($Z31:AI31)-SUM($CM31:CV31) -> 25245 | BQ31: =SUM($Z31:AJ31)-SUM($CM31:CW31) -> 23145 | BR31: =SUM($Z31:AK31)-SUM($CM31:CX31) -> 21045 | ... CI31: =SUM($Z31:BB31)-SUM($CM31:DO31) -> 14255 | CN31: {=SUMPRODUCT(TRANSPOSE(CN$4:CN$20),$G31:$W31)} -> 0 | CO31: {=SUMPRODUCT(TRANSPOSE(CO$4:CO$20),$G31:$W31)} -> 0 | CP31: {=SUMPRODUCT(TRANSPOSE(CP$4:CP$20),$G31:$W31)} -> 0 | CQ31: {=SUMPRODUCT(TRANSPOSE(CQ$4:CQ$20),$G31:$W31)} -> 2730 | CR31: {=SUMPRODUCT(TRANSPOSE(CR$4:CR$20),$G31:$W31)} -> 2450 | CS31: {=SUMPRODUCT(TRANSPOSE(CS$4:CS$20),$G31:$W31)} -> 2275 | CT31: {=SUMPRODUCT(TRANSPOSE(CT$4:CT$20),$G31:$W31)} -> 2100 | CU31: {=SUMPRODUCT(TRANSPOSE(CU$4:CU$20),$G31:$W31)} -> 2100 | ... DO31: {=SUMPRODUCT(TRANSPOSE(DO$4:DO$20),$G31:$W31)} -> 0
A32: =A31+1 -> 11 | B32: 0466.500NR | C32: 400506335 | D32: FUSE 0.5A/63V VERY FAST ACTION, ROHS, | E32: EA | F32: 2 | G32: 0 | H32: 0 | I32: 0 | J32: 0 | K32: 0 | L32: 0 | M32: 0 | N32: 0 | O32: 0 | P32: 0 | Q32: 70 | R32: 0 | S32: 0 | T32: 0 | U32: 70 | V32: 0 | W32: 0 | X32: Rabyte Technologies LLP | Y32: 0.053 | Z32: 75000 | AA32: 0 | AB32: 0 | AC32: 0 | AD32: 0 | AE32: 0 | AF32: 0 | AG32: 0 | AH32: 0 | AI32: 0 | AJ32: 0 | AK32: 0 | AL32: 0 | AM32: 0 | AN32: 0 | BK32: =SUM($Z32:AD32)-SUM($CM32:CQ32) -> 69540 | BL32: =SUM($Z32:AE32)-SUM($CM32:CR32) -> 64640 | BM32: =SUM($Z32:AF32)-SUM($CM32:CS32) -> 60090 | BN32: =SUM($Z32:AG32)-SUM($CM32:CT32) -> 55890 | BO32: =SUM($Z32:AH32)-SUM($CM32:CU32) -> 51690 | BP32: =SUM($Z32:AI32)-SUM($CM32:CV32) -> 47490 | BQ32: =SUM($Z32:AJ32)-SUM($CM32:CW32) -> 43290 | BR32: =SUM($Z32:AK32)-SUM($CM32:CX32) -> 39090 | ... CI32: =SUM($Z32:BB32)-SUM($CM32:DO32) -> 25510 | CN32: {=SUMPRODUCT(TRANSPOSE(CN$4:CN$20),$G32:$W32)} -> 0 | CO32: {=SUMPRODUCT(TRANSPOSE(CO$4:CO$20),$G32:$W32)} -> 0 | CP32: {=SUMPRODUCT(TRANSPOSE(CP$4:CP$20),$G32:$W32)} -> 0 | CQ32: {=SUMPRODUCT(TRANSPOSE(CQ$4:CQ$20),$G32:$W32)} -> 5460 | CR32: {=SUMPRODUCT(TRANSPOSE(CR$4:CR$20),$G32:$W32)} -> 4900 | CS32: {=SUMPRODUCT(TRANSPOSE(CS$4:CS$20),$G32:$W32)} -> 4550 | CT32: {=SUMPRODUCT(TRANSPOSE(CT$4:CT$20),$G32:$W32)} -> 4200 | CU32: {=SUMPRODUCT(TRANSPOSE(CU$4:CU$20),$G32:$W32)} -> 4200 | ... DO32: {=SUMPRODUCT(TRANSPOSE(DO$4:DO$20),$G32:$W32)} -> 0
A33: =A32+1 -> 12 | B33: 0466002.NRHF | C33: 403129345 | D33: FUSE VERY FAST-ACTING | E33: EA | F33: 2 | G33: 0 | H33: 0 | I33: 0 | J33: 0 | K33: 0 | L33: 0 | M33: 0 | N33: 0 | O33: 0 | P33: 0 | Q33: 34 | R33: 0 | S33: 0 | T33: 0 | U33: 0 | V33: 0 | W33: 0 | X33: Rabyte Technologies LLP | Y33: 0.067 | Z33: 40000 | AA33: 0 | AB33: 0 | AC33: 0 | AD33: 0 | AE33: 0 | AF33: 0 | AG33: 0 | AH33: 0 | AI33: 0 | AJ33: 0 | AK33: 0 | AL33: 0 | AM33: 0 | AN33: 0 | BK33: =SUM($Z33:AD33)-SUM($CM33:CQ33) -> 38810 | BL33: =SUM($Z33:AE33)-SUM($CM33:CR33) -> 37620 | BM33: =SUM($Z33:AF33)-SUM($CM33:CS33) -> 36430 | BN33: =SUM($Z33:AG33)-SUM($CM33:CT33) -> 35410 | BO33: =SUM($Z33:AH33)-SUM($CM33:CU33) -> 34390 | BP33: =SUM($Z33:AI33)-SUM($CM33:CV33) -> 33370 | BQ33: =SUM($Z33:AJ33)-SUM($CM33:CW33) -> 32350 | BR33: =SUM($Z33:AK33)-SUM($CM33:CX33) -> 31330 | ... CI33: =SUM($Z33:BB33)-SUM($CM33:DO33) -> 27794 | CN33: {=SUMPRODUCT(TRANSPOSE(CN$4:CN$20),$G33:$W33)} -> 0 | CO33: {=SUMPRODUCT(TRANSPOSE(CO$4:CO$20),$G33:$W33)} -> 0 | CP33: {=SUMPRODUCT(TRANSPOSE(CP$4:CP$20),$G33:$W33)} -> 0 | CQ33: {=SUMPRODUCT(TRANSPOSE(CQ$4:CQ$20),$G33:$W33)} -> 1190 | CR33: {=SUMPRODUCT(TRANSPOSE(CR$4:CR$20),$G33:$W33)} -> 1190 | CS33: {=SUMPRODUCT(TRANSPOSE(CS$4:CS$20),$G33:$W33)} -> 1190 | CT33: {=SUMPRODUCT(TRANSPOSE(CT$4:CT$20),$G33:$W33)} -> 1020 | CU33: {=SUMPRODUCT(TRANSPOSE(CU$4:CU$20),$G33:$W33)} -> 1020 | ... DO33: {=SUMPRODUCT(TRANSPOSE(DO$4:DO$20),$G33:$W33)} -> 0
A34: =A33+1 -> 13 | B34: 0505P100JW151XTV | C34: 410206308 | D34: CHIP CAP 10PF 5^ 150VOLT 55X55 PORCE | E34: EA | F34: 2 | G34: 0 | H34: 0 | I34: 0 | J34: 0 | K34: 0 | L34: 0 | M34: 0 | N34: 0 | O34: 0 | P34: 0 | Q34: 34 | R34: 0 | S34: 0 | T34: 0 | U34: 34 | V34: 0 | W34: 0 | X34: Phoenix | Y34: 0.535 | Z34: 36500 | AA34: 0 | AB34: 0 | AC34: 0 | AD34: 0 | AE34: 0 | AF34: 0 | AG34: 0 | AH34: 0 | AI34: 0 | AJ34: 0 | AK34: 0 | AL34: 0 | AM34: 0 | AN34: 0 | BK34: =SUM($Z34:AD34)-SUM($CM34:CQ34) -> 33848 | BL34: =SUM($Z34:AE34)-SUM($CM34:CR34) -> 31468 | BM34: =SUM($Z34:AF34)-SUM($CM34:CS34) -> 29258 | BN34: =SUM($Z34:AG34)-SUM($CM34:CT34) -> 27218 | BO34: =SUM($Z34:AH34)-SUM($CM34:CU34) -> 25178 | BP34: =SUM($Z34:AI34)-SUM($CM34:CV34) -> 23138 | BQ34: =SUM($Z34:AJ34)-SUM($CM34:CW34) -> 21098 | BR34: =SUM($Z34:AK34)-SUM($CM34:CX34) -> 19058 | ... CI34: =SUM($Z34:BB34)-SUM($CM34:DO34) -> 12462 | CN34: {=SUMPRODUCT(TRANSPOSE(CN$4:CN$20),$G34:$W34)} -> 0 | CO34: {=SUMPRODUCT(TRANSPOSE(CO$4:CO$20),$G34:$W34)} -> 0 | CP34: {=SUMPRODUCT(TRANSPOSE(CP$4:CP$20),$G34:$W34)} -> 0 | CQ34: {=SUMPRODUCT(TRANSPOSE(CQ$4:CQ$20),$G34:$W34)} -> 2652 | CR34: {=SUMPRODUCT(TRANSPOSE(CR$4:CR$20),$G34:$W34)} -> 2380 | CS34: {=SUMPRODUCT(TRANSPOSE(CS$4:CS$20),$G34:$W34)} -> 2210 | CT34: {=SUMPRODUCT(TRANSPOSE(CT$4:CT$20),$G34:$W34)} -> 2040 | CU34: {=SUMPRODUCT(TRANSPOSE(CU$4:CU$20),$G34:$W34)} -> 2040 | ... DO34: {=SUMPRODUCT(TRANSPOSE(DO$4:DO$20),$G34:$W34)} -> 0
A35: =A34+1 -> 14 | B35: 0505P4R7BW151XTV | C35: 411063876 | D35: CHIP CAP 4.7PF +/-0.1PF 150V 1.4MM2 | E35: EA | F35: 2 | G35: 0 | H35: 0 | I35: 0 | J35: 0 | K35: 0 | L35: 0 | M35: 0 | N35: 0 | O35: 0 | P35: 0 | Q35: 2 | R35: 0 | S35: 0 | T35: 0 | U35: 0 | V35: 0 | W35: 0 | X35: Phoenix | Y35: 0.89 | Z35: 2500 | AA35: 0 | AB35: 0 | AC35: 0 | AD35: 0 | AE35: 0 | AF35: 0 | AG35: 0 | AH35: 0 | AI35: 0 | AJ35: 0 | AK35: 0 | AL35: 0 | AM35: 0 | AN35: 0 | BK35: =SUM($Z35:AD35)-SUM($CM35:CQ35) -> 2430 | BL35: =SUM($Z35:AE35)-SUM($CM35:CR35) -> 2360 | BM35: =SUM($Z35:AF35)-SUM($CM35:CS35) -> 2290 | BN35: =SUM($Z35:AG35)-SUM($CM35:CT35) -> 2230 | BO35: =SUM($Z35:AH35)-SUM($CM35:CU35) -> 2170 | BP35: =SUM($Z35:AI35)-SUM($CM35:CV35) -> 2110 | BQ35: =SUM($Z35:AJ35)-SUM($CM35:CW35) -> 2050 | BR35: =SUM($Z35:AK35)-SUM($CM35:CX35) -> 1990 | ... CI35: =SUM($Z35:BB35)-SUM($CM35:DO35) -> 1782 | CN35: {=SUMPRODUCT(TRANSPOSE(CN$4:CN$20),$G35:$W35)} -> 0 | CO35: {=SUMPRODUCT(TRANSPOSE(CO$4:CO$20),$G35:$W35)} -> 0 | CP35: {=SUMPRODUCT(TRANSPOSE(CP$4:CP$20),$G35:$W35)} -> 0 | CQ35: {=SUMPRODUCT(TRANSPOSE(CQ$4:CQ$20),$G35:$W35)} -> 70 | CR35: {=SUMPRODUCT(TRANSPOSE(CR$4:CR$20),$G35:$W35)} -> 70 | CS35: {=SUMPRODUCT(TRANSPOSE(CS$4:CS$20),$G35:$W35)} -> 70 | CT35: {=SUMPRODUCT(TRANSPOSE(CT$4:CT$20),$G35:$W35)} -> 60 | CU35: {=SUMPRODUCT(TRANSPOSE(CU$4:CU$20),$G35:$W35)} -> 60 | ... DO35: {=SUMPRODUCT(TRANSPOSE(DO$4:DO$20),$G35:$W35)} -> 0
A36: =A35+1 -> 15 | B36: 080-1200 | C36: 732551668 | D36: ADHESIVE CONDUCTIVE SILICONE, SILVER | E36: AR | F36: 2 | G36: 0 | H36: 0 | I36: 0 | J36: 0 | K36: 0 | L36: 0 | M36: 0 | N36: 0 | O36: 0.025 | P36: 0 | Q36: 0 | R36: 0 | S36: 0.025 | T36: 0 | U36: 0 | V36: 0 | W36: 0.05 | X36: Spectra Innovations INC | Y36: 600 | Z36: 31 | AA36: 0 | AB36: 0 | AC36: 0 | AD36: 0 | AE36: 0 | AF36: 0 | AG36: 0 | AH36: 0 | AI36: 0 | AJ36: 0 | AK36: 0 | AL36: 0 | AM36: 0 | AN36: 0 | BK36: =SUM($Z36:AD36)-SUM($CM36:CQ36) -> 28.25 | BL36: =SUM($Z36:AE36)-SUM($CM36:CR36) -> 25.7 | BM36: =SUM($Z36:AF36)-SUM($CM36:CS36) -> 23.275 | BN36: =SUM($Z36:AG36)-SUM($CM36:CT36) -> 20.975 | BO36: =SUM($Z36:AH36)-SUM($CM36:CU36) -> 18.675 | BP36: =SUM($Z36:AI36)-SUM($CM36:CV36) -> 16.375 | BQ36: =SUM($Z36:AJ36)-SUM($CM36:CW36) -> 14.075 | BR36: =SUM($Z36:AK36)-SUM($CM36:CX36) -> 11.775 | ... CI36: =SUM($Z36:BB36)-SUM($CM36:DO36) -> 6.925 | CN36: {=SUMPRODUCT(TRANSPOSE(CN$4:CN$20),$G36:$W36)} -> 0 | CO36: {=SUMPRODUCT(TRANSPOSE(CO$4:CO$20),$G36:$W36)} -> 0 | CP36: {=SUMPRODUCT(TRANSPOSE(CP$4:CP$20),$G36:$W36)} -> 0 | CQ36: {=SUMPRODUCT(TRANSPOSE(CQ$4:CQ$20),$G36:$W36)} -> 2.75 | CR36: {=SUMPRODUCT(TRANSPOSE(CR$4:CR$20),$G36:$W36)} -> 2.55 | CS36: {=SUMPRODUCT(TRANSPOSE(CS$4:CS$20),$G36:$W36)} -> 2.425 | CT36: {=SUMPRODUCT(TRANSPOSE(CT$4:CT$20),$G36:$W36)} -> 2.3 | CU36: {=SUMPRODUCT(TRANSPOSE(CU$4:CU$20),$G36:$W36)} -> 2.3 | ... DO36: {=SUMPRODUCT(TRANSPOSE(DO$4:DO$20),$G36:$W36)} -> 0
A37: =A36+1 -> 16 | B37: 1/4-28X7/8SOCCAP316SSSIL | C37: 418969713 | D37: SEAL SCREW,THREAD 1/4"-28UNF,HEX SOCKET | E37: EA | F37: 1 | G37: 0 | H37: 0 | I37: 0 | J37: 0 | K37: 0 | L37: 0 | M37: 0 | N37: 0 | O37: 0 | P37: 0 | Q37: 0 | R37: 0 | S37: 0 | T37: 0 | U37: 0 | V37: 0 | W37: 19 | X37: Kaytech | Y37: 0.889 | Z37: 4390 | AA37: 0 | AB37: 0 | AC37: 0 | AD37: 0 | AE37: 0 | AF37: 0 | AG37: 0 | AH37: 0 | AI37: 0 | AJ37: 0 | AK37: 0 | AL37: 0 | AM37: 0 | AN37: 0 | BK37: =SUM($Z37:AD37)-SUM($CM37:CQ37) -> 4086 | BL37: =SUM($Z37:AE37)-SUM($CM37:CR37) -> 3782 | BM37: =SUM($Z37:AF37)-SUM($CM37:CS37) -> 3478 | BN37: =SUM($Z37:AG37)-SUM($CM37:CT37) -> 3174 | BO37: =SUM($Z37:AH37)-SUM($CM37:CU37) -> 2870 | BP37: =SUM($Z37:AI37)-SUM($CM37:CV37) -> 2566 | BQ37: =SUM($Z37:AJ37)-SUM($CM37:CW37) -> 2262 | BR37: =SUM($Z37:AK37)-SUM($CM37:CX37) -> 1958 | ... CI37: =SUM($Z37:BB37)-SUM($CM37:DO37) -> 1958 | CN37: {=SUMPRODUCT(TRANSPOSE(CN$4:CN$20),$G37:$W37)} -> 0 | CO37: {=SUMPRODUCT(TRANSPOSE(CO$4:CO$20),$G37:$W37)} -> 0 | CP37: {=SUMPRODUCT(TRANSPOSE(CP$4:CP$20),$G37:$W37)} -> 0 | CQ37: {=SUMPRODUCT(TRANSPOSE(CQ$4:CQ$20),$G37:$W37)} -> 304 | CR37: {=SUMPRODUCT(TRANSPOSE(CR$4:CR$20),$G37:$W37)} -> 304 | CS37: {=SUMPRODUCT(TRANSPOSE(CS$4:CS$20),$G37:$W37)} -> 304 | CT37: {=SUMPRODUCT(TRANSPOSE(CT$4:CT$20),$G37:$W37)} -> 304 | CU37: {=SUMPRODUCT(TRANSPOSE(CU$4:CU$20),$G37:$W37)} -> 304 | ... DO37: {=SUMPRODUCT(TRANSPOSE(DO$4:DO$20),$G37:$W37)} -> 0
A38: =A37+1 -> 17 | B38: 100RC37SCBRP1 | C38: N64403777 | D38: RECT RECP R/A 37 SKT DIP SOLDER | E38: EA | F38: 2 | G38: 0 | H38: 0 | I38: 0 | J38: 0 | K38: 0 | L38: 0 | M38: 0 | N38: 0 | O38: 0 | P38: 0 | Q38: 0 | R38: 1 | S38: 0 | T38: 0 | U38: 0 | V38: 1 | W38: 0 | X38: AMPHENOL Canada | Y38: 61.59 | Z38: 1067 | AA38: 0 | AB38: 0 | AC38: 0 | AD38: 0 | AE38: 0 | AF38: 0 | AG38: 0 | AH38: 0 | AI38: 0 | AJ38: 0 | AK38: 0 | AL38: 0 | AM38: 0 | AN38: 0 | BK38: =SUM($Z38:AD38)-SUM($CM38:CQ38) -> 997 | BL38: =SUM($Z38:AE38)-SUM($CM38:CR38) -> 927 | BM38: =SUM($Z38:AF38)-SUM($CM38:CS38) -> 857 | BN38: =SUM($Z38:AG38)-SUM($CM38:CT38) -> 787 | BO38: =SUM($Z38:AH38)-SUM($CM38:CU38) -> 717 | BP38: =SUM($Z38:AI38)-SUM($CM38:CV38) -> 647 | BQ38: =SUM($Z38:AJ38)-SUM($CM38:CW38) -> 577 | BR38: =SUM($Z38:AK38)-SUM($CM38:CX38) -> 507 | ... CI38: =SUM($Z38:BB38)-SUM($CM38:DO38) -> 402 | CN38: {=SUMPRODUCT(TRANSPOSE(CN$4:CN$20),$G38:$W38)} -> 0 | CO38: {=SUMPRODUCT(TRANSPOSE(CO$4:CO$20),$G38:$W38)} -> 0 | CP38: {=SUMPRODUCT(TRANSPOSE(CP$4:CP$20),$G38:$W38)} -> 0 | CQ38: {=SUMPRODUCT(TRANSPOSE(CQ$4:CQ$20),$G38:$W38)} -> 70 | CR38: {=SUMPRODUCT(TRANSPOSE(CR$4:CR$20),$G38:$W38)} -> 70 | CS38: {=SUMPRODUCT(TRANSPOSE(CS$4:CS$20),$G38:$W38)} -> 70 | CT38: {=SUMPRODUCT(TRANSPOSE(CT$4:CT$20),$G38:$W38)} -> 70 | CU38: {=SUMPRODUCT(TRANSPOSE(CU$4:CU$20),$G38:$W38)} -> 70 | ... DO38: {=SUMPRODUCT(TRANSPOSE(DO$4:DO$20),$G38:$W38)} -> 0
A39: =A38+1 -> 18 | B39: 1018419 | C39: 535101950 | D39: SHACKLE,G-209-3/8IN,ANCHOR,SCREW PIN,LOA | E39: EA | F39: 1 | G39: 0 | H39: 0 | I39: 0 | J39: 0 | K39: 0 | L39: 0 | M39: 0 | N39: 0 | O39: 0 | P39: 0 | Q39: 0 | R39: 0 | S39: 0 | T39: 0 | U39: 0 | V39: 0 | W39: 2 | X39: Agoran | Y39: 7.35 | Z39: 465 | AA39: 0 | AB39: 0 | AC39: 0 | AD39: 0 | AE39: 0 | AF39: 0 | AG39: 0 | AH39: 0 | AI39: 0 | AJ39: 0 | AK39: 0 | AL39: 0 | AM39: 0 | AN39: 0 | BK39: =SUM($Z39:AD39)-SUM($CM39:CQ39) -> 433 | BL39: =SUM($Z39:AE39)-SUM($CM39:CR39) -> 401 | BM39: =SUM($Z39:AF39)-SUM($CM39:CS39) -> 369 | BN39: =SUM($Z39:AG39)-SUM($CM39:CT39) -> 337 | BO39: =SUM($Z39:AH39)-SUM($CM39:CU39) -> 305 | BP39: =SUM($Z39:AI39)-SUM($CM39:CV39) -> 273 | BQ39: =SUM($Z39:AJ39)-SUM($CM39:CW39) -> 241 | BR39: =SUM($Z39:AK39)-SUM($CM39:CX39) -> 209 | ... CI39: =SUM($Z39:BB39)-SUM($CM39:DO39) -> 209 | CN39: {=SUMPRODUCT(TRANSPOSE(CN$4:CN$20),$G39:$W39)} -> 0 | CO39: {=SUMPRODUCT(TRANSPOSE(CO$4:CO$20),$G39:$W39)} -> 0 | CP39: {=SUMPRODUCT(TRANSPOSE(CP$4:CP$20),$G39:$W39)} -> 0 | CQ39: {=SUMPRODUCT(TRANSPOSE(CQ$4:CQ$20),$G39:$W39)} -> 32 | CR39: {=SUMPRODUCT(TRANSPOSE(CR$4:CR$20),$G39:$W39)} -> 32 | CS39: {=SUMPRODUCT(TRANSPOSE(CS$4:CS$20),$G39:$W39)} -> 32 | CT39: {=SUMPRODUCT(TRANSPOSE(CT$4:CT$20),$G39:$W39)} -> 32 | CU39: {=SUMPRODUCT(TRANSPOSE(CU$4:CU$20),$G39:$W39)} -> 32 | ... DO39: {=SUMPRODUCT(TRANSPOSE(DO$4:DO$20),$G39:$W39)} -> 0
A40: =A39+1 -> 19 | B40: 1038B611-001 | C40: 416969236 | D40: HEAT EXCHANGER | E40: EA | F40: 1 | G40: 0 | H40: 0 | I40: 0 | J40: 0 | K40: 0 | L40: 0 | M40: 0 | N40: 0 | O40: 0 | P40: 0 | Q40: 0 | R40: 0 | S40: 0 | T40: 0 | U40: 0 | V40: 0 | W40: 1 | X40: Godrej/Gopalan | Y40: 0 | Z40: 83 | AA40: 0 | AB40: 0 | AC40: 0 | AD40: 0 | AE40: 0 | AF40: 0 | AG40: 0 | AH40: 0 | AI40: 0 | AJ40: 0 | AK40: 0 | AL40: 0 | AM40: 0 | AN40: 0 | BK40: =SUM($Z40:AD40)-SUM($CM40:CQ40) -> 67 | BL40: =SUM($Z40:AE40)-SUM($CM40:CR40) -> 51 | BM40: =SUM($Z40:AF40)-SUM($CM40:CS40) -> 35 | BN40: =SUM($Z40:AG40)-SUM($CM40:CT40) -> 19 | BO40: =SUM($Z40:AH40)-SUM($CM40:CU40) -> 3 | BP40: =SUM($Z40:AI40)-SUM($CM40:CV40) -> -13 | BQ40: =SUM($Z40:AJ40)-SUM($CM40:CW40) -> -29 | BR40: =SUM($Z40:AK40)-SUM($CM40:CX40) -> -45 | ... CI40: =SUM($Z40:BB40)-SUM($CM40:DO40) -> -45 | CN40: {=SUMPRODUCT(TRANSPOSE(CN$4:CN$20),$G40:$W40)} -> 0 | CO40: {=SUMPRODUCT(TRANSPOSE(CO$4:CO$20),$G40:$W40)} -> 0 | CP40: {=SUMPRODUCT(TRANSPOSE(CP$4:CP$20),$G40:$W40)} -> 0 | CQ40: {=SUMPRODUCT(TRANSPOSE(CQ$4:CQ$20),$G40:$W40)} -> 16 | CR40: {=SUMPRODUCT(TRANSPOSE(CR$4:CR$20),$G40:$W40)} -> 16 | CS40: {=SUMPRODUCT(TRANSPOSE(CS$4:CS$20),$G40:$W40)} -> 16 | CT40: {=SUMPRODUCT(TRANSPOSE(CT$4:CT$20),$G40:$W40)} -> 16 | CU40: {=SUMPRODUCT(TRANSPOSE(CU$4:CU$20),$G40:$W40)} -> 16 | ... DO40: {=SUMPRODUCT(TRANSPOSE(DO$4:DO$20),$G40:$W40)} -> 0
A41: =A40+1 -> 20 | B41: 1038B801-001 | C41: 410825593 | D41: NAMEPLATE | E41: EA | F41: 1 | G41: 0 | H41: 0 | I41: 0 | J41: 0 | K41: 0 | L41: 0 | M41: 0 | N41: 1 | O41: 0 | P41: 0 | Q41: 0 | R41: 0 | S41: 0 | T41: 0 | U41: 0 | V41: 0 | W41: 0 | X41: Ackerman | Y41: 1.5 | Z41: 226 | AA41: 0 | AB41: 0 | AC41: 0 | AD41: 0 | AE41: 0 | AF41: 0 | AG41: 0 | AH41: 0 | AI41: 0 | AJ41: 0 | AK41: 0 | AL41: 0 | AM41: 0 | AN41: 0 | BK41: =SUM($Z41:AD41)-SUM($CM41:CQ41) -> 210 | BL41: =SUM($Z41:AE41)-SUM($CM41:CR41) -> 194 | BM41: =SUM($Z41:AF41)-SUM($CM41:CS41) -> 178 | BN41: =SUM($Z41:AG41)-SUM($CM41:CT41) -> 162 | BO41: =SUM($Z41:AH41)-SUM($CM41:CU41) -> 154 | BP41: =SUM($Z41:AI41)-SUM($CM41:CV41) -> 146 | BQ41: =SUM($Z41:AJ41)-SUM($CM41:CW41) -> 138 | BR41: =SUM($Z41:AK41)-SUM($CM41:CX41) -> 130 | ... CI41: =SUM($Z41:BB41)-SUM($CM41:DO41) -> 98 | CN41: {=SUMPRODUCT(TRANSPOSE(CN$4:CN$20),$G41:$W41)} -> 0 | CO41: {=SUMPRODUCT(TRANSPOSE(CO$4:CO$20),$G41:$W41)} -> 0 | CP41: {=SUMPRODUCT(TRANSPOSE(CP$4:CP$20),$G41:$W41)} -> 0 | CQ41: {=SUMPRODUCT(TRANSPOSE(CQ$4:CQ$20),$G41:$W41)} -> 16 | CR41: {=SUMPRODUCT(TRANSPOSE(CR$4:CR$20),$G41:$W41)} -> 16 | CS41: {=SUMPRODUCT(TRANSPOSE(CS$4:CS$20),$G41:$W41)} -> 16 | CT41: {=SUMPRODUCT(TRANSPOSE(CT$4:CT$20),$G41:$W41)} -> 16 | CU41: {=SUMPRODUCT(TRANSPOSE(CU$4:CU$20),$G41:$W41)} -> 8 | ... DO41: {=SUMPRODUCT(TRANSPOSE(DO$4:DO$20),$G41:$W41)} -> 0
...
