Workbook
Name TIER2: [1]TIER2!#REF!

Sheet avl 18.08.24
A1: DRM | K1: 1 | L1: 1 | M1: 1 | N1: 1 | O1: 1 | CT1: DTRM FINAL ASSY | CU1: =SUM(CV1:EO1) -> 35180 | DB1: 100 | DC1: 200 | DD1: 300 | DE1: 550 | DF1: 700 | DG1: 750 | DH1: 750 | DI1: 750 | DJ1: 750 | DK1: 750 | DL1: 750 | DM1: 1000 | DN1: 1000 | DO1: 1000 | DP1: 1000 | DQ1: 1000 | DR1: 1000 | DS1: 1000 | DT1: 1000 | DU1: 1000 | DV1: 1000 | DW1: 1000 | DX1: 1000 | DY1: 1000 | DZ1: 1000 | EA1: 1000 | EB1: 1000 | EC1: 1000 | ED1: 1000 | EE1: 1000 | EF1: 1000 | EG1: 1000 | EH1: 1000 | EI1: 1000 | EJ1: 1000 | EK1: 1000 | EL1: 1000 | EM1: 1000 | EN1: 1000 | EO1: 830 | FA1: Total No of line items | FC1: 293 | FI1: =_xlfn.XLOOKUP(FI$9,'PO Delivery Schedule'!$A$3:$A$41,'PO Delivery Schedule'!$N$3:$N$41) -> 3000 | FJ1: =_xlfn.XLOOKUP(FJ$9,'PO Delivery Schedule'!$A$3:$A$41,'PO Delivery Schedule'!$N$3:$N$41) -> 3000 | FK1: =_xlfn.XLOOKUP(FK$9,'PO Delivery Schedule'!$A$3:$A$41,'PO Delivery Schedule'!$N$3:$N$41) -> 3000 | FL1: =_xlfn.XLOOKUP(FL$9,'PO Delivery Schedule'!$A$3:$A$41,'PO Delivery Schedule'!$N$3:$N$41) -> 3000 | FM1: =_xlfn.XLOOKUP(FM$9,'PO Delivery Schedule'!$A$3:$A$41,'PO Delivery Schedule'!$N$3:$N$41) -> 3000 | FN1: =_xlfn.XLOOKUP(FN$9,'PO Delivery Schedule'!$A$3:$A$41,'PO Delivery Schedule'!$N$3:$N$41) -> 3000 | FO1: =_xlfn.XLOOKUP(FO$9,'PO Delivery Schedule'!$A$3:$A$41,'PO Delivery Schedule'!$N$3:$N$41) -> 3000 | FP1: =_xlfn.XLOOKUP(FP$9,'PO Delivery Schedule'!$A$3:$A$41,'PO Delivery Schedule'!$N$3:$N$41) -> 3000 | ... FU1: =_xlfn.XLOOKUP(FU$9,'PO Delivery Schedule'!$A$3:$A$41,'PO Delivery Schedule'!$N$3:$N$41) -> 0 | FV1: =SUM(FI1:FU1) -> 35198 | IJ1: Final Supplier | IK1: No of Line items
A2: DTRM | P2: 1 | Q2: 1 | R2: 1 | S2: 1 | T2: 1 | U2: 1 | V2: 1 | W2: 1 | X2: 1 | CT2: PA DTRM | CU2: =SUM(CV2:EO2) -> 35180 | DB2: 100 | DC2: 200 | DD2: 300 | DE2: 550 | DF2: 700 | DG2: 750 | DH2: 750 | DI2: 750 | DJ2: 750 | DK2: 750 | DL2: 750 | DM2: 1000 | DN2: 1000 | DO2: 1000 | DP2: 1000 | DQ2: 1000 | DR2: 1000 | DS2: 1000 | DT2: 1000 | DU2: 1000 | DV2: 1000 | DW2: 1000 | DX2: 1000 | DY2: 1000 | DZ2: 1000 | EA2: 1000 | EB2: 1000 | EC2: 1000 | ED2: 1000 | EE2: 1000 | EF2: 1000 | EG2: 1000 | EH2: 1000 | EI2: 1000 | EJ2: 1000 | EK2: 1000 | EL2: 1000 | EM2: 1000 | EN2: 1000 | EO2: 830 | FA2: Assy | FC2: 18 | FI2: =_xlfn.XLOOKUP(FI$9,'PO Delivery Schedule'!$A$3:$A$41,'PO Delivery Schedule'!$O$3:$O$41) -> 3000 | FJ2: =_xlfn.XLOOKUP(FJ$9,'PO Delivery Schedule'!$A$3:$A$41,'PO Delivery Schedule'!$O$3:$O$41) -> 3000 | FK2: =_xlfn.XLOOKUP(FK$9,'PO Delivery Schedule'!$A$3:$A$41,'PO Delivery Schedule'!$O$3:$O$41) -> 3000 | FL2: =_xlfn.XLOOKUP(FL$9,'PO Delivery Schedule'!$A$3:$A$41,'PO Delivery Schedule'!$O$3:$O$41) -> 3000 | FM2: =_xlfn.XLOOKUP(FM$9,'PO Delivery Schedule'!$A$3:$A$41,'PO Delivery Schedule'!$O$3:$O$41) -> 3000 | FN2: =_xlfn.XLOOKUP(FN$9,'PO Delivery Schedule'!$A$3:$A$41,'PO Delivery Schedule'!$O$3:$O$41) -> 3000 | FO2: =_xlfn.XLOOKUP(FO$9,'PO Delivery Schedule'!$A$3:$A$41,'PO Delivery Schedule'!$O$3:$O$41) -> 3000 | FP2: =_xlfn.XLOOKUP(FP$9,'PO Delivery Schedule'!$A$3:$A$41,'PO Delivery Schedule'!$O$3:$O$41) -> 3000 | ... FU2: =_xlfn.XLOOKUP(FU$9,'PO Delivery Schedule'!$A$3:$A$41,'PO Delivery Schedule'!$O$3:$O$41) -> 0 | FV2: =SUM(FI2:FU2) -> 34788 | IJ2: PRONAT | IK2: 1
A3: DAD | Y3: 1 | Z3: 1 | AA3: 1 | AB3: 1 | AC3: 1 | AD3: 1 | AE3: 1 | AF3: 1 | AG3: 1 | CT3: CONTROLLER DTRM | CU3: =SUM(CV3:EO3) -> 35180 | DB3: 100 | DC3: 200 | DD3: 300 | DE3: 550 | DF3: 700 | DG3: 750 | DH3: 750 | DI3: 750 | DJ3: 750 | DK3: 750 | DL3: 750 | DM3: 1000 | DN3: 1000 | DO3: 1000 | DP3: 1000 | DQ3: 1000 | DR3: 1000 | DS3: 1000 | DT3: 1000 | DU3: 1000 | DV3: 1000 | DW3: 1000 | DX3: 1000 | DY3: 1000 | DZ3: 1000 | EA3: 1000 | EB3: 1000 | EC3: 1000 | ED3: 1000 | EE3: 1000 | EF3: 1000 | EG3: 1000 | EH3: 1000 | EI3: 1000 | EJ3: 1000 | EK3: 1000 | EL3: 1000 | EM3: 1000 | EN3: 1000 | EO3: 830 | ET3: USD | EU3: 1 | FA3: BFE | FC3: 10 | FI3: =_xlfn.XLOOKUP(FI$9,'PO Delivery Schedule'!$A$3:$A$41,'PO Delivery Schedule'!$P$3:$P$41) -> 65 | FJ3: =_xlfn.XLOOKUP(FJ$9,'PO Delivery Schedule'!$A$3:$A$41,'PO Delivery Schedule'!$P$3:$P$41) -> 65 | FK3: =_xlfn.XLOOKUP(FK$9,'PO Delivery Schedule'!$A$3:$A$41,'PO Delivery Schedule'!$P$3:$P$41) -> 65 | FL3: =_xlfn.XLOOKUP(FL$9,'PO Delivery Schedule'!$A$3:$A$41,'PO Delivery Schedule'!$P$3:$P$41) -> 65 | FM3: =_xlfn.XLOOKUP(FM$9,'PO Delivery Schedule'!$A$3:$A$41,'PO Delivery Schedule'!$P$3:$P$41) -> 65 | FN3: =_xlfn.XLOOKUP(FN$9,'PO Delivery Schedule'!$A$3:$A$41,'PO Delivery Schedule'!$P$3:$P$41) -> 65 | FO3: =_xlfn.XLOOKUP(FO$9,'PO Delivery Schedule'!$A$3:$A$41,'PO Delivery Schedule'!$P$3:$P$41) -> 65 | FP3: =_xlfn.XLOOKUP(FP$9,'PO Delivery Schedule'!$A$3:$A$41,'PO Delivery Schedule'!$P$3:$P$41) -> 65 | ... FU3: =_xlfn.XLOOKUP(FU$9,'PO Delivery Schedule'!$A$3:$A$41,'PO Delivery Schedule'!$P$3:$P$41) -> 0 | FV3: =SUM(FI3:FU3) -> 635 | IJ3: ARROW RAPAC | IK3: 2
A4: Spares | M4: 1 | N4: 1 | O4: 1 | R4: 1 | S4: 1 | T4: 1 | U4: 1 | V4: 1 | X4: 1 | CT4: DRM FINAL ASSY | CU4: =SUM(CV4:EO4) -> 34778 | DB4: 100 | DC4: 200 | DD4: 300 | DE4: 550 | DF4: 700 | DG4: 750 | DH4: 750 | DI4: 750 | DJ4: 750 | DK4: 750 | DL4: 750 | DM4: 1000 | DN4: 1000 | DO4: 1000 | DP4: 1000 | DQ4: 1000 | DR4: 1000 | DS4: 1000 | DT4: 1000 | DU4: 1000 | DV4: 1000 | DW4: 1000 | DX4: 1000 | DY4: 1000 | DZ4: 1000 | EA4: 1000 | EB4: 1000 | EC4: 1000 | ED4: 1000 | EE4: 1000 | EF4: 1000 | EG4: 1000 | EH4: 1000 | EI4: 1000 | EJ4: 1000 | EK4: 1000 | EL4: 1000 | EM4: 1000 | EN4: 1000 | EO4: 428 | ET4: GBP | EU4: 1.3 | FA4: DNP | FC4: 8 | FE4: DD Received | FF4: Payment | FG4: Clarifications | FH4: DD yet to receive | FI4: =_xlfn.XLOOKUP(FI$9,'PO Delivery Schedule'!$A$3:$A$41,'PO Delivery Schedule'!$Q$3:$Q$41) -> 0 | FJ4: =_xlfn.XLOOKUP(FJ$9,'PO Delivery Schedule'!$A$3:$A$41,'PO Delivery Schedule'!$Q$3:$Q$41) -> 0 | FK4: =_xlfn.XLOOKUP(FK$9,'PO Delivery Schedule'!$A$3:$A$41,'PO Delivery Schedule'!$Q$3:$Q$41) -> 0 | FL4: =_xlfn.XLOOKUP(FL$9,'PO Delivery Schedule'!$A$3:$A$41,'PO Delivery Schedule'!$Q$3:$Q$41) -> 0 | FM4: =_xlfn.XLOOKUP(FM$9,'PO Delivery Schedule'!$A$3:$A$41,'PO Delivery Schedule'!$Q$3:$Q$41) -> 0 | FN4: =_xlfn.XLOOKUP(FN$9,'PO Delivery Schedule'!$A$3:$A$41,'PO Delivery Schedule'!$Q$3:$Q$41) -> 0 | FO4: =_xlfn.XLOOKUP(FO$9,'PO Delivery Schedule'!$A$3:$A$41,'PO Delivery Schedule'!$Q$3:$Q$41) -> 0 | FP4: =_xlfn.XLOOKUP(FP$9,'PO Delivery Schedule'!$A$3:$A$41,'PO Delivery Schedule'!$Q$3:$Q$41) -> 0 | ... FU4: =_xlfn.XLOOKUP(FU$9,'PO Delivery Schedule'!$A$3:$A$41,'PO Delivery Schedule'!$Q$3:$Q$41) -> 0 | FV4: =SUM(FI4:FU4) -> 30 | IC4: Total | IJ4: Kemograph | IK4: 1
CT5: RX CARD DRM | CU5: =SUM(CV5:EO5) -> 34778 | DB5: 100 | DC5: 200 | DD5: 300 | DE5: 550 | DF5: 700 | DG5: 750 | DH5: 750 | DI5: 750 | DJ5: 750 | DK5: 750 | DL5: 750 | DM5: 1000 | DN5: 1000 | DO5: 1000 | DP5: 1000 | DQ5: 1000 | DR5: 1000 | DS5: 1000 | DT5: 1000 | DU5: 1000 | DV5: 1000 | DW5: 1000 | DX5: 1000 | DY5: 1000 | DZ5: 1000 | EA5: 1000 | EB5: 1000 | EC5: 1000 | ED5: 1000 | EE5: 1000 | EF5: 1000 | EG5: 1000 | EH5: 1000 | EI5: 1000 | EJ5: 1000 | EK5: 1000 | EL5: 1000 | EM5: 1000 | EN5: 1000 | EO5: 428 | ET5: EUR | EU5: 1.12 | FA5: Ordered | FC5: 232 | FD5: Components | FE5: 204 | FF5: 10 | FG5: 15 | FH5: =FC5-FE5-FF5-FG5 -> 3 | IC5: =SUM(FE5:FH5) -> 232
A6: 42 | J6: QTY | K6: 35198 | L6: 35198 | M6: 35228 | N6: 35228 | O6: 35228 | P6: 34788 | Q6: 34788 | R6: 34818 | S6: 34818 | T6: 34818 | U6: 34818 | V6: 34818 | W6: 34788 | X6: 34818 | Y6: 635 | Z6: 635 | AA6: 635 | AB6: 635 | AC6: 635 | AD6: 635 | AE6: 635 | AF6: 635 | AG6: 635 | CT6: CONTROLLER DRM | CU6: =SUM(CV6:EO6) -> 34778 | DB6: 100 | DC6: 200 | DD6: 300 | DE6: 550 | DF6: 700 | DG6: 750 | DH6: 750 | DI6: 750 | DJ6: 750 | DK6: 750 | DL6: 750 | DM6: 1000 | DN6: 1000 | DO6: 1000 | DP6: 1000 | DQ6: 1000 | DR6: 1000 | DS6: 1000 | DT6: 1000 | DU6: 1000 | DV6: 1000 | DW6: 1000 | DX6: 1000 | DY6: 1000 | DZ6: 1000 | EA6: 1000 | EB6: 1000 | EC6: 1000 | ED6: 1000 | EE6: 1000 | EF6: 1000 | EG6: 1000 | EH6: 1000 | EI6: 1000 | EJ6: 1000 | EK6: 1000 | EL6: 1000 | EM6: 1000 | EN6: 1000 | EO6: 428 | ET6: INR | EU6: =1/83 -> 0.012048193 | FA6: Ordered-Partially | FC6: 10 | FD6: Consumable | FE6: 7 | FH6: =FC6-FE6-FF6-FG6 -> 3 | IC6: =SUM(FE6:FH6) -> 10
A7: 1 | J7: COUNT | K7: =COUNTIF(K11:K304,">0") -> 4 | L7: =COUNTIF(L11:L304,">0") -> 33 | M7: =COUNTIF(M11:M304,">0") -> 13 | N7: =COUNTIF(N11:N304,">0") -> 47 | O7: =COUNTIF(O11:O304,">0") -> 100 | P7: =COUNTIF(P11:P304,">0") -> 4 | Q7: =COUNTIF(Q11:Q304,">0") -> 33 | R7: =COUNTIF(R11:R304,">0") -> 30 | ... AG7: =COUNTIF(AG11:AG304,">0") -> 101 | CT7: DAD FINAL ASSY | CU7: =SUM(CV7:EO7) -> 631 | DB7: 100 | DC7: 200 | DD7: 331 | FA7: Ordered-clarifications | FC7: 5 | FD7: Price clarifications
J8: DESC | K8: =VLOOKUP(K10,$C$11:$F$303,4,) -> DRM F/ASSY | L8: =VLOOKUP(L10,$C$11:$F$303,4,) -> DRM ASSY | M8: =VLOOKUP(M10,$C$11:$F$303,4,) -> DRM PS ASSY RX | N8: =VLOOKUP(N10,$C$11:$F$303,4,) -> DRM RX ASSY | O8: =VLOOKUP(O10,$C$11:$F$303,4,) -> PC ASSY DRM CONTROLER NG 400 | P8: =VLOOKUP(P10,$C$11:$F$303,4,) -> DTRM F/ASSY | Q8: =VLOOKUP(Q10,$C$11:$F$303,4,) -> DTRM F/ASSY | R8: =VLOOKUP(R10,$C$11:$F$303,4,) -> DTRM POWER AMP ASSY | ... AG8: =VLOOKUP(AG10,$C$11:$F$303,4,) -> PC ASSY CONTROLLER 400 | BF8: ETA | CT8: PA DAD | CU8: =SUM(CV8:EO8) -> 631 | DB8: 100 | DC8: 200 | DD8: 331 | FA8: TBD | FC8: 10 | FI8: Required | FW8: Considering SPQ | GK8: Amount Considering SPQ | GZ8: Final Ordering | HN8: Final Ordering Amount
J9: BOM LEVAL | K9: 0 | L9: 1 | M9: 2 | N9: 3 | O9: 2 | P9: 0 | Q9: 1 | R9: 2 | S9: 3 | T9: 4 | U9: 3 | V9: 3 | W9: 2 | X9: 2 | Y9: 0 | Z9: 1 | AA9: 2 | AB9: 3 | AC9: 4 | AD9: 3 | AE9: 3 | AF9: 2 | AG9: 2 | BA9: DCX DEATAILS | CT9: CONTROLLER DAD | CU9: =SUM(CV9:EO9) -> 631 | DB9: 100 | DC9: 200 | DD9: 331 | FA9: Total | FC9: =SUM(FC2:FC8) -> 293 | FI9: 45566 | FJ9: 45717 | FK9: =EDATE(FJ9,3) -> 45809 | FL9: =EDATE(FK9,3) -> 45901 | FM9: =EDATE(FL9,3) -> 45992 | FN9: =EDATE(FM9,3) -> 46082 | FO9: =EDATE(FN9,3) -> 46174 | FP9: =EDATE(FO9,3) -> 46266 | FQ9: =EDATE(FP9,3) -> 46357 | FR9: =EDATE(FQ9,3) -> 46447 | ... FU9: =EDATE(FT9,3) -> 46722 | FW9: 45566 | FX9: 45717 | FY9: =EDATE(FX9,3) -> 45809 | FZ9: =EDATE(FY9,3) -> 45901 | GA9: =EDATE(FZ9,3) -> 45992 | GB9: =EDATE(GA9,3) -> 46082 | GC9: =EDATE(GB9,3) -> 46174 | GD9: =EDATE(GC9,3) -> 46266 | GE9: =EDATE(GD9,3) -> 46357 | GF9: =EDATE(GE9,3) -> 46447 | ... GI9: =EDATE(GH9,3) -> 46722 | GK9: 45566 | GL9: 45717 | GM9: =EDATE(GL9,3) -> 45809 | GN9: =EDATE(GM9,3) -> 45901 | GO9: =EDATE(GN9,3) -> 45992 | GP9: =EDATE(GO9,3) -> 46082 | GQ9: =EDATE(GP9,3) -> 46174 | GR9: =EDATE(GQ9,3) -> 46266 | GS9: =EDATE(GR9,3) -> 46357 | GT9: =EDATE(GS9,3) -> 46447 | ... GW9: =EDATE(GV9,3) -> 46722 | GZ9: 45566 | HA9: 45717 | HB9: =EDATE(HA9,3) -> 45809 | HC9: =EDATE(HB9,3) -> 45901 | HD9: =EDATE(HC9,3) -> 45992 | HE9: =EDATE(HD9,3) -> 46082 | HF9: =EDATE(HE9,3) -> 46174 | HG9: =EDATE(HF9,3) -> 46266 | HH9: =EDATE(HG9,3) -> 46357 | HI9: =EDATE(HH9,3) -> 46447 | ... HL9: =EDATE(HK9,3) -> 46722 | HN9: 45566 | HO9: 45717 | HP9: =EDATE(HO9,3) -> 45809 | HQ9: =EDATE(HP9,3) -> 45901 | HR9: =EDATE(HQ9,3) -> 45992 | HS9: =EDATE(HR9,3) -> 46082 | HT9: =EDATE(HS9,3) -> 46174 | HU9: =EDATE(HT9,3) -> 46266 | HV9: =EDATE(HU9,3) -> 46357 | HW9: =EDATE(HV9,3) -> 46447 | ... HZ9: =EDATE(HY9,3) -> 46722
A10: # | C10: PN_ID | D10: REV | E10: CATALOG | F10: DESCRIPTION | G10: FFF CLASS | H10: UOM | I10: SUG_MLAI | J10: ORIG_QTY | K10: 1096M150-001 | L10: 1096M155-001 | M10: 1096M156-001 | N10: 1096M160-001 | O10: 1094T037-001 | P10: 1096M130-001 | Q10: 1096M135-001 | R10: 1096M136-001 | S10: 1096M140-001 | T10: 1094Y038-001 | U10: 1094N754-001 | V10: 1093G277-001 | W10: 1093N746-001 | X10: 1094N790-003 | Y10: 1096M170-001 | Z10: 1096M175-001 | AA10: 1096M176-001 | AB10: 1096M180-001 | AC10: 1094Y038-001 | AD10: 1094N754-001 | AE10: 1093G277-001 | AF10: 1093N746-001 | AG10: 1094N790-003 | AH10: SUM | AI10: QTY/DRM | AJ10: QTY/DTRM | AK10: QTY/DAD | AL10: QTY/Spares | AM10: TOTAL QTY | AN10: MPQ | AO10: CELLING | AP10: NOTES | AQ10: MFG | AR10: SUPPLIER | AS10: DCX Remarks | AT10: Indian Supllier | AU10: FINAL PRICE | AV10: CUR | AW10: POC/NAME | AX10: E-MAIL | AY10: E-MAIL | AZ10: PHONE # | BA10: PO # | BB10: ACTUAL PRICE | BC10: L.T in Wks | BD10: QTY # | BE10: STOCK | BF10: 45474 | BG10: 45505 | BH10: 45536 | BI10: 45566 | BJ10: 45597 | BK10: 45627 | BL10: 45658 | BM10: 45689 | BN10: 45717 | BO10: 45748 | BP10: 45778 | BQ10: 45809 | BR10: 45839 | BS10: 45870 | BT10: 45901 | BU10: 45931 | BV10: 45962 | BW10: 45992 | BX10: 46023 | BY10: 46054 | BZ10: 46082 | CA10: 46113 | CB10: 46143 | CC10: 46174 | CD10: 46204 | CE10: 46235 | CF10: 46266 | CG10: 46296 | CH10: 46327 | CI10: 46357 | CJ10: 46388 | CK10: 46419 | CL10: 46447 | CM10: 46478 | CN10: 46508 | CO10: 46539 | CP10: 46569 | CQ10: 46600 | CR10: 46631 | CS10: 46661 | CT10: PLAN | CU10: SUM | CV10: 45474 | CW10: 45505 | CX10: 45536 | CY10: 45566 | CZ10: 45597 | DA10: 45627 | DB10: 45658 | DC10: 45689 | DD10: 45717 | DE10: 45748 | DF10: 45778 | DG10: 45809 | DH10: 45839 | DI10: 45870 | DJ10: 45901 | DK10: 45931 | DL10: 45962 | DM10: 45992 | DN10: 46023 | DO10: 46054 | DP10: 46082 | DQ10: 46113 | DR10: 46143 | DS10: 46174 | DT10: 46204 | DU10: 46235 | DV10: 46266 | DW10: 46296 | DX10: 46327 | DY10: 46357 | DZ10: 46388 | EA10: 46419 | EB10: 46447 | EC10: 46478 | ED10: 46508 | EE10: 46539 | EF10: 46569 | EG10: 46600 | EH10: 46631 | EI10: 46661 | EJ10: 46692 | EK10: 46722 | EL10: 46753 | EM10: 46784 | EN10: 46813 | EO10: 46844 | EP10: Final Supplier | EQ10: Final P/N | ER10: Final Make | ES10: Final Price | ET10: Final CNY | EU10: CCR to USD | EV10: Final Price in USD | EW10: SPQ | EX10: MOQ | EY10: Additional QTY to Order | EZ10: Total Order QTY | FA10: Total Order Amount $ | FB10: Surplus QTY | FC10: Amount for Surplus QTY $ | FD10: Approval Date | FE10: Approved By | FF10: Remarks | FG10: Finalised | FH10: Order to be placed by | FI10: 1 | FJ10: 2 | FK10: =FJ10+1 -> 3 | FL10: =FK10+1 -> 4 | FM10: =FL10+1 -> 5 | FN10: =FM10+1 -> 6 | FO10: =FN10+1 -> 7 | FP10: =FO10+1 -> 8 | FQ10: =FP10+1 -> 9 | FR10: =FQ10+1 -> 10 | ... FU10: =FT10+1 -> 13 | FV10: X | FW10: 1 | FX10: 2 | FY10: =FX10+1 -> 3 | FZ10: =FY10+1 -> 4 | GA10: =FZ10+1 -> 5 | GB10: =GA10+1 -> 6 | GC10: =GB10+1 -> 7 | GD10: =GC10+1 -> 8 | GE10: =GD10+1 -> 9 | GF10: =GE10+1 -> 10 | ... GI10: =GH10+1 -> 13 | GJ10: X | GK10: 1 | GL10: 2 | GM10: =GL10+1 -> 3 | GN10: =GM10+1 -> 4 | GO10: =GN10+1 -> 5 | GP10: =GO10+1 -> 6 | GQ10: =GP10+1 -> 7 | GR10: =GQ10+1 -> 8 | GS10: =GR10+1 -> 9 | GT10: =GS10+1 -> 10 | ... GW10: =GV10+1 -> 13 | GX10: Total | GY10: Split Lot | GZ10: 1 | HA10: 2 | HB10: =HA10+1 -> 3 | HC10: =HB10+1 -> 4 | HD10: =HC10+1 -> 5 | HE10: =HD10+1 -> 6 | HF10: =HE10+1 -> 7 | HG10: =HF10+1 -> 8 | HH10: =HG10+1 -> 9 | HI10: =HH10+1 -> 10 | ... HL10: =HK10+1 -> 13 | HM10: X | HN10: 1 | HO10: 2 | HP10: =HO10+1 -> 3 | HQ10: =HP10+1 -> 4 | HR10: =HQ10+1 -> 5 | HS10: =HR10+1 -> 6 | HT10: =HS10+1 -> 7 | HU10: =HT10+1 -> 8 | HV10: =HU10+1 -> 9 | HW10: =HV10+1 -> 10 | ... HZ10: =HY10+1 -> 13 | IA10: Total | IC10: PO number | ID10: PO Date | IE10: OA | IF10: Payment | IG10: DD | IH10: Remarks | II10: COO
A11: 1 | B11: LT01-289 | C11: 1096M130-001 | D11: - | E11: 410977392 | F11: DTRM F/ASSY | H11: EA | I11: 1 | J11: 1 | K11: 0 | L11: 0 | M11: 0 | N11: 0 | O11: 0 | P11: 1 | Q11: 0 | R11: 0 | S11: 0 | T11: 0 | U11: 0 | V11: 0 | W11: 0 | X11: 0 | Y11: 0 | Z11: 0 | AA11: 0 | AB11: 0 | AC11: 0 | AD11: 0 | AE11: 0 | AF11: 0 | AG11: 0 | AH11: =SUM(K11:AB11) -> 1 | AI11: =SUMPRODUCT($K$1:$AG$1,$K11:$AG11) -> 0 | AJ11: =SUMPRODUCT($K$2:$AG$2,$K11:$AG11) -> 1 | AK11: =SUMPRODUCT($K$3:$AG$3,$K11:$AG11) -> 0 | AL11: =SUMPRODUCT($K$4:$AG$4,$K11:$AG11) -> 0 | AM11: =SUMPRODUCT(K11:AG11,$K$6:$AG$6) -> 34788 | AN11: 1 | AO11: =CEILING(AM11,AN11) -> 34788 | AP11: ASSY | AQ11: ASSY | BA11: =IC11 -> 0 | BB11: =EV11 -> #NAME? | BD11: =EZ11 -> 34788 | CW11: =SUM($BE11,$BF11:BF11)-SUM($CV$1:CW$1)*SUM($P11:$Q11,$W11)-SUM($CV$2:CW$2)*SUM($R11:$V11)-SUM($CV$3:CW$3)*$X11-SUM($CV$4:CW$4)*SUM($K11:$L11)-SUM($CV$5:CW$5)*SUM($M11:$N11)-SUM($CV$6:CW$6)*$O11-SUM($CV$7:CW$7)*SUM($Y11:$Z11,$AF11)-SUM($CV$8:CW$8)*SUM($AA11:$AE11)-SUM($CV$9:CW$9)*$AG11 -> 0 | CX11: =SUM($BE11,$BF11:BG11)-SUM($CV$1:CX$1)*SUM($P11:$Q11,$W11)-SUM($CV$2:CX$2)*SUM($R11:$V11)-SUM($CV$3:CX$3)*$X11-SUM($CV$4:CX$4)*SUM($K11:$L11)-SUM($CV$5:CX$5)*SUM($M11:$N11)-SUM($CV$6:CX$6)*$O11-SUM($CV$7:CX$7)*SUM($Y11:$Z11,$AF11)-SUM($CV$8:CX$8)*SUM($AA11:$AE11)-SUM($CV$9:CX$9)*$AG11 -> 0 | CY11: =SUM($BE11,$BF11:BH11)-SUM($CV$1:CY$1)*SUM($P11:$Q11,$W11)-SUM($CV$2:CY$2)*SUM($R11:$V11)-SUM($CV$3:CY$3)*$X11-SUM($CV$4:CY$4)*SUM($K11:$L11)-SUM($CV$5:CY$5)*SUM($M11:$N11)-SUM($CV$6:CY$6)*$O11-SUM($CV$7:CY$7)*SUM($Y11:$Z11,$AF11)-SUM($CV$8:CY$8)*SUM($AA11:$AE11)-SUM($CV$9:CY$9)*$AG11 -> 0 | CZ11: =SUM($BE11,$BF11:BI11)-SUM($CV$1:CZ$1)*SUM($P11:$Q11,$W11)-SUM($CV$2:CZ$2)*SUM($R11:$V11)-SUM($CV$3:CZ$3)*$X11-SUM($CV$4:CZ$4)*SUM($K11:$L11)-SUM($CV$5:CZ$5)*SUM($M11:$N11)-SUM($CV$6:CZ$6)*$O11-SUM($CV$7:CZ$7)*SUM($Y11:$Z11,$AF11)-SUM($CV$8:CZ$8)*SUM($AA11:$AE11)-SUM($CV$9:CZ$9)*$AG11 -> 0 | DA11: =SUM($BE11,$BF11:BJ11)-SUM($CV$1:DA$1)*SUM($P11:$Q11,$W11)-SUM($CV$2:DA$2)*SUM($R11:$V11)-SUM($CV$3:DA$3)*$X11-SUM($CV$4:DA$4)*SUM($K11:$L11)-SUM($CV$5:DA$5)*SUM($M11:$N11)-SUM($CV$6:DA$6)*$O11-SUM($CV$7:DA$7)*SUM($Y11:$Z11,$AF11)-SUM($CV$8:DA$8)*SUM($AA11:$AE11)-SUM($CV$9:DA$9)*$AG11 -> 0 | DB11: =SUM($BE11,$BF11:BK11)-SUM($CV$1:DB$1)*SUM($P11:$Q11,$W11)-SUM($CV$2:DB$2)*SUM($R11:$V11)-SUM($CV$3:DB$3)*$X11-SUM($CV$4:DB$4)*SUM($K11:$L11)-SUM($CV$5:DB$5)*SUM($M11:$N11)-SUM($CV$6:DB$6)*$O11-SUM($CV$7:DB$7)*SUM($Y11:$Z11,$AF11)-SUM($CV$8:DB$8)*SUM($AA11:$AE11)-SUM($CV$9:DB$9)*$AG11 -> -100 | DC11: =SUM($BE11,$BF11:BL11)-SUM($CV$1:DC$1)*SUM($P11:$Q11,$W11)-SUM($CV$2:DC$2)*SUM($R11:$V11)-SUM($CV$3:DC$3)*$X11-SUM($CV$4:DC$4)*SUM($K11:$L11)-SUM($CV$5:DC$5)*SUM($M11:$N11)-SUM($CV$6:DC$6)*$O11-SUM($CV$7:DC$7)*SUM($Y11:$Z11,$AF11)-SUM($CV$8:DC$8)*SUM($AA11:$AE11)-SUM($CV$9:DC$9)*$AG11 -> -300 | DD11: =SUM($BE11,$BF11:BM11)-SUM($CV$1:DD$1)*SUM($P11:$Q11,$W11)-SUM($CV$2:DD$2)*SUM($R11:$V11)-SUM($CV$3:DD$3)*$X11-SUM($CV$4:DD$4)*SUM($K11:$L11)-SUM($CV$5:DD$5)*SUM($M11:$N11)-SUM($CV$6:DD$6)*$O11-SUM($CV$7:DD$7)*SUM($Y11:$Z11,$AF11)-SUM($CV$8:DD$8)*SUM($AA11:$AE11)-SUM($CV$9:DD$9)*$AG11 -> -600 | ... EO11: =SUM($BE11,$BF11:CX11)-SUM($CV$1:EO$1)*SUM($P11:$Q11,$W11)-SUM($CV$2:EO$2)*SUM($R11:$V11)-SUM($CV$3:EO$3)*$X11-SUM($CV$4:EO$4)*SUM($K11:$L11)-SUM($CV$5:EO$5)*SUM($M11:$N11)-SUM($CV$6:EO$6)*$O11-SUM($CV$7:EO$7)*SUM($Y11:$Z11,$AF11)-SUM($CV$8:EO$8)*SUM($AA11:$AE11)-SUM($CV$9:EO$9)*$AG11 -> -35180 | EP11: ASSY | EQ11: =C11 -> 1096M130-001 | ER11: =AQ11 -> ASSY | ES11: =AU11 -> 0 | ET11: =AV11 -> 0 | EU11: =_xlfn.XLOOKUP(ET11,ET$3:ET$6,EU$3:EU$6,0) -> #NAME? | EV11: =ES11*EU11 -> #NAME? | EW11: =AN11 -> 1 | EX11: =AN11 -> 1 | EZ11: =MAX(EX11,CEILING(AM11+EY11,EW11)) -> 34788 | FA11: =EZ11*EV11 -> #NAME? | FB11: =EZ11-AM11 -> 0 | FC11: =FB11*EV11 -> #NAME? | FD11: 45523 | FE11: Sagi | FF11: ASSY | FI11: {=SUMPRODUCT($AI11:$AL11,TRANSPOSE(FI$1:FI$4))} -> 3000 | FJ11: {=SUMPRODUCT($AI11:$AL11,TRANSPOSE(FJ$1:FJ$4))} -> 3000 | FK11: {=SUMPRODUCT($AI11:$AL11,TRANSPOSE(FK$1:FK$4))} -> 3000 | FL11: {=SUMPRODUCT($AI11:$AL11,TRANSPOSE(FL$1:FL$4))} -> 3000 | FM11: {=SUMPRODUCT($AI11:$AL11,TRANSPOSE(FM$1:FM$4))} -> 3000 | FN11: {=SUMPRODUCT($AI11:$AL11,TRANSPOSE(FN$1:FN$4))} -> 3000 | FO11: {=SUMPRODUCT($AI11:$AL11,TRANSPOSE(FO$1:FO$4))} -> 3000 | FP11: {=SUMPRODUCT($AI11:$AL11,TRANSPOSE(FP$1:FP$4))} -> 3000 | ... FU11: {=SUMPRODUCT($AI11:$AL11,TRANSPOSE(FU$1:FU$4))} -> 0 | FW11: =CEILING(FI11,$EW11) -> 3000 | FX11: =CEILING(SUM($FI11:FJ11)-SUM($FW11:FW11),$EW11) -> 3000 | FY11: =CEILING(SUM($FI11:FK11)-SUM($FW11:FX11),$EW11) -> 3000 | FZ11: =CEILING(SUM($FI11:FL11)-SUM($FW11:FY11),$EW11) -> 3000 | GA11: =CEILING(SUM($FI11:FM11)-SUM($FW11:FZ11),$EW11) -> 3000 | GB11: =CEILING(SUM($FI11:FN11)-SUM($FW11:GA11),$EW11) -> 3000 | GC11: =CEILING(SUM($FI11:FO11)-SUM($FW11:GB11),$EW11) -> 3000 | GD11: =CEILING(SUM($FI11:FP11)-SUM($FW11:GC11),$EW11) -> 3000 | GE11: =CEILING(SUM($FI11:FQ11)-SUM($FW11:GD11),$EW11) -> 3000 | ... GG11: =CEILING(SUM($FI11:FS11)-SUM($FW11:GF11),$EW11) -> 3000 | GH11: =EZ11-SUM(FW11:GG11) -> 1788 | GI11: =EZ11-SUM(FW11:GH11) -> 0 | GK11: =FW11*$EV11 -> #NAME? | GL11: =FX11*$EV11 -> #NAME? | GM11: =FY11*$EV11 -> #NAME? | GN11: =FZ11*$EV11 -> #NAME? | GO11: =GA11*$EV11 -> #NAME? | GP11: =GB11*$EV11 -> #NAME? | GQ11: =GC11*$EV11 -> #NAME? | GR11: =GD11*$EV11 -> #NAME? | ... GW11: =GI11*$EV11 -> #NAME? | GX11: =SUM(GK11:GW11) -> #NAME? | HL11: =GI11 -> 0 | HN11: =GZ11*$EV11 -> #NAME? | HO11: =HA11*$EV11 -> #NAME? | HP11: =HB11*$EV11 -> #NAME? | HQ11: =HC11*$EV11 -> #NAME? | HR11: =HD11*$EV11 -> #NAME? | HS11: =HE11*$EV11 -> #NAME? | HT11: =HF11*$EV11 -> #NAME? | HU11: =HG11*$EV11 -> #NAME? | ... HZ11: =HL11*$EV11 -> #NAME? | IA11: =SUM(HN11:HZ11) -> #NAME? | IB11: LT01-289
A12: 2 | B12: LT01-290 | C12: 1096M150-001 | D12: - | E12: 410977469 | F12: DRM F/ASSY | H12: EA | I12: 1 | J12: 1 | K12: 1 | L12: 0 | M12: 0 | N12: 0 | O12: 0 | P12: 0 | Q12: 0 | R12: 0 | S12: 0 | T12: 0 | U12: 0 | V12: 0 | W12: 0 | X12: 0 | Y12: 0 | Z12: 0 | AA12: 0 | AB12: 0 | AC12: 0 | AD12: 0 | AE12: 0 | AF12: 0 | AG12: 0 | AH12: =SUM(K12:AB12) -> 1 | AI12: =SUMPRODUCT($K$1:$AG$1,$K12:$AG12) -> 1 | AJ12: =SUMPRODUCT($K$2:$AG$2,$K12:$AG12) -> 0 | AK12: =SUMPRODUCT($K$3:$AG$3,$K12:$AG12) -> 0 | AL12: =SUMPRODUCT($K$4:$AG$4,$K12:$AG12) -> 0 | AM12: =SUMPRODUCT(K12:AG12,$K$6:$AG$6) -> 35198 | AN12: 1 | AO12: =CEILING(AM12,AN12) -> 35198 | AP12: ASSY | AQ12: ASSY | BA12: =IC12 -> 0 | BB12: =EV12 -> #NAME? | BD12: =EZ12 -> 35198 | CW12: =SUM($BE12,$BF12:BF12)-SUM($CV$1:CW$1)*SUM($P12:$Q12,$W12)-SUM($CV$2:CW$2)*SUM($R12:$V12)-SUM($CV$3:CW$3)*$X12-SUM($CV$4:CW$4)*SUM($K12:$L12)-SUM($CV$5:CW$5)*SUM($M12:$N12)-SUM($CV$6:CW$6)*$O12-SUM($CV$7:CW$7)*SUM($Y12:$Z12,$AF12)-SUM($CV$8:CW$8)*SUM($AA12:$AE12)-SUM($CV$9:CW$9)*$AG12 -> 0 | CX12: =SUM($BE12,$BF12:BG12)-SUM($CV$1:CX$1)*SUM($P12:$Q12,$W12)-SUM($CV$2:CX$2)*SUM($R12:$V12)-SUM($CV$3:CX$3)*$X12-SUM($CV$4:CX$4)*SUM($K12:$L12)-SUM($CV$5:CX$5)*SUM($M12:$N12)-SUM($CV$6:CX$6)*$O12-SUM($CV$7:CX$7)*SUM($Y12:$Z12,$AF12)-SUM($CV$8:CX$8)*SUM($AA12:$AE12)-SUM($CV$9:CX$9)*$AG12 -> 0 | CY12: =SUM($BE12,$BF12:BH12)-SUM($CV$1:CY$1)*SUM($P12:$Q12,$W12)-SUM($CV$2:CY$2)*SUM($R12:$V12)-SUM($CV$3:CY$3)*$X12-SUM($CV$4:CY$4)*SUM($K12:$L12)-SUM($CV$5:CY$5)*SUM($M12:$N12)-SUM($CV$6:CY$6)*$O12-SUM($CV$7:CY$7)*SUM($Y12:$Z12,$AF12)-SUM($CV$8:CY$8)*SUM($AA12:$AE12)-SUM($CV$9:CY$9)*$AG12 -> 0 | CZ12: =SUM($BE12,$BF12:BI12)-SUM($CV$1:CZ$1)*SUM($P12:$Q12,$W12)-SUM($CV$2:CZ$2)*SUM($R12:$V12)-SUM($CV$3:CZ$3)*$X12-SUM($CV$4:CZ$4)*SUM($K12:$L12)-SUM($CV$5:CZ$5)*SUM($M12:$N12)-SUM($CV$6:CZ$6)*$O12-SUM($CV$7:CZ$7)*SUM($Y12:$Z12,$AF12)-SUM($CV$8:CZ$8)*SUM($AA12:$AE12)-SUM($CV$9:CZ$9)*$AG12 -> 0 | DA12: =SUM($BE12,$BF12:BJ12)-SUM($CV$1:DA$1)*SUM($P12:$Q12,$W12)-SUM($CV$2:DA$2)*SUM($R12:$V12)-SUM($CV$3:DA$3)*$X12-SUM($CV$4:DA$4)*SUM($K12:$L12)-SUM($CV$5:DA$5)*SUM($M12:$N12)-SUM($CV$6:DA$6)*$O12-SUM($CV$7:DA$7)*SUM($Y12:$Z12,$AF12)-SUM($CV$8:DA$8)*SUM($AA12:$AE12)-SUM($CV$9:DA$9)*$AG12 -> 0 | DB12: =SUM($BE12,$BF12:BK12)-SUM($CV$1:DB$1)*SUM($P12:$Q12,$W12)-SUM($CV$2:DB$2)*SUM($R12:$V12)-SUM($CV$3:DB$3)*$X12-SUM($CV$4:DB$4)*SUM($K12:$L12)-SUM($CV$5:DB$5)*SUM($M12:$N12)-SUM($CV$6:DB$6)*$O12-SUM($CV$7:DB$7)*SUM($Y12:$Z12,$AF12)-SUM($CV$8:DB$8)*SUM($AA12:$AE12)-SUM($CV$9:DB$9)*$AG12 -> -100 | DC12: =SUM($BE12,$BF12:BL12)-SUM($CV$1:DC$1)*SUM($P12:$Q12,$W12)-SUM($CV$2:DC$2)*SUM($R12:$V12)-SUM($CV$3:DC$3)*$X12-SUM($CV$4:DC$4)*SUM($K12:$L12)-SUM($CV$5:DC$5)*SUM($M12:$N12)-SUM($CV$6:DC$6)*$O12-SUM($CV$7:DC$7)*SUM($Y12:$Z12,$AF12)-SUM($CV$8:DC$8)*SUM($AA12:$AE12)-SUM($CV$9:DC$9)*$AG12 -> -300 | DD12: =SUM($BE12,$BF12:BM12)-SUM($CV$1:DD$1)*SUM($P12:$Q12,$W12)-SUM($CV$2:DD$2)*SUM($R12:$V12)-SUM($CV$3:DD$3)*$X12-SUM($CV$4:DD$4)*SUM($K12:$L12)-SUM($CV$5:DD$5)*SUM($M12:$N12)-SUM($CV$6:DD$6)*$O12-SUM($CV$7:DD$7)*SUM($Y12:$Z12,$AF12)-SUM($CV$8:DD$8)*SUM($AA12:$AE12)-SUM($CV$9:DD$9)*$AG12 -> -600 | ... EO12: =SUM($BE12,$BF12:CX12)-SUM($CV$1:EO$1)*SUM($P12:$Q12,$W12)-SUM($CV$2:EO$2)*SUM($R12:$V12)-SUM($CV$3:EO$3)*$X12-SUM($CV$4:EO$4)*SUM($K12:$L12)-SUM($CV$5:EO$5)*SUM($M12:$N12)-SUM($CV$6:EO$6)*$O12-SUM($CV$7:EO$7)*SUM($Y12:$Z12,$AF12)-SUM($CV$8:EO$8)*SUM($AA12:$AE12)-SUM($CV$9:EO$9)*$AG12 -> -34778 | EP12: ASSY | EQ12: =C12 -> 1096M150-001 | ER12: =AQ12 -> ASSY | ES12: =AU12 -> 0 | ET12: =AV12 -> 0 | EU12: =_xlfn.XLOOKUP(ET12,ET$3:ET$6,EU$3:EU$6,0) -> #NAME? | EV12: =ES12*EU12 -> #NAME? | EW12: =AN12 -> 1 | EX12: =AN12 -> 1 | EZ12: =MAX(EX12,CEILING(AM12+EY12,EW12)) -> 35198 | FA12: =EZ12*EV12 -> #NAME? | FB12: =EZ12-AM12 -> 0 | FC12: =FB12*EV12 -> #NAME? | FD12: 45523 | FE12: Sagi | FF12: ASSY | FI12: {=SUMPRODUCT($AI12:$AL12,TRANSPOSE(FI$1:FI$4))} -> 3000 | FJ12: {=SUMPRODUCT($AI12:$AL12,TRANSPOSE(FJ$1:FJ$4))} -> 3000 | FK12: {=SUMPRODUCT($AI12:$AL12,TRANSPOSE(FK$1:FK$4))} -> 3000 | FL12: {=SUMPRODUCT($AI12:$AL12,TRANSPOSE(FL$1:FL$4))} -> 3000 | FM12: {=SUMPRODUCT($AI12:$AL12,TRANSPOSE(FM$1:FM$4))} -> 3000 | FN12: {=SUMPRODUCT($AI12:$AL12,TRANSPOSE(FN$1:FN$4))} -> 3000 | FO12: {=SUMPRODUCT($AI12:$AL12,TRANSPOSE(FO$1:FO$4))} -> 3000 | FP12: {=SUMPRODUCT($AI12:$AL12,TRANSPOSE(FP$1:FP$4))} -> 3000 | ... FU12: {=SUMPRODUCT($AI12:$AL12,TRANSPOSE(FU$1:FU$4))} -> 0 | FW12: =CEILING(FI12,$EW12) -> 3000 | FX12: =CEILING(SUM($FI12:FJ12)-SUM($FW12:FW12),$EW12) -> 3000 | FY12: =CEILING(SUM($FI12:FK12)-SUM($FW12:FX12),$EW12) -> 3000 | FZ12: =CEILING(SUM($FI12:FL12)-SUM($FW12:FY12),$EW12) -> 3000 | GA12: =CEILING(SUM($FI12:FM12)-SUM($FW12:FZ12),$EW12) -> 3000 | GB12: =CEILING(SUM($FI12:FN12)-SUM($FW12:GA12),$EW12) -> 3000 | GC12: =CEILING(SUM($FI12:FO12)-SUM($FW12:GB12),$EW12) -> 3000 | GD12: =CEILING(SUM($FI12:FP12)-SUM($FW12:GC12),$EW12) -> 3000 | GE12: =CEILING(SUM($FI12:FQ12)-SUM($FW12:GD12),$EW12) -> 3000 | ... GG12: =CEILING(SUM($FI12:FS12)-SUM($FW12:GF12),$EW12) -> 3000 | GH12: =EZ12-SUM(FW12:GG12) -> 2198 | GI12: =EZ12-SUM(FW12:GH12) -> 0 | GK12: =FW12*$EV12 -> #NAME? | GL12: =FX12*$EV12 -> #NAME? | GM12: =FY12*$EV12 -> #NAME? | GN12: =FZ12*$EV12 -> #NAME? | GO12: =GA12*$EV12 -> #NAME? | GP12: =GB12*$EV12 -> #NAME? | GQ12: =GC12*$EV12 -> #NAME? | GR12: =GD12*$EV12 -> #NAME? | ... GW12: =GI12*$EV12 -> #NAME? | GX12: =SUM(GK12:GW12) -> #NAME? | HL12: =GI12 -> 0 | HN12: =GZ12*$EV12 -> #NAME? | HO12: =HA12*$EV12 -> #NAME? | HP12: =HB12*$EV12 -> #NAME? | HQ12: =HC12*$EV12 -> #NAME? | HR12: =HD12*$EV12 -> #NAME? | HS12: =HE12*$EV12 -> #NAME? | HT12: =HF12*$EV12 -> #NAME? | HU12: =HG12*$EV12 -> #NAME? | ... HZ12: =HL12*$EV12 -> #NAME? | IA12: =SUM(HN12:HZ12) -> #NAME? | IB12: LT01-290
A13: 3 | B13: LT01-274 | C13: 1096M170-001 | D13: - | E13: 410977542 | F13: D.A.D. F/ASSY | H13: EA | I13: 1 | J13: 1 | K13: 0 | L13: 0 | M13: 0 | N13: 0 | O13: 0 | P13: 0 | Q13: 0 | R13: 0 | S13: 0 | T13: 0 | U13: 0 | V13: 0 | W13: 0 | X13: 0 | Y13: 1 | Z13: 0 | AA13: 0 | AB13: 0 | AC13: 0 | AD13: 0 | AE13: 0 | AF13: 0 | AG13: 0 | AH13: =SUM(K13:AB13) -> 1 | AI13: =SUMPRODUCT($K$1:$AG$1,$K13:$AG13) -> 0 | AJ13: =SUMPRODUCT($K$2:$AG$2,$K13:$AG13) -> 0 | AK13: =SUMPRODUCT($K$3:$AG$3,$K13:$AG13) -> 1 | AL13: =SUMPRODUCT($K$4:$AG$4,$K13:$AG13) -> 0 | AM13: =SUMPRODUCT(K13:AG13,$K$6:$AG$6) -> 635 | AN13: 1 | AO13: =CEILING(AM13,AN13) -> 635 | AP13: ASSY | AQ13: ASSY | BA13: =IC13 -> 0 | BB13: =EV13 -> #NAME? | BD13: =EZ13 -> 635 | CW13: =SUM($BE13,$BF13:BF13)-SUM($CV$1:CW$1)*SUM($P13:$Q13,$W13)-SUM($CV$2:CW$2)*SUM($R13:$V13)-SUM($CV$3:CW$3)*$X13-SUM($CV$4:CW$4)*SUM($K13:$L13)-SUM($CV$5:CW$5)*SUM($M13:$N13)-SUM($CV$6:CW$6)*$O13-SUM($CV$7:CW$7)*SUM($Y13:$Z13,$AF13)-SUM($CV$8:CW$8)*SUM($AA13:$AE13)-SUM($CV$9:CW$9)*$AG13 -> 0 | CX13: =SUM($BE13,$BF13:BG13)-SUM($CV$1:CX$1)*SUM($P13:$Q13,$W13)-SUM($CV$2:CX$2)*SUM($R13:$V13)-SUM($CV$3:CX$3)*$X13-SUM($CV$4:CX$4)*SUM($K13:$L13)-SUM($CV$5:CX$5)*SUM($M13:$N13)-SUM($CV$6:CX$6)*$O13-SUM($CV$7:CX$7)*SUM($Y13:$Z13,$AF13)-SUM($CV$8:CX$8)*SUM($AA13:$AE13)-SUM($CV$9:CX$9)*$AG13 -> 0 | CY13: =SUM($BE13,$BF13:BH13)-SUM($CV$1:CY$1)*SUM($P13:$Q13,$W13)-SUM($CV$2:CY$2)*SUM($R13:$V13)-SUM($CV$3:CY$3)*$X13-SUM($CV$4:CY$4)*SUM($K13:$L13)-SUM($CV$5:CY$5)*SUM($M13:$N13)-SUM($CV$6:CY$6)*$O13-SUM($CV$7:CY$7)*SUM($Y13:$Z13,$AF13)-SUM($CV$8:CY$8)*SUM($AA13:$AE13)-SUM($CV$9:CY$9)*$AG13 -> 0 | CZ13: =SUM($BE13,$BF13:BI13)-SUM($CV$1:CZ$1)*SUM($P13:$Q13,$W13)-SUM($CV$2:CZ$2)*SUM($R13:$V13)-SUM($CV$3:CZ$3)*$X13-SUM($CV$4:CZ$4)*SUM($K13:$L13)-SUM($CV$5:CZ$5)*SUM($M13:$N13)-SUM($CV$6:CZ$6)*$O13-SUM($CV$7:CZ$7)*SUM($Y13:$Z13,$AF13)-SUM($CV$8:CZ$8)*SUM($AA13:$AE13)-SUM($CV$9:CZ$9)*$AG13 -> 0 | DA13: =SUM($BE13,$BF13:BJ13)-SUM($CV$1:DA$1)*SUM($P13:$Q13,$W13)-SUM($CV$2:DA$2)*SUM($R13:$V13)-SUM($CV$3:DA$3)*$X13-SUM($CV$4:DA$4)*SUM($K13:$L13)-SUM($CV$5:DA$5)*SUM($M13:$N13)-SUM($CV$6:DA$6)*$O13-SUM($CV$7:DA$7)*SUM($Y13:$Z13,$AF13)-SUM($CV$8:DA$8)*SUM($AA13:$AE13)-SUM($CV$9:DA$9)*$AG13 -> 0 | DB13: =SUM($BE13,$BF13:BK13)-SUM($CV$1:DB$1)*SUM($P13:$Q13,$W13)-SUM($CV$2:DB$2)*SUM($R13:$V13)-SUM($CV$3:DB$3)*$X13-SUM($CV$4:DB$4)*SUM($K13:$L13)-SUM($CV$5:DB$5)*SUM($M13:$N13)-SUM($CV$6:DB$6)*$O13-SUM($CV$7:DB$7)*SUM($Y13:$Z13,$AF13)-SUM($CV$8:DB$8)*SUM($AA13:$AE13)-SUM($CV$9:DB$9)*$AG13 -> -100 | DC13: =SUM($BE13,$BF13:BL13)-SUM($CV$1:DC$1)*SUM($P13:$Q13,$W13)-SUM($CV$2:DC$2)*SUM($R13:$V13)-SUM($CV$3:DC$3)*$X13-SUM($CV$4:DC$4)*SUM($K13:$L13)-SUM($CV$5:DC$5)*SUM($M13:$N13)-SUM($CV$6:DC$6)*$O13-SUM($CV$7:DC$7)*SUM($Y13:$Z13,$AF13)-SUM($CV$8:DC$8)*SUM($AA13:$AE13)-SUM($CV$9:DC$9)*$AG13 -> -300 | DD13: =SUM($BE13,$BF13:BM13)-SUM($CV$1:DD$1)*SUM($P13:$Q13,$W13)-SUM($CV$2:DD$2)*SUM($R13:$V13)-SUM($CV$3:DD$3)*$X13-SUM($CV$4:DD$4)*SUM($K13:$L13)-SUM($CV$5:DD$5)*SUM($M13:$N13)-SUM($CV$6:DD$6)*$O13-SUM($CV$7:DD$7)*SUM($Y13:$Z13,$AF13)-SUM($CV$8:DD$8)*SUM($AA13:$AE13)-SUM($CV$9:DD$9)*$AG13 -> -631 | ... EO13: =SUM($BE13,$BF13:CX13)-SUM($CV$1:EO$1)*SUM($P13:$Q13,$W13)-SUM($CV$2:EO$2)*SUM($R13:$V13)-SUM($CV$3:EO$3)*$X13-SUM($CV$4:EO$4)*SUM($K13:$L13)-SUM($CV$5:EO$5)*SUM($M13:$N13)-SUM($CV$6:EO$6)*$O13-SUM($CV$7:EO$7)*SUM($Y13:$Z13,$AF13)-SUM($CV$8:EO$8)*SUM($AA13:$AE13)-SUM($CV$9:EO$9)*$AG13 -> -631 | EP13: ASSY | EQ13: =C13 -> 1096M170-001 | ER13: =AQ13 -> ASSY | ES13: =AU13 -> 0 | ET13: =AV13 -> 0 | EU13: =_xlfn.XLOOKUP(ET13,ET$3:ET$6,EU$3:EU$6,0) -> #NAME? | EV13: =ES13*EU13 -> #NAME? | EW13: =AN13 -> 1 | EX13: =AN13 -> 1 | EZ13: =MAX(EX13,CEILING(AM13+EY13,EW13)) -> 635 | FA13: =EZ13*EV13 -> #NAME? | FB13: =EZ13-AM13 -> 0 | FC13: =FB13*EV13 -> #NAME? | FD13: 45523 | FE13: Sagi | FF13: ASSY | FI13: {=SUMPRODUCT($AI13:$AL13,TRANSPOSE(FI$1:FI$4))} -> 65 | FJ13: {=SUMPRODUCT($AI13:$AL13,TRANSPOSE(FJ$1:FJ$4))} -> 65 | FK13: {=SUMPRODUCT($AI13:$AL13,TRANSPOSE(FK$1:FK$4))} -> 65 | FL13: {=SUMPRODUCT($AI13:$AL13,TRANSPOSE(FL$1:FL$4))} -> 65 | FM13: {=SUMPRODUCT($AI13:$AL13,TRANSPOSE(FM$1:FM$4))} -> 65 | FN13: {=SUMPRODUCT($AI13:$AL13,TRANSPOSE(FN$1:FN$4))} -> 65 | FO13: {=SUMPRODUCT($AI13:$AL13,TRANSPOSE(FO$1:FO$4))} -> 65 | FP13: {=SUMPRODUCT($AI13:$AL13,TRANSPOSE(FP$1:FP$4))} -> 65 | ... FU13: {=SUMPRODUCT($AI13:$AL13,TRANSPOSE(FU$1:FU$4))} -> 0 | FW13: =CEILING(FI13,$EW13) -> 65 | FX13: =CEILING(SUM($FI13:FJ13)-SUM($FW13:FW13),$EW13) -> 65 | FY13: =CEILING(SUM($FI13:FK13)-SUM($FW13:FX13),$EW13) -> 65 | FZ13: =CEILING(SUM($FI13:FL13)-SUM($FW13:FY13),$EW13) -> 65 | GA13: =CEILING(SUM($FI13:FM13)-SUM($FW13:FZ13),$EW13) -> 65 | GB13: =CEILING(SUM($FI13:FN13)-SUM($FW13:GA13),$EW13) -> 65 | GC13: =CEILING(SUM($FI13:FO13)-SUM($FW13:GB13),$EW13) -> 65 | GD13: =CEILING(SUM($FI13:FP13)-SUM($FW13:GC13),$EW13) -> 65 | GE13: =CEILING(SUM($FI13:FQ13)-SUM($FW13:GD13),$EW13) -> 65 | ... GG13: =CEILING(SUM($FI13:FS13)-SUM($FW13:GF13),$EW13) -> 0 | GH13: =EZ13-SUM(FW13:GG13) -> 0 | GI13: =EZ13-SUM(FW13:GH13) -> 0 | GK13: =FW13*$EV13 -> #NAME? | GL13: =FX13*$EV13 -> #NAME? | GM13: =FY13*$EV13 -> #NAME? | GN13: =FZ13*$EV13 -> #NAME? | GO13: =GA13*$EV13 -> #NAME? | GP13: =GB13*$EV13 -> #NAME? | GQ13: =GC13*$EV13 -> #NAME? | GR13: =GD13*$EV13 -> #NAME? | ... GW13: =GI13*$EV13 -> #NAME? | GX13: =SUM(GK13:GW13) -> #NAME? | HL13: =GI13 -> 0 | HN13: =GZ13*$EV13 -> #NAME? | HO13: =HA13*$EV13 -> #NAME? | HP13: =HB13*$EV13 -> #NAME? | HQ13: =HC13*$EV13 -> #NAME? | HR13: =HD13*$EV13 -> #NAME? | HS13: =HE13*$EV13 -> #NAME? | HT13: =HF13*$EV13 -> #NAME? | HU13: =HG13*$EV13 -> #NAME? | ... HZ13: =HL13*$EV13 -> #NAME? | IA13: =SUM(HN13:HZ13) -> #NAME? | IB13: LT01-274
A14: 4 | B14: LT01-003 | C14: 000800-0826 | D14: BUY1 | E14: 400550300 | F14: CONN RECT PCB R/A PLUG 42 BLADES 3 ROWS, | G14: 404421765 | H14: EA | I14: 2 | J14: 3 | K14: 0 | L14: 0 | M14: 0 | N14: 0 | O14: 1 | P14: 0 | Q14: 0 | R14: 0 | S14: 0 | T14: 0 | U14: 0 | V14: 0 | W14: 0 | X14: 1 | Y14: 0 | Z14: 0 | AA14: 0 | AB14: 0 | AC14: 0 | AD14: 0 | AE14: 0 | AF14: 0 | AG14: 1 | AH14: =SUM(K14:AB14) -> 2 | AI14: =SUMPRODUCT($K$1:$AG$1,$K14:$AG14) -> 1 | AJ14: =SUMPRODUCT($K$2:$AG$2,$K14:$AG14) -> 1 | AK14: =SUMPRODUCT($K$3:$AG$3,$K14:$AG14) -> 1 | AL14: =SUMPRODUCT($K$4:$AG$4,$K14:$AG14) -> 2 | AM14: =SUMPRODUCT(K14:AG14,$K$6:$AG$6) -> 70681 | AN14: 1 | AO14: =CEILING(AM14,AN14) -> 70681 | AQ14: DCX-CHOL Entr. Inc | AR14: Masterite | AU14: 23 | AV14: USD | AW14: Elad Zafrir | AX14: elad.zafrir@emet.co.il | AZ14: 972-54-302-7334 | BA14: =IC14 -> P0011 | BB14: =EV14 -> #NAME? | BD14: =EZ14 -> 70731 | BL14: 3000 | CW14: =SUM($BE14,$BF14:BF14)-SUM($CV$1:CW$1)*SUM($P14:$Q14,$W14)-SUM($CV$2:CW$2)*SUM($R14:$V14)-SUM($CV$3:CW$3)*$X14-SUM($CV$4:CW$4)*SUM($K14:$L14)-SUM($CV$5:CW$5)*SUM($M14:$N14)-SUM($CV$6:CW$6)*$O14-SUM($CV$7:CW$7)*SUM($Y14:$Z14,$AF14)-SUM($CV$8:CW$8)*SUM($AA14:$AE14)-SUM($CV$9:CW$9)*$AG14 -> 0 | CX14: =SUM($BE14,$BF14:BG14)-SUM($CV$1:CX$1)*SUM($P14:$Q14,$W14)-SUM($CV$2:CX$2)*SUM($R14:$V14)-SUM($CV$3:CX$3)*$X14-SUM($CV$4:CX$4)*SUM($K14:$L14)-SUM($CV$5:CX$5)*SUM($M14:$N14)-SUM($CV$6:CX$6)*$O14-SUM($CV$7:CX$7)*SUM($Y14:$Z14,$AF14)-SUM($CV$8:CX$8)*SUM($AA14:$AE14)-SUM($CV$9:CX$9)*$AG14 -> 0 | CY14: =SUM($BE14,$BF14:BH14)-SUM($CV$1:CY$1)*SUM($P14:$Q14,$W14)-SUM($CV$2:CY$2)*SUM($R14:$V14)-SUM($CV$3:CY$3)*$X14-SUM($CV$4:CY$4)*SUM($K14:$L14)-SUM($CV$5:CY$5)*SUM($M14:$N14)-SUM($CV$6:CY$6)*$O14-SUM($CV$7:CY$7)*SUM($Y14:$Z14,$AF14)-SUM($CV$8:CY$8)*SUM($AA14:$AE14)-SUM($CV$9:CY$9)*$AG14 -> 0 | CZ14: =SUM($BE14,$BF14:BI14)-SUM($CV$1:CZ$1)*SUM($P14:$Q14,$W14)-SUM($CV$2:CZ$2)*SUM($R14:$V14)-SUM($CV$3:CZ$3)*$X14-SUM($CV$4:CZ$4)*SUM($K14:$L14)-SUM($CV$5:CZ$5)*SUM($M14:$N14)-SUM($CV$6:CZ$6)*$O14-SUM($CV$7:CZ$7)*SUM($Y14:$Z14,$AF14)-SUM($CV$8:CZ$8)*SUM($AA14:$AE14)-SUM($CV$9:CZ$9)*$AG14 -> 0 | DA14: =SUM($BE14,$BF14:BJ14)-SUM($CV$1:DA$1)*SUM($P14:$Q14,$W14)-SUM($CV$2:DA$2)*SUM($R14:$V14)-SUM($CV$3:DA$3)*$X14-SUM($CV$4:DA$4)*SUM($K14:$L14)-SUM($CV$5:DA$5)*SUM($M14:$N14)-SUM($CV$6:DA$6)*$O14-SUM($CV$7:DA$7)*SUM($Y14:$Z14,$AF14)-SUM($CV$8:DA$8)*SUM($AA14:$AE14)-SUM($CV$9:DA$9)*$AG14 -> 0 | DB14: =SUM($BE14,$BF14:BK14)-SUM($CV$1:DB$1)*SUM($P14:$Q14,$W14)-SUM($CV$2:DB$2)*SUM($R14:$V14)-SUM($CV$3:DB$3)*$X14-SUM($CV$4:DB$4)*SUM($K14:$L14)-SUM($CV$5:DB$5)*SUM($M14:$N14)-SUM($CV$6:DB$6)*$O14-SUM($CV$7:DB$7)*SUM($Y14:$Z14,$AF14)-SUM($CV$8:DB$8)*SUM($AA14:$AE14)-SUM($CV$9:DB$9)*$AG14 -> -300 | DC14: =SUM($BE14,$BF14:BL14)-SUM($CV$1:DC$1)*SUM($P14:$Q14,$W14)-SUM($CV$2:DC$2)*SUM($R14:$V14)-SUM($CV$3:DC$3)*$X14-SUM($CV$4:DC$4)*SUM($K14:$L14)-SUM($CV$5:DC$5)*SUM($M14:$N14)-SUM($CV$6:DC$6)*$O14-SUM($CV$7:DC$7)*SUM($Y14:$Z14,$AF14)-SUM($CV$8:DC$8)*SUM($AA14:$AE14)-SUM($CV$9:DC$9)*$AG14 -> 2100 | DD14: =SUM($BE14,$BF14:BM14)-SUM($CV$1:DD$1)*SUM($P14:$Q14,$W14)-SUM($CV$2:DD$2)*SUM($R14:$V14)-SUM($CV$3:DD$3)*$X14-SUM($CV$4:DD$4)*SUM($K14:$L14)-SUM($CV$5:DD$5)*SUM($M14:$N14)-SUM($CV$6:DD$6)*$O14-SUM($CV$7:DD$7)*SUM($Y14:$Z14,$AF14)-SUM($CV$8:DD$8)*SUM($AA14:$AE14)-SUM($CV$9:DD$9)*$AG14 -> 1169 | ... EO14: =SUM($BE14,$BF14:CX14)-SUM($CV$1:EO$1)*SUM($P14:$Q14,$W14)-SUM($CV$2:EO$2)*SUM($R14:$V14)-SUM($CV$3:EO$3)*$X14-SUM($CV$4:EO$4)*SUM($K14:$L14)-SUM($CV$5:EO$5)*SUM($M14:$N14)-SUM($CV$6:EO$6)*$O14-SUM($CV$7:EO$7)*SUM($Y14:$Z14,$AF14)-SUM($CV$8:EO$8)*SUM($AA14:$AE14)-SUM($CV$9:EO$9)*$AG14 -> -67589 | EP14: =AR14 -> Masterite | EQ14: =C14 -> 000800-0826 | ER14: =AQ14 -> DCX-CHOL Entr. Inc | ES14: =AU14 -> 23 | ET14: =AV14 -> USD | EU14: =_xlfn.XLOOKUP(ET14,ET$3:ET$6,EU$3:EU$6,0) -> #NAME? | EV14: =ES14*EU14 -> #NAME? | EW14: =AN14 -> 1 | EX14: =AN14 -> 1 | EY14: 50 | EZ14: =MAX(EX14,CEILING(AM14+EY14,EW14)) -> 70731 | FA14: =EZ14*EV14 -> #NAME? | FB14: =EZ14-AM14 -> 50 | FC14: =FB14*EV14 -> #NAME? | FD14: 45523 | FE14: Sagi | FF14: Ordered | FG14: Y | FH14: RNSE | FI14: {=SUMPRODUCT($AI14:$AL14,TRANSPOSE(FI$1:FI$4))} -> 6065 | FJ14: {=SUMPRODUCT($AI14:$AL14,TRANSPOSE(FJ$1:FJ$4))} -> 6065 | FK14: {=SUMPRODUCT($AI14:$AL14,TRANSPOSE(FK$1:FK$4))} -> 6065 | FL14: {=SUMPRODUCT($AI14:$AL14,TRANSPOSE(FL$1:FL$4))} -> 6065 | FM14: {=SUMPRODUCT($AI14:$AL14,TRANSPOSE(FM$1:FM$4))} -> 6065 | FN14: {=SUMPRODUCT($AI14:$AL14,TRANSPOSE(FN$1:FN$4))} -> 6065 | FO14: {=SUMPRODUCT($AI14:$AL14,TRANSPOSE(FO$1:FO$4))} -> 6065 | FP14: {=SUMPRODUCT($AI14:$AL14,TRANSPOSE(FP$1:FP$4))} -> 6065 | ... FU14: {=SUMPRODUCT($AI14:$AL14,TRANSPOSE(FU$1:FU$4))} -> 0 | FW14: =CEILING(FI14,$EW14) -> 6065 | FX14: =CEILING(SUM($FI14:FJ14)-SUM($FW14:FW14),$EW14) -> 6065 | FY14: =CEILING(SUM($FI14:FK14)-SUM($FW14:FX14),$EW14) -> 6065 | FZ14: =CEILING(SUM($FI14:FL14)-SUM($FW14:FY14),$EW14) -> 6065 | GA14: =CEILING(SUM($FI14:FM14)-SUM($FW14:FZ14),$EW14) -> 6065 | GB14: =CEILING(SUM($FI14:FN14)-SUM($FW14:GA14),$EW14) -> 6065 | GC14: =CEILING(SUM($FI14:FO14)-SUM($FW14:GB14),$EW14) -> 6065 | GD14: =CEILING(SUM($FI14:FP14)-SUM($FW14:GC14),$EW14) -> 6065 | GE14: =CEILING(SUM($FI14:FQ14)-SUM($FW14:GD14),$EW14) -> 6065 | ... GG14: =CEILING(SUM($FI14:FS14)-SUM($FW14:GF14),$EW14) -> 6000 | GH14: =EZ14-SUM(FW14:GG14) -> 4096 | GI14: =EZ14-SUM(FW14:GH14) -> 0 | GK14: =FW14*$EV14 -> #NAME? | GL14: =FX14*$EV14 -> #NAME? | GM14: =FY14*$EV14 -> #NAME? | GN14: =FZ14*$EV14 -> #NAME? | GO14: =GA14*$EV14 -> #NAME? | GP14: =GB14*$EV14 -> #NAME? | GQ14: =GC14*$EV14 -> #NAME? | GR14: =GD14*$EV14 -> #NAME? | ... GW14: =GI14*$EV14 -> #NAME? | GX14: =SUM(GK14:GW14) -> #NAME? | GY14: 12 | GZ14: =FW14 -> 6065 | HA14: =FX14 -> 6065 | HB14: =FY14 -> 6065 | HC14: =FZ14 -> 6065 | HD14: =GA14 -> 6065 | HE14: =GB14 -> 6065 | HF14: =GC14 -> 6065 | HG14: =GD14 -> 6065 | ... HL14: =GI14 -> 0 | HN14: =GZ14*$EV14 -> #NAME? | HO14: =HA14*$EV14 -> #NAME? | HP14: =HB14*$EV14 -> #NAME? | HQ14: =HC14*$EV14 -> #NAME? | HR14: =HD14*$EV14 -> #NAME? | HS14: =HE14*$EV14 -> #NAME? | HT14: =HF14*$EV14 -> #NAME? | HU14: =HG14*$EV14 -> #NAME? | ... HZ14: =HL14*$EV14 -> #NAME? | IA14: =SUM(HN14:HZ14) -> #NAME? | IB14: LT01-003 | IC14: P0011 | ID14: 45523 | IE14: Yes | IF14: Yes | IG14: Yes
A15: 5 | B15: LT01-004 | C15: 04021J0R3PBSTR | D15: BUY1 | E15: 401238835 | F15: CHIP CAP 0.3PF +-.02PF 100V T&R | H15: EA | I15: 2 | J15: 6 | K15: 0 | L15: 0 | M15: 0 | N15: 2 | O15: 0 | P15: 0 | Q15: 0 | R15: 0 | S15: 2 | T15: 0 | U15: 0 | V15: 0 | W15: 0 | X15: 0 | Y15: 0 | Z15: 0 | AA15: 0 | AB15: 2 | AC15: 0 | AD15: 0 | AE15: 0 | AF15: 0 | AG15: 0 | AH15: =SUM(K15:AB15) -> 6 | AI15: =SUMPRODUCT($K$1:$AG$1,$K15:$AG15) -> 2 | AJ15: =SUMPRODUCT($K$2:$AG$2,$K15:$AG15) -> 2 | AK15: =SUMPRODUCT($K$3:$AG$3,$K15:$AG15) -> 2 | AL15: =SUMPRODUCT($K$4:$AG$4,$K15:$AG15) -> 4 | AM15: =SUMPRODUCT(K15:AG15,$K$6:$AG$6) -> 141362 | AN15: 10000 | AO15: =CEILING(AM15,AN15) -> 150000 | AQ15: AVX | AR15: SHIRTECH | AU15: 0.18 | AV15: USD | AW15: LIZA COHEN | AX15: LIZA@SHIRTECH.CO.IL | AZ15: 972-3-9516495 | BA15: =IC15 -> P0037 | BB15: =EV15 -> #NAME? | BC15: 14 | BD15: =EZ15 -> 150000 | BK15: 80000 | BQ15: 70000 | CW15: =SUM($BE15,$BF15:BF15)-SUM($CV$1:CW$1)*SUM($P15:$Q15,$W15)-SUM($CV$2:CW$2)*SUM($R15:$V15)-SUM($CV$3:CW$3)*$X15-SUM($CV$4:CW$4)*SUM($K15:$L15)-SUM($CV$5:CW$5)*SUM($M15:$N15)-SUM($CV$6:CW$6)*$O15-SUM($CV$7:CW$7)*SUM($Y15:$Z15,$AF15)-SUM($CV$8:CW$8)*SUM($AA15:$AE15)-SUM($CV$9:CW$9)*$AG15 -> 0 | CX15: =SUM($BE15,$BF15:BG15)-SUM($CV$1:CX$1)*SUM($P15:$Q15,$W15)-SUM($CV$2:CX$2)*SUM($R15:$V15)-SUM($CV$3:CX$3)*$X15-SUM($CV$4:CX$4)*SUM($K15:$L15)-SUM($CV$5:CX$5)*SUM($M15:$N15)-SUM($CV$6:CX$6)*$O15-SUM($CV$7:CX$7)*SUM($Y15:$Z15,$AF15)-SUM($CV$8:CX$8)*SUM($AA15:$AE15)-SUM($CV$9:CX$9)*$AG15 -> 0 | CY15: =SUM($BE15,$BF15:BH15)-SUM($CV$1:CY$1)*SUM($P15:$Q15,$W15)-SUM($CV$2:CY$2)*SUM($R15:$V15)-SUM($CV$3:CY$3)*$X15-SUM($CV$4:CY$4)*SUM($K15:$L15)-SUM($CV$5:CY$5)*SUM($M15:$N15)-SUM($CV$6:CY$6)*$O15-SUM($CV$7:CY$7)*SUM($Y15:$Z15,$AF15)-SUM($CV$8:CY$8)*SUM($AA15:$AE15)-SUM($CV$9:CY$9)*$AG15 -> 0 | CZ15: =SUM($BE15,$BF15:BI15)-SUM($CV$1:CZ$1)*SUM($P15:$Q15,$W15)-SUM($CV$2:CZ$2)*SUM($R15:$V15)-SUM($CV$3:CZ$3)*$X15-SUM($CV$4:CZ$4)*SUM($K15:$L15)-SUM($CV$5:CZ$5)*SUM($M15:$N15)-SUM($CV$6:CZ$6)*$O15-SUM($CV$7:CZ$7)*SUM($Y15:$Z15,$AF15)-SUM($CV$8:CZ$8)*SUM($AA15:$AE15)-SUM($CV$9:CZ$9)*$AG15 -> 0 | DA15: =SUM($BE15,$BF15:BJ15)-SUM($CV$1:DA$1)*SUM($P15:$Q15,$W15)-SUM($CV$2:DA$2)*SUM($R15:$V15)-SUM($CV$3:DA$3)*$X15-SUM($CV$4:DA$4)*SUM($K15:$L15)-SUM($CV$5:DA$5)*SUM($M15:$N15)-SUM($CV$6:DA$6)*$O15-SUM($CV$7:DA$7)*SUM($Y15:$Z15,$AF15)-SUM($CV$8:DA$8)*SUM($AA15:$AE15)-SUM($CV$9:DA$9)*$AG15 -> 0 | DB15: =SUM($BE15,$BF15:BK15)-SUM($CV$1:DB$1)*SUM($P15:$Q15,$W15)-SUM($CV$2:DB$2)*SUM($R15:$V15)-SUM($CV$3:DB$3)*$X15-SUM($CV$4:DB$4)*SUM($K15:$L15)-SUM($CV$5:DB$5)*SUM($M15:$N15)-SUM($CV$6:DB$6)*$O15-SUM($CV$7:DB$7)*SUM($Y15:$Z15,$AF15)-SUM($CV$8:DB$8)*SUM($AA15:$AE15)-SUM($CV$9:DB$9)*$AG15 -> 79400 | DC15: =SUM($BE15,$BF15:BL15)-SUM($CV$1:DC$1)*SUM($P15:$Q15,$W15)-SUM($CV$2:DC$2)*SUM($R15:$V15)-SUM($CV$3:DC$3)*$X15-SUM($CV$4:DC$4)*SUM($K15:$L15)-SUM($CV$5:DC$5)*SUM($M15:$N15)-SUM($CV$6:DC$6)*$O15-SUM($CV$7:DC$7)*SUM($Y15:$Z15,$AF15)-SUM($CV$8:DC$8)*SUM($AA15:$AE15)-SUM($CV$9:DC$9)*$AG15 -> 78200 | DD15: =SUM($BE15,$BF15:BM15)-SUM($CV$1:DD$1)*SUM($P15:$Q15,$W15)-SUM($CV$2:DD$2)*SUM($R15:$V15)-SUM($CV$3:DD$3)*$X15-SUM($CV$4:DD$4)*SUM($K15:$L15)-SUM($CV$5:DD$5)*SUM($M15:$N15)-SUM($CV$6:DD$6)*$O15-SUM($CV$7:DD$7)*SUM($Y15:$Z15,$AF15)-SUM($CV$8:DD$8)*SUM($AA15:$AE15)-SUM($CV$9:DD$9)*$AG15 -> 76338 | ... EO15: =SUM($BE15,$BF15:CX15)-SUM($CV$1:EO$1)*SUM($P15:$Q15,$W15)-SUM($CV$2:EO$2)*SUM($R15:$V15)-SUM($CV$3:EO$3)*$X15-SUM($CV$4:EO$4)*SUM($K15:$L15)-SUM($CV$5:EO$5)*SUM($M15:$N15)-SUM($CV$6:EO$6)*$O15-SUM($CV$7:EO$7)*SUM($Y15:$Z15,$AF15)-SUM($CV$8:EO$8)*SUM($AA15:$AE15)-SUM($CV$9:EO$9)*$AG15 -> 8822 | EP15: PHONIX TECHNOLOGIES | EQ15: =C15 -> 04021J0R3PBSTR | ER15: =AQ15 -> AVX | ES15: 0.175 | ET15: =AV15 -> USD | EU15: =_xlfn.XLOOKUP(ET15,ET$3:ET$6,EU$3:EU$6,0) -> #NAME? | EV15: =ES15*EU15 -> #NAME? | EW15: =AN15 -> 10000 | EX15: =AN15 -> 10000 | EZ15: =MAX(EX15,CEILING(AM15+EY15,EW15)) -> 150000 | FA15: =EZ15*EV15 -> #NAME? | FB15: =EZ15-AM15 -> 8638 | FC15: =FB15*EV15 -> #NAME? | FD15: 45523 | FE15: Sagi | FF15: Ordered | FG15: Y | FH15: RNSE | FI15: {=SUMPRODUCT($AI15:$AL15,TRANSPOSE(FI$1:FI$4))} -> 12130 | FJ15: {=SUMPRODUCT($AI15:$AL15,TRANSPOSE(FJ$1:FJ$4))} -> 12130 | FK15: {=SUMPRODUCT($AI15:$AL15,TRANSPOSE(FK$1:FK$4))} -> 12130 | FL15: {=SUMPRODUCT($AI15:$AL15,TRANSPOSE(FL$1:FL$4))} -> 12130 | FM15: {=SUMPRODUCT($AI15:$AL15,TRANSPOSE(FM$1:FM$4))} -> 12130 | FN15: {=SUMPRODUCT($AI15:$AL15,TRANSPOSE(FN$1:FN$4))} -> 12130 | FO15: {=SUMPRODUCT($AI15:$AL15,TRANSPOSE(FO$1:FO$4))} -> 12130 | FP15: {=SUMPRODUCT($AI15:$AL15,TRANSPOSE(FP$1:FP$4))} -> 12130 | ... FU15: {=SUMPRODUCT($AI15:$AL15,TRANSPOSE(FU$1:FU$4))} -> 0 | FW15: =CEILING(FI15,$EW15) -> 20000 | FX15: =CEILING(SUM($FI15:FJ15)-SUM($FW15:FW15),$EW15) -> 10000 | FY15: =CEILING(SUM($FI15:FK15)-SUM($FW15:FX15),$EW15) -> 10000 | FZ15: =CEILING(SUM($FI15:FL15)-SUM($FW15:FY15),$EW15) -> 10000 | GA15: =CEILING(SUM($FI15:FM15)-SUM($FW15:FZ15),$EW15) -> 20000 | GB15: =CEILING(SUM($FI15:FN15)-SUM($FW15:GA15),$EW15) -> 10000 | GC15: =CEILING(SUM($FI15:FO15)-SUM($FW15:GB15),$EW15) -> 10000 | GD15: =CEILING(SUM($FI15:FP15)-SUM($FW15:GC15),$EW15) -> 10000 | GE15: =CEILING(SUM($FI15:FQ15)-SUM($FW15:GD15),$EW15) -> 10000 | ... GG15: =CEILING(SUM($FI15:FS15)-SUM($FW15:GF15),$EW15) -> 10000 | GH15: =EZ15-SUM(FW15:GG15) -> 10000 | GI15: =EZ15-SUM(FW15:GH15) -> 0 | GK15: =FW15*$EV15 -> #NAME? | GL15: =FX15*$EV15 -> #NAME? | GM15: =FY15*$EV15 -> #NAME? | GN15: =FZ15*$EV15 -> #NAME? | GO15: =GA15*$EV15 -> #NAME? | GP15: =GB15*$EV15 -> #NAME? | GQ15: =GC15*$EV15 -> #NAME? | GR15: =GD15*$EV15 -> #NAME? | ... GW15: =GI15*$EV15 -> #NAME? | GX15: =SUM(GK15:GW15) -> #NAME? | GY15: 2 | GZ15: =SUM(FW15:GB15) -> 80000 | HF15: =SUM(GC15:GI15) -> 70000 | HN15: =GZ15*$EV15 -> #NAME? | HO15: =HA15*$EV15 -> #NAME? | HP15: =HB15*$EV15 -> #NAME? | HQ15: =HC15*$EV15 -> #NAME? | HR15: =HD15*$EV15 -> #NAME? | HS15: =HE15*$EV15 -> #NAME? | HT15: =HF15*$EV15 -> #NAME? | HU15: =HG15*$EV15 -> #NAME? | ... HZ15: =HL15*$EV15 -> #NAME? | IA15: =SUM(HN15:HZ15) -> #NAME? | IB15: LT01-004 | IC15: P0037 | ID15: 45526 | IE15: Yes | IG15: Yes | II15: Israel
A16: 6 | B16: LT01-005 | C16: 0402CS-5N6XGRW | D16: BUY1 | E16: 408260904 | F16: INDUCTOR CHIP 5.6NH 2^ 0.76A 0402 T&R | H16: EA | I16: 1 | J16: 6 | K16: 0 | L16: 0 | M16: 0 | N16: 2 | O16: 0 | P16: 0 | Q16: 0 | R16: 0 | S16: 2 | T16: 0 | U16: 0 | V16: 0 | W16: 0 | X16: 0 | Y16: 0 | Z16: 0 | AA16: 0 | AB16: 2 | AC16: 0 | AD16: 0 | AE16: 0 | AF16: 0 | AG16: 0 | AH16: =SUM(K16:AB16) -> 6 | AI16: =SUMPRODUCT($K$1:$AG$1,$K16:$AG16) -> 2 | AJ16: =SUMPRODUCT($K$2:$AG$2,$K16:$AG16) -> 2 | AK16: =SUMPRODUCT($K$3:$AG$3,$K16:$AG16) -> 2 | AL16: =SUMPRODUCT($K$4:$AG$4,$K16:$AG16) -> 4 | AM16: =SUMPRODUCT(K16:AG16,$K$6:$AG$6) -> 141362 | AN16: 2000 | AO16: =CEILING(AM16,AN16) -> 142000 | AQ16: COILCRAFT INC. | AR16: ELINA | AU16: 0.072 | AV16: USD | AW16: Avi Elia | AX16: avi@elina.co.il | AZ16: 972.73.2224830 | BA16: =IC16 -> P0025 | BB16: =EV16 -> #NAME? | BC16: 7 | BD16: =EZ16 -> 142000 | BJ16: 142000 | CW16: =SUM($BE16,$BF16:BF16)-SUM($CV$1:CW$1)*SUM($P16:$Q16,$W16)-SUM($CV$2:CW$2)*SUM($R16:$V16)-SUM($CV$3:CW$3)*$X16-SUM($CV$4:CW$4)*SUM($K16:$L16)-SUM($CV$5:CW$5)*SUM($M16:$N16)-SUM($CV$6:CW$6)*$O16-SUM($CV$7:CW$7)*SUM($Y16:$Z16,$AF16)-SUM($CV$8:CW$8)*SUM($AA16:$AE16)-SUM($CV$9:CW$9)*$AG16 -> 0 | CX16: =SUM($BE16,$BF16:BG16)-SUM($CV$1:CX$1)*SUM($P16:$Q16,$W16)-SUM($CV$2:CX$2)*SUM($R16:$V16)-SUM($CV$3:CX$3)*$X16-SUM($CV$4:CX$4)*SUM($K16:$L16)-SUM($CV$5:CX$5)*SUM($M16:$N16)-SUM($CV$6:CX$6)*$O16-SUM($CV$7:CX$7)*SUM($Y16:$Z16,$AF16)-SUM($CV$8:CX$8)*SUM($AA16:$AE16)-SUM($CV$9:CX$9)*$AG16 -> 0 | CY16: =SUM($BE16,$BF16:BH16)-SUM($CV$1:CY$1)*SUM($P16:$Q16,$W16)-SUM($CV$2:CY$2)*SUM($R16:$V16)-SUM($CV$3:CY$3)*$X16-SUM($CV$4:CY$4)*SUM($K16:$L16)-SUM($CV$5:CY$5)*SUM($M16:$N16)-SUM($CV$6:CY$6)*$O16-SUM($CV$7:CY$7)*SUM($Y16:$Z16,$AF16)-SUM($CV$8:CY$8)*SUM($AA16:$AE16)-SUM($CV$9:CY$9)*$AG16 -> 0 | CZ16: =SUM($BE16,$BF16:BI16)-SUM($CV$1:CZ$1)*SUM($P16:$Q16,$W16)-SUM($CV$2:CZ$2)*SUM($R16:$V16)-SUM($CV$3:CZ$3)*$X16-SUM($CV$4:CZ$4)*SUM($K16:$L16)-SUM($CV$5:CZ$5)*SUM($M16:$N16)-SUM($CV$6:CZ$6)*$O16-SUM($CV$7:CZ$7)*SUM($Y16:$Z16,$AF16)-SUM($CV$8:CZ$8)*SUM($AA16:$AE16)-SUM($CV$9:CZ$9)*$AG16 -> 0 | DA16: =SUM($BE16,$BF16:BJ16)-SUM($CV$1:DA$1)*SUM($P16:$Q16,$W16)-SUM($CV$2:DA$2)*SUM($R16:$V16)-SUM($CV$3:DA$3)*$X16-SUM($CV$4:DA$4)*SUM($K16:$L16)-SUM($CV$5:DA$5)*SUM($M16:$N16)-SUM($CV$6:DA$6)*$O16-SUM($CV$7:DA$7)*SUM($Y16:$Z16,$AF16)-SUM($CV$8:DA$8)*SUM($AA16:$AE16)-SUM($CV$9:DA$9)*$AG16 -> 142000 | DB16: =SUM($BE16,$BF16:BK16)-SUM($CV$1:DB$1)*SUM($P16:$Q16,$W16)-SUM($CV$2:DB$2)*SUM($R16:$V16)-SUM($CV$3:DB$3)*$X16-SUM($CV$4:DB$4)*SUM($K16:$L16)-SUM($CV$5:DB$5)*SUM($M16:$N16)-SUM($CV$6:DB$6)*$O16-SUM($CV$7:DB$7)*SUM($Y16:$Z16,$AF16)-SUM($CV$8:DB$8)*SUM($AA16:$AE16)-SUM($CV$9:DB$9)*$AG16 -> 141400 | DC16: =SUM($BE16,$BF16:BL16)-SUM($CV$1:DC$1)*SUM($P16:$Q16,$W16)-SUM($CV$2:DC$2)*SUM($R16:$V16)-SUM($CV$3:DC$3)*$X16-SUM($CV$4:DC$4)*SUM($K16:$L16)-SUM($CV$5:DC$5)*SUM($M16:$N16)-SUM($CV$6:DC$6)*$O16-SUM($CV$7:DC$7)*SUM($Y16:$Z16,$AF16)-SUM($CV$8:DC$8)*SUM($AA16:$AE16)-SUM($CV$9:DC$9)*$AG16 -> 140200 | DD16: =SUM($BE16,$BF16:BM16)-SUM($CV$1:DD$1)*SUM($P16:$Q16,$W16)-SUM($CV$2:DD$2)*SUM($R16:$V16)-SUM($CV$3:DD$3)*$X16-SUM($CV$4:DD$4)*SUM($K16:$L16)-SUM($CV$5:DD$5)*SUM($M16:$N16)-SUM($CV$6:DD$6)*$O16-SUM($CV$7:DD$7)*SUM($Y16:$Z16,$AF16)-SUM($CV$8:DD$8)*SUM($AA16:$AE16)-SUM($CV$9:DD$9)*$AG16 -> 138338 | ... EO16: =SUM($BE16,$BF16:CX16)-SUM($CV$1:EO$1)*SUM($P16:$Q16,$W16)-SUM($CV$2:EO$2)*SUM($R16:$V16)-SUM($CV$3:EO$3)*$X16-SUM($CV$4:EO$4)*SUM($K16:$L16)-SUM($CV$5:EO$5)*SUM($M16:$N16)-SUM($CV$6:EO$6)*$O16-SUM($CV$7:EO$7)*SUM($Y16:$Z16,$AF16)-SUM($CV$8:EO$8)*SUM($AA16:$AE16)-SUM($CV$9:EO$9)*$AG16 -> 822 | EP16: coilcraft | EQ16: =C16 -> 0402CS-5N6XGRW | ER16: =AQ16 -> COILCRAFT INC. | ES16: =AU16 -> 0.072 | ET16: =AV16 -> USD | EU16: =_xlfn.XLOOKUP(ET16,ET$3:ET$6,EU$3:EU$6,0) -> #NAME? | EV16: =ES16*EU16 -> #NAME? | EW16: =AN16 -> 2000 | EX16: 10000 | EZ16: =MAX(EX16,CEILING(AM16+EY16,EW16)) -> 142000 | FA16: =EZ16*EV16 -> #NAME? | FB16: =EZ16-AM16 -> 638 | FC16: =FB16*EV16 -> #NAME? | FD16: 45523 | FE16: Sagi | FF16: Ordered | FG16: Y | FH16: RNSE | FI16: {=SUMPRODUCT($AI16:$AL16,TRANSPOSE(FI$1:FI$4))} -> 12130 | FJ16: {=SUMPRODUCT($AI16:$AL16,TRANSPOSE(FJ$1:FJ$4))} -> 12130 | FK16: {=SUMPRODUCT($AI16:$AL16,TRANSPOSE(FK$1:FK$4))} -> 12130 | FL16: {=SUMPRODUCT($AI16:$AL16,TRANSPOSE(FL$1:FL$4))} -> 12130 | FM16: {=SUMPRODUCT($AI16:$AL16,TRANSPOSE(FM$1:FM$4))} -> 12130 | FN16: {=SUMPRODUCT($AI16:$AL16,TRANSPOSE(FN$1:FN$4))} -> 12130 | FO16: {=SUMPRODUCT($AI16:$AL16,TRANSPOSE(FO$1:FO$4))} -> 12130 | FP16: {=SUMPRODUCT($AI16:$AL16,TRANSPOSE(FP$1:FP$4))} -> 12130 | ... FU16: {=SUMPRODUCT($AI16:$AL16,TRANSPOSE(FU$1:FU$4))} -> 0 | FW16: =CEILING(FI16,$EW16) -> 14000 | FX16: =CEILING(SUM($FI16:FJ16)-SUM($FW16:FW16),$EW16) -> 12000 | FY16: =CEILING(SUM($FI16:FK16)-SUM($FW16:FX16),$EW16) -> 12000 | FZ16: =CEILING(SUM($FI16:FL16)-SUM($FW16:FY16),$EW16) -> 12000 | GA16: =CEILING(SUM($FI16:FM16)-SUM($FW16:FZ16),$EW16) -> 12000 | GB16: =CEILING(SUM($FI16:FN16)-SUM($FW16:GA16),$EW16) -> 12000 | GC16: =CEILING(SUM($FI16:FO16)-SUM($FW16:GB16),$EW16) -> 12000 | GD16: =CEILING(SUM($FI16:FP16)-SUM($FW16:GC16),$EW16) -> 12000 | GE16: =CEILING(SUM($FI16:FQ16)-SUM($FW16:GD16),$EW16) -> 12000 | ... GG16: =CEILING(SUM($FI16:FS16)-SUM($FW16:GF16),$EW16) -> 12000 | GH16: =EZ16-SUM(FW16:GG16) -> 8000 | GI16: =EZ16-SUM(FW16:GH16) -> 0 | GK16: =FW16*$EV16 -> #NAME? | GL16: =FX16*$EV16 -> #NAME? | GM16: =FY16*$EV16 -> #NAME? | GN16: =FZ16*$EV16 -> #NAME? | GO16: =GA16*$EV16 -> #NAME? | GP16: =GB16*$EV16 -> #NAME? | GQ16: =GC16*$EV16 -> #NAME? | GR16: =GD16*$EV16 -> #NAME? | ... GW16: =GI16*$EV16 -> #NAME? | GX16: =SUM(GK16:GW16) -> #NAME? | GY16: 1 | GZ16: =SUM(FW16:GI16) -> 142000 | HL16: =GI16 -> 0 | HN16: =GZ16*$EV16 -> #NAME? | HO16: =HA16*$EV16 -> #NAME? | HP16: =HB16*$EV16 -> #NAME? | HQ16: =HC16*$EV16 -> #NAME? | HR16: =HD16*$EV16 -> #NAME? | HS16: =HE16*$EV16 -> #NAME? | HT16: =HF16*$EV16 -> #NAME? | HU16: =HG16*$EV16 -> #NAME? | ... HZ16: =HL16*$EV16 -> #NAME? | IA16: =SUM(HN16:HZ16) -> #NAME? | IB16: LT01-005 | IC16: P0025 | ID16: 45526 | IE16: Yes | IF16: Yes | IG16: Yes | II16: Indonesia / Malaysia / Vietnam
A17: 7 | B17: LT01-006 | C17: 0603CS-15NXGRW | D17: BUY1 | E17: 407184523 | F17: CHIP INDUCTOR 15NH 2^ T&R | H17: EA | I17: 1 | J17: 16 | K17: 0 | L17: 0 | M17: 0 | N17: 4 | O17: 0 | P17: 0 | Q17: 0 | R17: 0 | S17: 6 | T17: 0 | U17: 0 | V17: 0 | W17: 0 | X17: 0 | Y17: 0 | Z17: 0 | AA17: 0 | AB17: 6 | AC17: 0 | AD17: 0 | AE17: 0 | AF17: 0 | AG17: 0 | AH17: =SUM(K17:AB17) -> 16 | AI17: =SUMPRODUCT($K$1:$AG$1,$K17:$AG17) -> 4 | AJ17: =SUMPRODUCT($K$2:$AG$2,$K17:$AG17) -> 6 | AK17: =SUMPRODUCT($K$3:$AG$3,$K17:$AG17) -> 6 | AL17: =SUMPRODUCT($K$4:$AG$4,$K17:$AG17) -> 10 | AM17: =SUMPRODUCT(K17:AG17,$K$6:$AG$6) -> 353630 | AN17: 2000 | AO17: =CEILING(AM17,AN17) -> 354000 | AQ17: COILCRAFT INC. | AR17: ELINA | AU17: 0.065 | AV17: USD | AW17: Avi Elia | AX17: avi@elina.co.il | AZ17: 972.73.2224830 | BA17: =IC17 -> P0025 | BB17: =EV17 -> #NAME? | BC17: 7 | BD17: =EZ17 -> 354000 | BJ17: 354000 | CW17: =SUM($BE17,$BF17:BF17)-SUM($CV$1:CW$1)*SUM($P17:$Q17,$W17)-SUM($CV$2:CW$2)*SUM($R17:$V17)-SUM($CV$3:CW$3)*$X17-SUM($CV$4:CW$4)*SUM($K17:$L17)-SUM($CV$5:CW$5)*SUM($M17:$N17)-SUM($CV$6:CW$6)*$O17-SUM($CV$7:CW$7)*SUM($Y17:$Z17,$AF17)-SUM($CV$8:CW$8)*SUM($AA17:$AE17)-SUM($CV$9:CW$9)*$AG17 -> 0 | CX17: =SUM($BE17,$BF17:BG17)-SUM($CV$1:CX$1)*SUM($P17:$Q17,$W17)-SUM($CV$2:CX$2)*SUM($R17:$V17)-SUM($CV$3:CX$3)*$X17-SUM($CV$4:CX$4)*SUM($K17:$L17)-SUM($CV$5:CX$5)*SUM($M17:$N17)-SUM($CV$6:CX$6)*$O17-SUM($CV$7:CX$7)*SUM($Y17:$Z17,$AF17)-SUM($CV$8:CX$8)*SUM($AA17:$AE17)-SUM($CV$9:CX$9)*$AG17 -> 0 | CY17: =SUM($BE17,$BF17:BH17)-SUM($CV$1:CY$1)*SUM($P17:$Q17,$W17)-SUM($CV$2:CY$2)*SUM($R17:$V17)-SUM($CV$3:CY$3)*$X17-SUM($CV$4:CY$4)*SUM($K17:$L17)-SUM($CV$5:CY$5)*SUM($M17:$N17)-SUM($CV$6:CY$6)*$O17-SUM($CV$7:CY$7)*SUM($Y17:$Z17,$AF17)-SUM($CV$8:CY$8)*SUM($AA17:$AE17)-SUM($CV$9:CY$9)*$AG17 -> 0 | CZ17: =SUM($BE17,$BF17:BI17)-SUM($CV$1:CZ$1)*SUM($P17:$Q17,$W17)-SUM($CV$2:CZ$2)*SUM($R17:$V17)-SUM($CV$3:CZ$3)*$X17-SUM($CV$4:CZ$4)*SUM($K17:$L17)-SUM($CV$5:CZ$5)*SUM($M17:$N17)-SUM($CV$6:CZ$6)*$O17-SUM($CV$7:CZ$7)*SUM($Y17:$Z17,$AF17)-SUM($CV$8:CZ$8)*SUM($AA17:$AE17)-SUM($CV$9:CZ$9)*$AG17 -> 0 | DA17: =SUM($BE17,$BF17:BJ17)-SUM($CV$1:DA$1)*SUM($P17:$Q17,$W17)-SUM($CV$2:DA$2)*SUM($R17:$V17)-SUM($CV$3:DA$3)*$X17-SUM($CV$4:DA$4)*SUM($K17:$L17)-SUM($CV$5:DA$5)*SUM($M17:$N17)-SUM($CV$6:DA$6)*$O17-SUM($CV$7:DA$7)*SUM($Y17:$Z17,$AF17)-SUM($CV$8:DA$8)*SUM($AA17:$AE17)-SUM($CV$9:DA$9)*$AG17 -> 354000 | DB17: =SUM($BE17,$BF17:BK17)-SUM($CV$1:DB$1)*SUM($P17:$Q17,$W17)-SUM($CV$2:DB$2)*SUM($R17:$V17)-SUM($CV$3:DB$3)*$X17-SUM($CV$4:DB$4)*SUM($K17:$L17)-SUM($CV$5:DB$5)*SUM($M17:$N17)-SUM($CV$6:DB$6)*$O17-SUM($CV$7:DB$7)*SUM($Y17:$Z17,$AF17)-SUM($CV$8:DB$8)*SUM($AA17:$AE17)-SUM($CV$9:DB$9)*$AG17 -> 352400 | DC17: =SUM($BE17,$BF17:BL17)-SUM($CV$1:DC$1)*SUM($P17:$Q17,$W17)-SUM($CV$2:DC$2)*SUM($R17:$V17)-SUM($CV$3:DC$3)*$X17-SUM($CV$4:DC$4)*SUM($K17:$L17)-SUM($CV$5:DC$5)*SUM($M17:$N17)-SUM($CV$6:DC$6)*$O17-SUM($CV$7:DC$7)*SUM($Y17:$Z17,$AF17)-SUM($CV$8:DC$8)*SUM($AA17:$AE17)-SUM($CV$9:DC$9)*$AG17 -> 349200 | DD17: =SUM($BE17,$BF17:BM17)-SUM($CV$1:DD$1)*SUM($P17:$Q17,$W17)-SUM($CV$2:DD$2)*SUM($R17:$V17)-SUM($CV$3:DD$3)*$X17-SUM($CV$4:DD$4)*SUM($K17:$L17)-SUM($CV$5:DD$5)*SUM($M17:$N17)-SUM($CV$6:DD$6)*$O17-SUM($CV$7:DD$7)*SUM($Y17:$Z17,$AF17)-SUM($CV$8:DD$8)*SUM($AA17:$AE17)-SUM($CV$9:DD$9)*$AG17 -> 344214 | ... EO17: =SUM($BE17,$BF17:CX17)-SUM($CV$1:EO$1)*SUM($P17:$Q17,$W17)-SUM($CV$2:EO$2)*SUM($R17:$V17)-SUM($CV$3:EO$3)*$X17-SUM($CV$4:EO$4)*SUM($K17:$L17)-SUM($CV$5:EO$5)*SUM($M17:$N17)-SUM($CV$6:EO$6)*$O17-SUM($CV$7:EO$7)*SUM($Y17:$Z17,$AF17)-SUM($CV$8:EO$8)*SUM($AA17:$AE17)-SUM($CV$9:EO$9)*$AG17 -> 22 | EP17: coilcraft | EQ17: =C17 -> 0603CS-15NXGRW | ER17: =AQ17 -> COILCRAFT INC. | ES17: =AU17 -> 0.065 | ET17: =AV17 -> USD | EU17: =_xlfn.XLOOKUP(ET17,ET$3:ET$6,EU$3:EU$6,0) -> #NAME? | EV17: =ES17*EU17 -> #NAME? | EW17: =AN17 -> 2000 | EX17: 26000 | EZ17: =MAX(EX17,CEILING(AM17+EY17,EW17)) -> 354000 | FA17: =EZ17*EV17 -> #NAME? | FB17: =EZ17-AM17 -> 370 | FC17: =FB17*EV17 -> #NAME? | FD17: 45523 | FE17: Sagi | FF17: Ordered | FG17: Y | FH17: RNSE | FI17: {=SUMPRODUCT($AI17:$AL17,TRANSPOSE(FI$1:FI$4))} -> 30390 | FJ17: {=SUMPRODUCT($AI17:$AL17,TRANSPOSE(FJ$1:FJ$4))} -> 30390 | FK17: {=SUMPRODUCT($AI17:$AL17,TRANSPOSE(FK$1:FK$4))} -> 30390 | FL17: {=SUMPRODUCT($AI17:$AL17,TRANSPOSE(FL$1:FL$4))} -> 30390 | FM17: {=SUMPRODUCT($AI17:$AL17,TRANSPOSE(FM$1:FM$4))} -> 30390 | FN17: {=SUMPRODUCT($AI17:$AL17,TRANSPOSE(FN$1:FN$4))} -> 30390 | FO17: {=SUMPRODUCT($AI17:$AL17,TRANSPOSE(FO$1:FO$4))} -> 30390 | FP17: {=SUMPRODUCT($AI17:$AL17,TRANSPOSE(FP$1:FP$4))} -> 30390 | ... FU17: {=SUMPRODUCT($AI17:$AL17,TRANSPOSE(FU$1:FU$4))} -> 0 | FW17: =CEILING(FI17,$EW17) -> 32000 | FX17: =CEILING(SUM($FI17:FJ17)-SUM($FW17:FW17),$EW17) -> 30000 | FY17: =CEILING(SUM($FI17:FK17)-SUM($FW17:FX17),$EW17) -> 30000 | FZ17: =CEILING(SUM($FI17:FL17)-SUM($FW17:FY17),$EW17) -> 30000 | GA17: =CEILING(SUM($FI17:FM17)-SUM($FW17:FZ17),$EW17) -> 30000 | GB17: =CEILING(SUM($FI17:FN17)-SUM($FW17:GA17),$EW17) -> 32000 | GC17: =CEILING(SUM($FI17:FO17)-SUM($FW17:GB17),$EW17) -> 30000 | GD17: =CEILING(SUM($FI17:FP17)-SUM($FW17:GC17),$EW17) -> 30000 | GE17: =CEILING(SUM($FI17:FQ17)-SUM($FW17:GD17),$EW17) -> 30000 | ... GG17: =CEILING(SUM($FI17:FS17)-SUM($FW17:GF17),$EW17) -> 30000 | GH17: =EZ17-SUM(FW17:GG17) -> 20000 | GI17: =EZ17-SUM(FW17:GH17) -> 0 | GK17: =FW17*$EV17 -> #NAME? | GL17: =FX17*$EV17 -> #NAME? | GM17: =FY17*$EV17 -> #NAME? | GN17: =FZ17*$EV17 -> #NAME? | GO17: =GA17*$EV17 -> #NAME? | GP17: =GB17*$EV17 -> #NAME? | GQ17: =GC17*$EV17 -> #NAME? | GR17: =GD17*$EV17 -> #NAME? | ... GW17: =GI17*$EV17 -> #NAME? | GX17: =SUM(GK17:GW17) -> #NAME? | GY17: 2 | GZ17: =SUM(FW17:GB17) -> 184000 | HF17: =SUM(GC17:GI17) -> 170000 | HN17: =GZ17*$EV17 -> #NAME? | HO17: =HA17*$EV17 -> #NAME? | HP17: =HB17*$EV17 -> #NAME? | HQ17: =HC17*$EV17 -> #NAME? | HR17: =HD17*$EV17 -> #NAME? | HS17: =HE17*$EV17 -> #NAME? | HT17: =HF17*$EV17 -> #NAME? | HU17: =HG17*$EV17 -> #NAME? | ... HZ17: =HL17*$EV17 -> #NAME? | IA17: =SUM(HN17:HZ17) -> #NAME? | IB17: LT01-006 | IC17: P0025 | ID17: 45526 | IE17: Yes | IF17: Yes | IG17: Yes | II17: Indonesia / Malaysia / Vietnam
