Workbook
Name TIER2: [1]TIER2!#REF!

Sheet avl 18.08.24
CU5: DRM F/ASSY | CV5: 0 | CW5: 1096M150-001 | DD5: 180 | DE5: 598 | DF5: 1000 | DG5: 1000 | DH5: 1000 | DI5: 1000 | DJ5: 1000 | DK5: 1000 | DL5: 1000 | DM5: 1000 | DN5: 1000 | DO5: 1000 | DP5: 1000 | DQ5: 1000 | DR5: 1000 | DS5: 1000 | DT5: 1000 | DU5: 1000 | DV5: 1000 | DW5: 1000 | DX5: 1000 | DY5: 1000 | DZ5: 1000 | EA5: 1000 | EB5: 1000 | EC5: 1000 | ED5: 1000 | EE5: 1000 | EF5: 1000 | EG5: 1000 | EH5: 1000 | EI5: 1000 | EJ5: 1000 | EK5: 1000 | EL5: 1000 | EM5: 1000 | ER5: DRM F/ASSY | ES5: 0 | ET5: 1096M150-001 | EU5: =CX5 -> 0 | EV5: =CY5 -> 0 | EW5: =CZ5 -> 0 | EX5: =DA5 -> 0 | EY5: =DB5 -> 0 | EZ5: =DC5 -> 0 | FA5: =DD5 -> 180 | FB5: =DE5 -> 598 | ... GJ5: =EM5 -> 1000 | IV5: ;
CU6: DRM ASSY | CV6: 1 | CW6: 1096M155-001 | DD6: 180 | DE6: 598 | DF6: 1000 | DG6: 1000 | DH6: 1000 | DI6: 1000 | DJ6: 1000 | DK6: 1000 | DL6: 1000 | DM6: 1000 | DN6: 1000 | DO6: 1000 | DP6: 1000 | DQ6: 1000 | DR6: 1000 | DS6: 1000 | DT6: 1000 | DU6: 1000 | DV6: 1000 | DW6: 1000 | DX6: 1000 | DY6: 1000 | DZ6: 1000 | EA6: 1000 | EB6: 1000 | EC6: 1000 | ED6: 1000 | EE6: 1000 | EF6: 1000 | EG6: 1000 | EH6: 1000 | EI6: 1000 | EJ6: 1000 | EK6: 1000 | EL6: 1000 | EM6: 1000 | ER6: DRM ASSY | ES6: 1 | ET6: 1096M155-001 | EU6: =CX6 -> 0 | EV6: =CY6 -> 0 | EW6: =CZ6 -> 0 | EX6: =DA6 -> 0 | EY6: =DB6 -> 0 | EZ6: =DC6 -> 0 | FA6: =DD6 -> 180 | FB6: =DE6 -> 598 | ... GJ6: =EM6 -> 1000
CU7: DRM PS ASSY RX | CV7: 2 | CW7: 1096M156-001 | DD7: 180 | DE7: 598 | DF7: 1000 | DG7: 1000 | DH7: 1000 | DI7: 1000 | DJ7: 1000 | DK7: 1000 | DL7: 1000 | DM7: 1000 | DN7: 1000 | DO7: 1000 | DP7: 1000 | DQ7: 1000 | DR7: 1000 | DS7: 1000 | DT7: 1000 | DU7: 1000 | DV7: 1000 | DW7: 1000 | DX7: 1000 | DY7: 1000 | DZ7: 1000 | EA7: 1000 | EB7: 1000 | EC7: 1000 | ED7: 1000 | EE7: 1000 | EF7: 1000 | EG7: 1000 | EH7: 1000 | EI7: 1000 | EJ7: 1000 | EK7: 1000 | EL7: 1000 | EM7: 1000 | ER7: DRM PS ASSY RX | ES7: 2 | ET7: 1096M156-001 | EU7: =CX7 -> 0 | EV7: =CY7 -> 0 | EW7: =CZ7 -> 0 | EX7: =DA7 -> 0 | EY7: =DB7 -> 0 | EZ7: =DC7 -> 0 | FA7: =DD7 -> 180 | FB7: =DE7 -> 598 | ... GJ7: =EM7 -> 1000
CU8: DRM RX ASSY | CV8: 3 | CW8: 1096M160-001 | DD8: 180 | DE8: 598 | DF8: 1000 | DG8: 1000 | DH8: 1000 | DI8: 1000 | DJ8: 1000 | DK8: 1000 | DL8: 1000 | DM8: 1000 | DN8: 1000 | DO8: 1000 | DP8: 1000 | DQ8: 1000 | DR8: 1000 | DS8: 1000 | DT8: 1000 | DU8: 1000 | DV8: 1000 | DW8: 1000 | DX8: 1000 | DY8: 1000 | DZ8: 1000 | EA8: 1000 | EB8: 1000 | EC8: 1000 | ED8: 1000 | EE8: 1000 | EF8: 1000 | EG8: 1000 | EH8: 1000 | EI8: 1000 | EJ8: 1000 | EK8: 1000 | EL8: 1000 | EM8: 1000 | ER8: DRM RX ASSY | ES8: 3 | ET8: 1096M160-001 | EU8: =CX8 -> 0 | EV8: =CY8 -> 0 | EW8: =CZ8 -> 0 | EX8: =DA8 -> 0 | EY8: =DB8 -> 0 | EZ8: =DC8 -> 0 | FA8: =DD8 -> 180 | FB8: =DE8 -> 598 | ... GJ8: =EM8 -> 1000
CU9: PC ASSY DRM CONTROLER NG 400 | CV9: 2 | CW9: 1094T037-001 | DD9: 180 | DE9: 598 | DF9: 1000 | DG9: 1000 | DH9: 1000 | DI9: 1000 | DJ9: 1000 | DK9: 1000 | DL9: 1000 | DM9: 1000 | DN9: 1000 | DO9: 1000 | DP9: 1000 | DQ9: 1000 | DR9: 1000 | DS9: 1000 | DT9: 1000 | DU9: 1000 | DV9: 1000 | DW9: 1000 | DX9: 1000 | DY9: 1000 | DZ9: 1000 | EA9: 1000 | EB9: 1000 | EC9: 1000 | ED9: 1000 | EE9: 1000 | EF9: 1000 | EG9: 1000 | EH9: 1000 | EI9: 1000 | EJ9: 1000 | EK9: 1000 | EL9: 1000 | EM9: 1000 | ER9: PC ASSY DRM CONTROLER NG 400 | ES9: 2 | ET9: 1094T037-001 | EU9: =CX9 -> 0 | EV9: =CY9 -> 0 | EW9: =CZ9 -> 0 | EX9: =DA9 -> 0 | EY9: =DB9 -> 0 | EZ9: =DC9 -> 0 | FA9: =DD9 -> 180 | FB9: =DE9 -> 598 | ... GJ9: =EM9 -> 1000
CU10: DTRM F/ASSY | CV10: 0 | CW10: 1096M130-001 | DD10: 180 | DE10: 1000 | DF10: 1000 | DG10: 1000 | DH10: 1000 | DI10: 1000 | DJ10: 1000 | DK10: 1000 | DL10: 1000 | DM10: 1000 | DN10: 1000 | DO10: 1000 | DP10: 1000 | DQ10: 1000 | DR10: 1000 | DS10: 1000 | DT10: 1000 | DU10: 1000 | DV10: 1000 | DW10: 1000 | DX10: 1000 | DY10: 1000 | DZ10: 1000 | EA10: 1000 | EB10: 1000 | EC10: 1000 | ED10: 1000 | EE10: 1000 | EF10: 1000 | EG10: 1000 | EH10: 1000 | EI10: 1000 | EJ10: 1000 | EK10: 1000 | EL10: 1000 | EM10: 1000 | ER10: DTRM F/ASSY | ES10: 0 | ET10: 1096M130-001 | EU10: =CX10 -> 0 | EV10: =CY10 -> 0 | EW10: =CZ10 -> 0 | EX10: =DA10 -> 0 | EY10: =DB10 -> 0 | EZ10: =DC10 -> 0 | FA10: =DD10 -> 180 | FB10: =DE10 -> 1000 | ... GJ10: =EM10 -> 1000
CU11: DTRM F/ASSY | CV11: 1 | CW11: 1096M135-001 | DD11: 180 | DE11: 1000 | DF11: 1000 | DG11: 1000 | DH11: 1000 | DI11: 1000 | DJ11: 1000 | DK11: 1000 | DL11: 1000 | DM11: 1000 | DN11: 1000 | DO11: 1000 | DP11: 1000 | DQ11: 1000 | DR11: 1000 | DS11: 1000 | DT11: 1000 | DU11: 1000 | DV11: 1000 | DW11: 1000 | DX11: 1000 | DY11: 1000 | DZ11: 1000 | EA11: 1000 | EB11: 1000 | EC11: 1000 | ED11: 1000 | EE11: 1000 | EF11: 1000 | EG11: 1000 | EH11: 1000 | EI11: 1000 | EJ11: 1000 | EK11: 1000 | EL11: 1000 | EM11: 1000 | ER11: DTRM F/ASSY | ES11: 1 | ET11: 1096M135-001 | EU11: =CX11 -> 0 | EV11: =CY11 -> 0 | EW11: =CZ11 -> 0 | EX11: =DA11 -> 0 | EY11: =DB11 -> 0 | EZ11: =DC11 -> 0 | FA11: =DD11 -> 180 | FB11: =DE11 -> 1000 | ... GJ11: =EM11 -> 1000
CU12: DTRM POWER AMP ASSY | CV12: 2 | CW12: 1096M136-001 | DD12: 180 | DE12: 1000 | DF12: 1000 | DG12: 1000 | DH12: 1000 | DI12: 1000 | DJ12: 1000 | DK12: 1000 | DL12: 1000 | DM12: 1000 | DN12: 1000 | DO12: 1000 | DP12: 1000 | DQ12: 1000 | DR12: 1000 | DS12: 1000 | DT12: 1000 | DU12: 1000 | DV12: 1000 | DW12: 1000 | DX12: 1000 | DY12: 1000 | DZ12: 1000 | EA12: 1000 | EB12: 1000 | EC12: 1000 | ED12: 1000 | EE12: 1000 | EF12: 1000 | EG12: 1000 | EH12: 1000 | EI12: 1000 | EJ12: 1000 | EK12: 1000 | EL12: 1000 | EM12: 1000 | ER12: DTRM POWER AMP ASSY | ES12: 2 | ET12: 1096M136-001 | EU12: =CX12 -> 0 | EV12: =CY12 -> 0 | EW12: =CZ12 -> 0 | EX12: =DA12 -> 0 | EY12: =DB12 -> 0 | EZ12: =DC12 -> 0 | FA12: =DD12 -> 180 | FB12: =DE12 -> 1000 | ... GJ12: =EM12 -> 1000
CU13: DTRM PC ASSY PA CR | CV13: 3 | CW13: 1096M140-001 | DD13: 180 | DE13: 1000 | DF13: 1000 | DG13: 1000 | DH13: 1000 | DI13: 1000 | DJ13: 1000 | DK13: 1000 | DL13: 1000 | DM13: 1000 | DN13: 1000 | DO13: 1000 | DP13: 1000 | DQ13: 1000 | DR13: 1000 | DS13: 1000 | DT13: 1000 | DU13: 1000 | DV13: 1000 | DW13: 1000 | DX13: 1000 | DY13: 1000 | DZ13: 1000 | EA13: 1000 | EB13: 1000 | EC13: 1000 | ED13: 1000 | EE13: 1000 | EF13: 1000 | EG13: 1000 | EH13: 1000 | EI13: 1000 | EJ13: 1000 | EK13: 1000 | EL13: 1000 | EM13: 1000 | ER13: DTRM PC ASSY PA CR | ES13: 3 | ET13: 1096M140-001 | EU13: =CX13 -> 0 | EV13: =CY13 -> 0 | EW13: =CZ13 -> 0 | EX13: =DA13 -> 0 | EY13: =DB13 -> 0 | EZ13: =DC13 -> 0 | FA13: =DD13 -> 180 | FB13: =DE13 -> 1000 | ... GJ13: =EM13 -> 1000
CU14: CAPASITORS CALIBRATION KIT | CV14: 4 | CW14: 1094Y038-001 | DD14: 180 | DE14: 1000 | DF14: 1000 | DG14: 1000 | DH14: 1000 | DI14: 1000 | DJ14: 1000 | DK14: 1000 | DL14: 1000 | DM14: 1000 | DN14: 1000 | DO14: 1000 | DP14: 1000 | DQ14: 1000 | DR14: 1000 | DS14: 1000 | DT14: 1000 | DU14: 1000 | DV14: 1000 | DW14: 1000 | DX14: 1000 | DY14: 1000 | DZ14: 1000 | EA14: 1000 | EB14: 1000 | EC14: 1000 | ED14: 1000 | EE14: 1000 | EF14: 1000 | EG14: 1000 | EH14: 1000 | EI14: 1000 | EJ14: 1000 | EK14: 1000 | EL14: 1000 | EM14: 1000 | ER14: CAPASITORS CALIBRATION KIT | ES14: 4 | ET14: 1094Y038-001 | EU14: =CX14 -> 0 | EV14: =CY14 -> 0 | EW14: =CZ14 -> 0 | EX14: =DA14 -> 0 | EY14: =DB14 -> 0 | EZ14: =DC14 -> 0 | FA14: =DD14 -> 180 | FB14: =DE14 -> 1000 | ... GJ14: =EM14 -> 1000
CU15: BEND OF TRANSISTOR | CV15: 3 | CW15: 1094N754-001 | DD15: 180 | DE15: 1000 | DF15: 1000 | DG15: 1000 | DH15: 1000 | DI15: 1000 | DJ15: 1000 | DK15: 1000 | DL15: 1000 | DM15: 1000 | DN15: 1000 | DO15: 1000 | DP15: 1000 | DQ15: 1000 | DR15: 1000 | DS15: 1000 | DT15: 1000 | DU15: 1000 | DV15: 1000 | DW15: 1000 | DX15: 1000 | DY15: 1000 | DZ15: 1000 | EA15: 1000 | EB15: 1000 | EC15: 1000 | ED15: 1000 | EE15: 1000 | EF15: 1000 | EG15: 1000 | EH15: 1000 | EI15: 1000 | EJ15: 1000 | EK15: 1000 | EL15: 1000 | EM15: 1000 | ER15: BEND OF TRANSISTOR | ES15: 3 | ET15: 1094N754-001 | EU15: =CX15 -> 0 | EV15: =CY15 -> 0 | EW15: =CZ15 -> 0 | EX15: =DA15 -> 0 | EY15: =DB15 -> 0 | EZ15: =DC15 -> 0 | FA15: =DD15 -> 180 | FB15: =DE15 -> 1000 | ... GJ15: =EM15 -> 1000
CU16: EV CAP WITH BRACKET | CV16: 3 | CW16: 1093G277-001 | DD16: 180 | DE16: 1000 | DF16: 1000 | DG16: 1000 | DH16: 1000 | DI16: 1000 | DJ16: 1000 | DK16: 1000 | DL16: 1000 | DM16: 1000 | DN16: 1000 | DO16: 1000 | DP16: 1000 | DQ16: 1000 | DR16: 1000 | DS16: 1000 | DT16: 1000 | DU16: 1000 | DV16: 1000 | DW16: 1000 | DX16: 1000 | DY16: 1000 | DZ16: 1000 | EA16: 1000 | EB16: 1000 | EC16: 1000 | ED16: 1000 | EE16: 1000 | EF16: 1000 | EG16: 1000 | EH16: 1000 | EI16: 1000 | EJ16: 1000 | EK16: 1000 | EL16: 1000 | EM16: 1000 | ER16: EV CAP WITH BRACKET | ES16: 3 | ET16: 1093G277-001 | EU16: =CX16 -> 0 | EV16: =CY16 -> 0 | EW16: =CZ16 -> 0 | EX16: =DA16 -> 0 | EY16: =DB16 -> 0 | EZ16: =DC16 -> 0 | FA16: =DD16 -> 180 | FB16: =DE16 -> 1000 | ... GJ16: =EM16 -> 1000
CU17: INSIDE COVER ASSY | CV17: 2 | CW17: 1093N746-001 | DD17: 180 | DE17: 1000 | DF17: 1000 | DG17: 1000 | DH17: 1000 | DI17: 1000 | DJ17: 1000 | DK17: 1000 | DL17: 1000 | DM17: 1000 | DN17: 1000 | DO17: 1000 | DP17: 1000 | DQ17: 1000 | DR17: 1000 | DS17: 1000 | DT17: 1000 | DU17: 1000 | DV17: 1000 | DW17: 1000 | DX17: 1000 | DY17: 1000 | DZ17: 1000 | EA17: 1000 | EB17: 1000 | EC17: 1000 | ED17: 1000 | EE17: 1000 | EF17: 1000 | EG17: 1000 | EH17: 1000 | EI17: 1000 | EJ17: 1000 | EK17: 1000 | EL17: 1000 | EM17: 1000 | ER17: INSIDE COVER ASSY | ES17: 2 | ET17: 1093N746-001 | EU17: =CX17 -> 0 | EV17: =CY17 -> 0 | EW17: =CZ17 -> 0 | EX17: =DA17 -> 0 | EY17: =DB17 -> 0 | EZ17: =DC17 -> 0 | FA17: =DD17 -> 180 | FB17: =DE17 -> 1000 | ... GJ17: =EM17 -> 1000
CU18: PC ASSY CONTROLLER 400 | CV18: 2 | CW18: 1094N790-003 | DD18: 180 | DE18: 1000 | DF18: 1000 | DG18: 1000 | DH18: 1000 | DI18: 1000 | DJ18: 1000 | DK18: 1000 | DL18: 1000 | DM18: 1000 | DN18: 1000 | DO18: 1000 | DP18: 1000 | DQ18: 1000 | DR18: 1000 | DS18: 1000 | DT18: 1000 | DU18: 1000 | DV18: 1000 | DW18: 1000 | DX18: 1000 | DY18: 1000 | DZ18: 1000 | EA18: 1000 | EB18: 1000 | EC18: 1000 | ED18: 1000 | EE18: 1000 | EF18: 1000 | EG18: 1000 | EH18: 1000 | EI18: 1000 | EJ18: 1000 | EK18: 1000 | EL18: 1000 | EM18: 1000 | ER18: PC ASSY CONTROLLER 400 | ES18: 2 | ET18: 1094N790-003 | EU18: =CX18 -> 0 | EV18: =CY18 -> 0 | EW18: =CZ18 -> 0 | EX18: =DA18 -> 0 | EY18: =DB18 -> 0 | EZ18: =DC18 -> 0 | FA18: =DD18 -> 180 | FB18: =DE18 -> 1000 | ... GJ18: =EM18 -> 1000
A19: DRM | K19: 1 | L19: 1 | M19: 1 | N19: 1 | O19: 1 | CU19: D.A.D. F/ASSY | CV19: 0 | CW19: 1096M170-001 | DD19: 100 | DE19: 200 | DF19: 331 | ER19: D.A.D. F/ASSY | ES19: 0 | ET19: 1096M170-001 | EU19: =CX19 -> 0 | EV19: =CY19 -> 0 | EW19: =CZ19 -> 0 | EX19: =DA19 -> 0 | EY19: =DB19 -> 0 | EZ19: =DC19 -> 0 | FA19: =DD19 -> 100 | FB19: =DE19 -> 200 | ... GJ19: =EM19 -> 0 | JG19: Total No of line items | JI19: 293 | JO19: =_xlfn.XLOOKUP(JO$27,'PO Delivery Schedule'!$A$3:$A$41,'PO Delivery Schedule'!$N$3:$N$41) -> #NAME? | JP19: =_xlfn.XLOOKUP(JP$27,'PO Delivery Schedule'!$A$3:$A$41,'PO Delivery Schedule'!$N$3:$N$41) -> #NAME? | JQ19: =_xlfn.XLOOKUP(JQ$27,'PO Delivery Schedule'!$A$3:$A$41,'PO Delivery Schedule'!$N$3:$N$41) -> #NAME? | JR19: =_xlfn.XLOOKUP(JR$27,'PO Delivery Schedule'!$A$3:$A$41,'PO Delivery Schedule'!$N$3:$N$41) -> #NAME? | JS19: =_xlfn.XLOOKUP(JS$27,'PO Delivery Schedule'!$A$3:$A$41,'PO Delivery Schedule'!$N$3:$N$41) -> #NAME? | JT19: =_xlfn.XLOOKUP(JT$27,'PO Delivery Schedule'!$A$3:$A$41,'PO Delivery Schedule'!$N$3:$N$41) -> #NAME? | JU19: =_xlfn.XLOOKUP(JU$27,'PO Delivery Schedule'!$A$3:$A$41,'PO Delivery Schedule'!$N$3:$N$41) -> #NAME? | JV19: =_xlfn.XLOOKUP(JV$27,'PO Delivery Schedule'!$A$3:$A$41,'PO Delivery Schedule'!$N$3:$N$41) -> #NAME? | ... KA19: =_xlfn.XLOOKUP(KA$27,'PO Delivery Schedule'!$A$3:$A$41,'PO Delivery Schedule'!$N$3:$N$41) -> #NAME? | KB19: =SUM(JO19:KA19) -> #NAME? | MP19: Final Supplier | MQ19: No of Line items
A20: DTRM | P20: 1 | Q20: 1 | R20: 1 | S20: 1 | T20: 1 | U20: 1 | V20: 1 | W20: 1 | X20: 1 | CU20: D.A.D. ASSY | CV20: 1 | CW20: 1096M175-001 | DD20: 100 | DE20: 200 | DF20: 331 | ER20: D.A.D. ASSY | ES20: 1 | ET20: 1096M175-001 | EU20: =CX20 -> 0 | EV20: =CY20 -> 0 | EW20: =CZ20 -> 0 | EX20: =DA20 -> 0 | EY20: =DB20 -> 0 | EZ20: =DC20 -> 0 | FA20: =DD20 -> 100 | FB20: =DE20 -> 200 | ... GJ20: =EM20 -> 0 | JG20: Assy | JI20: 18 | JO20: =_xlfn.XLOOKUP(JO$27,'PO Delivery Schedule'!$A$3:$A$41,'PO Delivery Schedule'!$O$3:$O$41) -> #NAME? | JP20: =_xlfn.XLOOKUP(JP$27,'PO Delivery Schedule'!$A$3:$A$41,'PO Delivery Schedule'!$O$3:$O$41) -> #NAME? | JQ20: =_xlfn.XLOOKUP(JQ$27,'PO Delivery Schedule'!$A$3:$A$41,'PO Delivery Schedule'!$O$3:$O$41) -> #NAME? | JR20: =_xlfn.XLOOKUP(JR$27,'PO Delivery Schedule'!$A$3:$A$41,'PO Delivery Schedule'!$O$3:$O$41) -> #NAME? | JS20: =_xlfn.XLOOKUP(JS$27,'PO Delivery Schedule'!$A$3:$A$41,'PO Delivery Schedule'!$O$3:$O$41) -> #NAME? | JT20: =_xlfn.XLOOKUP(JT$27,'PO Delivery Schedule'!$A$3:$A$41,'PO Delivery Schedule'!$O$3:$O$41) -> #NAME? | JU20: =_xlfn.XLOOKUP(JU$27,'PO Delivery Schedule'!$A$3:$A$41,'PO Delivery Schedule'!$O$3:$O$41) -> #NAME? | JV20: =_xlfn.XLOOKUP(JV$27,'PO Delivery Schedule'!$A$3:$A$41,'PO Delivery Schedule'!$O$3:$O$41) -> #NAME? | ... KA20: =_xlfn.XLOOKUP(KA$27,'PO Delivery Schedule'!$A$3:$A$41,'PO Delivery Schedule'!$O$3:$O$41) -> #NAME? | KB20: =SUM(JO20:KA20) -> #NAME? | MP20: PRONAT | MQ20: 1
A21: DAD | Y21: 1 | Z21: 1 | AA21: 1 | AB21: 1 | AC21: 1 | AD21: 1 | AE21: 1 | AF21: 1 | AG21: 1 | CU21: D.A.D. POWER AMP ASSY | CV21: 2 | CW21: 1096M176-001 | DD21: 100 | DE21: 200 | DF21: 331 | ER21: D.A.D. POWER AMP ASSY | ES21: 2 | ET21: 1096M176-001 | EU21: =CX21 -> 0 | EV21: =CY21 -> 0 | EW21: =CZ21 -> 0 | EX21: =DA21 -> 0 | EY21: =DB21 -> 0 | EZ21: =DC21 -> 0 | FA21: =DD21 -> 100 | FB21: =DE21 -> 200 | ... GJ21: =EM21 -> 0 | IZ21: USD | JA21: 1 | JG21: BFE | JI21: 10 | JO21: =_xlfn.XLOOKUP(JO$27,'PO Delivery Schedule'!$A$3:$A$41,'PO Delivery Schedule'!$P$3:$P$41) -> #NAME? | JP21: =_xlfn.XLOOKUP(JP$27,'PO Delivery Schedule'!$A$3:$A$41,'PO Delivery Schedule'!$P$3:$P$41) -> #NAME? | JQ21: =_xlfn.XLOOKUP(JQ$27,'PO Delivery Schedule'!$A$3:$A$41,'PO Delivery Schedule'!$P$3:$P$41) -> #NAME? | JR21: =_xlfn.XLOOKUP(JR$27,'PO Delivery Schedule'!$A$3:$A$41,'PO Delivery Schedule'!$P$3:$P$41) -> #NAME? | JS21: =_xlfn.XLOOKUP(JS$27,'PO Delivery Schedule'!$A$3:$A$41,'PO Delivery Schedule'!$P$3:$P$41) -> #NAME? | JT21: =_xlfn.XLOOKUP(JT$27,'PO Delivery Schedule'!$A$3:$A$41,'PO Delivery Schedule'!$P$3:$P$41) -> #NAME? | JU21: =_xlfn.XLOOKUP(JU$27,'PO Delivery Schedule'!$A$3:$A$41,'PO Delivery Schedule'!$P$3:$P$41) -> #NAME? | JV21: =_xlfn.XLOOKUP(JV$27,'PO Delivery Schedule'!$A$3:$A$41,'PO Delivery Schedule'!$P$3:$P$41) -> #NAME? | ... KA21: =_xlfn.XLOOKUP(KA$27,'PO Delivery Schedule'!$A$3:$A$41,'PO Delivery Schedule'!$P$3:$P$41) -> #NAME? | KB21: =SUM(JO21:KA21) -> #NAME? | MP21: ARROW RAPAC | MQ21: 2
A22: Spares | M22: 1 | N22: 1 | O22: 1 | R22: 1 | S22: 1 | T22: 1 | U22: 1 | V22: 1 | X22: 1 | CU22: D.A.D. PC ASSY PA CR | CV22: 3 | CW22: 1096M180-001 | DD22: 100 | DE22: 200 | DF22: 331 | ER22: D.A.D. PC ASSY PA CR | ES22: 3 | ET22: 1096M180-001 | EU22: =CX22 -> 0 | EV22: =CY22 -> 0 | EW22: =CZ22 -> 0 | EX22: =DA22 -> 0 | EY22: =DB22 -> 0 | EZ22: =DC22 -> 0 | FA22: =DD22 -> 100 | FB22: =DE22 -> 200 | ... GJ22: =EM22 -> 0 | IZ22: GBP | JA22: 1.3 | JG22: DNP | JI22: 8 | JK22: DD Received | JL22: Payment | JM22: Clarifications | JN22: DD yet to receive | JO22: =_xlfn.XLOOKUP(JO$27,'PO Delivery Schedule'!$A$3:$A$41,'PO Delivery Schedule'!$Q$3:$Q$41) -> #NAME? | JP22: =_xlfn.XLOOKUP(JP$27,'PO Delivery Schedule'!$A$3:$A$41,'PO Delivery Schedule'!$Q$3:$Q$41) -> #NAME? | JQ22: =_xlfn.XLOOKUP(JQ$27,'PO Delivery Schedule'!$A$3:$A$41,'PO Delivery Schedule'!$Q$3:$Q$41) -> #NAME? | JR22: =_xlfn.XLOOKUP(JR$27,'PO Delivery Schedule'!$A$3:$A$41,'PO Delivery Schedule'!$Q$3:$Q$41) -> #NAME? | JS22: =_xlfn.XLOOKUP(JS$27,'PO Delivery Schedule'!$A$3:$A$41,'PO Delivery Schedule'!$Q$3:$Q$41) -> #NAME? | JT22: =_xlfn.XLOOKUP(JT$27,'PO Delivery Schedule'!$A$3:$A$41,'PO Delivery Schedule'!$Q$3:$Q$41) -> #NAME? | JU22: =_xlfn.XLOOKUP(JU$27,'PO Delivery Schedule'!$A$3:$A$41,'PO Delivery Schedule'!$Q$3:$Q$41) -> #NAME? | JV22: =_xlfn.XLOOKUP(JV$27,'PO Delivery Schedule'!$A$3:$A$41,'PO Delivery Schedule'!$Q$3:$Q$41) -> #NAME? | ... KA22: =_xlfn.XLOOKUP(KA$27,'PO Delivery Schedule'!$A$3:$A$41,'PO Delivery Schedule'!$Q$3:$Q$41) -> #NAME? | KB22: =SUM(JO22:KA22) -> #NAME? | MI22: Total | MP22: Kemograph | MQ22: 1
CU23: CAPASITORS CALIBRATION KIT | CV23: 4 | CW23: 1094Y038-001 | DD23: 100 | DE23: 200 | DF23: 331 | ER23: CAPASITORS CALIBRATION KIT | ES23: 4 | ET23: 1094Y038-001 | EU23: =CX23 -> 0 | EV23: =CY23 -> 0 | EW23: =CZ23 -> 0 | EX23: =DA23 -> 0 | EY23: =DB23 -> 0 | EZ23: =DC23 -> 0 | FA23: =DD23 -> 100 | FB23: =DE23 -> 200 | ... GJ23: =EM23 -> 0 | IZ23: EUR | JA23: 1.12 | JG23: Ordered | JI23: 232 | JJ23: Components | JK23: 204 | JL23: 10 | JM23: 15 | JN23: =JI23-JK23-JL23-JM23 -> 3 | MI23: =SUM(JK23:JN23) -> 232
A24: 42 | J24: QTY | K24: 34778 | L24: 34778 | M24: 34778 | N24: 34778 | O24: 34778 | P24: 35180 | Q24: 35180 | R24: 35180 | S24: 35180 | T24: 35180 | U24: 35180 | V24: 35180 | W24: 35180 | X24: 35180 | Y24: 631 | Z24: 631 | AA24: 631 | AB24: 631 | AC24: 631 | AD24: 631 | AE24: 631 | AF24: 631 | AG24: 631 | CU24: BEND OF TRANSISTOR | CV24: 3 | CW24: 1094N754-001 | DD24: 100 | DE24: 200 | DF24: 331 | ER24: BEND OF TRANSISTOR | ES24: 3 | ET24: 1094N754-001 | EU24: =CX24 -> 0 | EV24: =CY24 -> 0 | EW24: =CZ24 -> 0 | EX24: =DA24 -> 0 | EY24: =DB24 -> 0 | EZ24: =DC24 -> 0 | FA24: =DD24 -> 100 | FB24: =DE24 -> 200 | ... GJ24: =EM24 -> 0 | IZ24: INR | JA24: =1/83 -> 0.012048193 | JG24: Ordered-Partially | JI24: 10 | JJ24: Consumable | JK24: 7 | JN24: =JI24-JK24-JL24-JM24 -> 3 | MI24: =SUM(JK24:JN24) -> 10
A25: 1 | J25: COUNT | K25: =COUNTIF(K29:K322,">0") -> 4 | L25: =COUNTIF(L29:L322,">0") -> 33 | M25: =COUNTIF(M29:M322,">0") -> 13 | N25: =COUNTIF(N29:N322,">0") -> 47 | O25: =COUNTIF(O29:O322,">0") -> 100 | P25: =COUNTIF(P29:P322,">0") -> 4 | Q25: =COUNTIF(Q29:Q322,">0") -> 33 | R25: =COUNTIF(R29:R322,">0") -> 30 | ... AG25: =COUNTIF(AG29:AG322,">0") -> 101 | CU25: EV CAP WITH BRACKET | CV25: 3 | CW25: 1093G277-001 | DD25: 100 | DE25: 200 | DF25: 331 | ER25: EV CAP WITH BRACKET | ES25: 3 | ET25: 1093G277-001 | EU25: =CX25 -> 0 | EV25: =CY25 -> 0 | EW25: =CZ25 -> 0 | EX25: =DA25 -> 0 | EY25: =DB25 -> 0 | EZ25: =DC25 -> 0 | FA25: =DD25 -> 100 | FB25: =DE25 -> 200 | ... GJ25: =EM25 -> 0 | JG25: Ordered-clarifications | JI25: 5 | JJ25: Price clarifications
J26: DESC | K26: =VLOOKUP(K28,$C$29:$F$321,4,) -> DRM F/ASSY | L26: =VLOOKUP(L28,$C$29:$F$321,4,) -> DRM ASSY | M26: =VLOOKUP(M28,$C$29:$F$321,4,) -> DRM PS ASSY RX | N26: =VLOOKUP(N28,$C$29:$F$321,4,) -> DRM RX ASSY | O26: =VLOOKUP(O28,$C$29:$F$321,4,) -> PC ASSY DRM CONTROLER NG 400 | P26: =VLOOKUP(P28,$C$29:$F$321,4,) -> DTRM F/ASSY | Q26: =VLOOKUP(Q28,$C$29:$F$321,4,) -> DTRM F/ASSY | R26: =VLOOKUP(R28,$C$29:$F$321,4,) -> DTRM POWER AMP ASSY | ... AG26: =VLOOKUP(AG28,$C$29:$F$321,4,) -> PC ASSY CONTROLLER 400 | BA26: ETA | CU26: INSIDE COVER ASSY | CV26: 2 | CW26: 1093N746-001 | DD26: 100 | DE26: 200 | DF26: 331 | ER26: INSIDE COVER ASSY | ES26: 2 | ET26: 1093N746-001 | EU26: =CX26 -> 0 | EV26: =CY26 -> 0 | EW26: =CZ26 -> 0 | EX26: =DA26 -> 0 | EY26: =DB26 -> 0 | EZ26: =DC26 -> 0 | FA26: =DD26 -> 100 | FB26: =DE26 -> 200 | ... GJ26: =EM26 -> 0 | JG26: TBD | JI26: 10 | JO26: Required | KC26: Considering SPQ | KQ26: Amount Considering SPQ | LF26: Final Ordering | LT26: Final Ordering Amount
J27: BOM LEVAL | K27: 0 | L27: 1 | M27: 2 | N27: 3 | O27: 2 | P27: 0 | Q27: 1 | R27: 2 | S27: 3 | T27: 4 | U27: 3 | V27: 3 | W27: 2 | X27: 2 | Y27: 0 | Z27: 1 | AA27: 2 | AB27: 3 | AC27: 4 | AD27: 3 | AE27: 3 | AF27: 2 | AG27: 2 | AV27: DCX DEATAILS | CU27: PC ASSY CONTROLLER 400 | CV27: 2 | CW27: 1094N790-003 | DD27: 100 | DE27: 200 | DF27: 331 | ER27: PC ASSY CONTROLLER 400 | ES27: 2 | ET27: 1094N790-003 | EU27: =CX27 -> 0 | EV27: =CY27 -> 0 | EW27: =CZ27 -> 0 | EX27: =DA27 -> 0 | EY27: =DB27 -> 0 | EZ27: =DC27 -> 0 | FA27: =DD27 -> 100 | FB27: =DE27 -> 200 | ... GJ27: =EM27 -> 0 | JG27: Total | JI27: =SUM(JI20:JI26) -> 293 | JO27: 45566 | JP27: 45717 | JQ27: =EDATE(JP27,3) -> 45809 | JR27: =EDATE(JQ27,3) -> 45901 | JS27: =EDATE(JR27,3) -> 45992 | JT27: =EDATE(JS27,3) -> 46082 | JU27: =EDATE(JT27,3) -> 46174 | JV27: =EDATE(JU27,3) -> 46266 | JW27: =EDATE(JV27,3) -> 46357 | JX27: =EDATE(JW27,3) -> 46447 | ... KA27: =EDATE(JZ27,3) -> 46722 | KC27: 45566 | KD27: 45717 | KE27: =EDATE(KD27,3) -> 45809 | KF27: =EDATE(KE27,3) -> 45901 | KG27: =EDATE(KF27,3) -> 45992 | KH27: =EDATE(KG27,3) -> 46082 | KI27: =EDATE(KH27,3) -> 46174 | KJ27: =EDATE(KI27,3) -> 46266 | KK27: =EDATE(KJ27,3) -> 46357 | KL27: =EDATE(KK27,3) -> 46447 | ... KO27: =EDATE(KN27,3) -> 46722 | KQ27: 45566 | KR27: 45717 | KS27: =EDATE(KR27,3) -> 45809 | KT27: =EDATE(KS27,3) -> 45901 | KU27: =EDATE(KT27,3) -> 45992 | KV27: =EDATE(KU27,3) -> 46082 | KW27: =EDATE(KV27,3) -> 46174 | KX27: =EDATE(KW27,3) -> 46266 | KY27: =EDATE(KX27,3) -> 46357 | KZ27: =EDATE(KY27,3) -> 46447 | ... LC27: =EDATE(LB27,3) -> 46722 | LF27: 45566 | LG27: 45717 | LH27: =EDATE(LG27,3) -> 45809 | LI27: =EDATE(LH27,3) -> 45901 | LJ27: =EDATE(LI27,3) -> 45992 | LK27: =EDATE(LJ27,3) -> 46082 | LL27: =EDATE(LK27,3) -> 46174 | LM27: =EDATE(LL27,3) -> 46266 | LN27: =EDATE(LM27,3) -> 46357 | LO27: =EDATE(LN27,3) -> 46447 | ... LR27: =EDATE(LQ27,3) -> 46722 | LT27: 45566 | LU27: 45717 | LV27: =EDATE(LU27,3) -> 45809 | LW27: =EDATE(LV27,3) -> 45901 | LX27: =EDATE(LW27,3) -> 45992 | LY27: =EDATE(LX27,3) -> 46082 | LZ27: =EDATE(LY27,3) -> 46174 | MA27: =EDATE(LZ27,3) -> 46266 | MB27: =EDATE(MA27,3) -> 46357 | MC27: =EDATE(MB27,3) -> 46447 | ... MF27: =EDATE(ME27,3) -> 46722
A28: # | C28: PN_ID | D28: REV | E28: CATALOG | F28: DESCRIPTION | G28: FFF CLASS | H28: UOM | I28: SUG_MLAI | J28: ORIG_QTY | K28: 1096M150-001 | L28: 1096M155-001 | M28: 1096M156-001 | N28: 1096M160-001 | O28: 1094T037-001 | P28: 1096M130-001 | Q28: 1096M135-001 | R28: 1096M136-001 | S28: 1096M140-001 | T28: 1094Y038-001 | U28: 1094N754-001 | V28: 1093G277-001 | W28: 1093N746-001 | X28: 1094N790-003 | Y28: 1096M170-001 | Z28: 1096M175-001 | AA28: 1096M176-001 | AB28: 1096M180-001 | AC28: 1094Y038-001 | AD28: 1094N754-001 | AE28: 1093G277-001 | AF28: 1093N746-001 | AG28: 1094N790-003 | AH28: SUM | AI28: Total QTY | AJ28: MPQ | AK28: NOTES | AL28: MFG | AM28: SUPPLIER | AN28: DCX Remarks | AO28: Indian Supllier | AP28: FINAL PRICE | AQ28: CUR | AR28: POC/NAME | AS28: E-MAIL | AT28: E-MAIL | AU28: PHONE # | AV28: PO # | AW28: ACTUAL PRICE | AX28: L.T in Wks | AY28: QTY # | AZ28: STOCK | BA28: 45474 | BB28: 45505 | BC28: 45536 | BD28: 45566 | BE28: 45597 | BF28: 45627 | BG28: 45658 | BH28: 45689 | BI28: 45717 | BJ28: 45748 | BK28: 45778 | BL28: 45809 | BM28: 45839 | BN28: 45870 | BO28: 45901 | BP28: 45931 | BQ28: 45962 | BR28: 45992 | BS28: 46023 | BT28: 46054 | BU28: 46082 | BV28: 46113 | BW28: 46143 | BX28: 46174 | BY28: 46204 | BZ28: 46235 | CA28: 46266 | CB28: 46296 | CC28: 46327 | CD28: 46357 | CE28: 46388 | CF28: 46419 | CG28: 46447 | CH28: 46478 | CI28: 46508 | CJ28: 46539 | CK28: 46569 | CL28: 46600 | CM28: 46631 | CN28: 46661 | CO28: 46692 | CP28: 46722 | CQ28: 46753 | CR28: 46784 | CS28: 46813 | CT28: 46844 | CU28: DESC | CV28: LEVEL | CW28: PN | CX28: 45474 | CY28: 45505 | CZ28: 45536 | DA28: 45566 | DB28: 45597 | DC28: 45627 | DD28: 45658 | DE28: 45689 | DF28: 45717 | DG28: 45748 | DH28: 45778 | DI28: 45809 | DJ28: 45839 | DK28: 45870 | DL28: 45901 | DM28: 45931 | DN28: 45962 | DO28: 45992 | DP28: 46023 | DQ28: 46054 | DR28: 46082 | DS28: 46113 | DT28: 46143 | DU28: 46174 | DV28: 46204 | DW28: 46235 | DX28: 46266 | DY28: 46296 | DZ28: 46327 | EA28: 46357 | EB28: 46388 | EC28: 46419 | ED28: 46447 | EE28: 46478 | EF28: 46508 | EG28: 46539 | EH28: 46569 | EI28: 46600 | EJ28: 46631 | EK28: 46661 | EL28: 46692 | EM28: 46722 | EN28: 46753 | EO28: 46784 | EP28: 46813 | EQ28: 46844 | ER28: DESC | ES28: LEVEL | ET28: PN | EU28: 45474 | EV28: 45505 | EW28: 45536 | EX28: 45566 | EY28: 45597 | EZ28: 45627 | FA28: 45658 | FB28: 45689 | FC28: 45717 | FD28: 45748 | FE28: 45778 | FF28: 45809 | FG28: 45839 | FH28: 45870 | FI28: 45901 | FJ28: 45931 | FK28: 45962 | FL28: 45992 | FM28: 46023 | FN28: 46054 | FO28: 46082 | FP28: 46113 | FQ28: 46143 | FR28: 46174 | FS28: 46204 | FT28: 46235 | FU28: 46266 | FV28: 46296 | FW28: 46327 | FX28: 46357 | FY28: 46388 | FZ28: 46419 | GA28: 46447 | GB28: 46478 | GC28: 46508 | GD28: 46539 | GE28: 46569 | GF28: 46600 | GG28: 46631 | GH28: 46661 | GI28: 46692 | GJ28: 46722 | GK28: 46753 | GL28: 46784 | GM28: 46813 | GN28: 46844 | IV28: Final Supplier | IW28: Final P/N | IX28: Final Make | IY28: Final Price | IZ28: Final CNY | JA28: CCR to USD | JB28: Final Price in USD | JC28: SPQ | JD28: MOQ | JE28: Additional QTY to Order | JF28: Total Order QTY | JG28: Total Order Amount $ | JH28: Surplus QTY | JI28: Amount for Surplus QTY $ | JJ28: Approval Date | JK28: Approved By | JL28: Remarks | JM28: Finalised | JN28: Order to be placed by | JO28: 1 | JP28: 2 | JQ28: =JP28+1 -> 3 | JR28: =JQ28+1 -> 4 | JS28: =JR28+1 -> 5 | JT28: =JS28+1 -> 6 | JU28: =JT28+1 -> 7 | JV28: =JU28+1 -> 8 | JW28: =JV28+1 -> 9 | JX28: =JW28+1 -> 10 | ... KA28: =JZ28+1 -> 13 | KB28: X | KC28: 1 | KD28: 2 | KE28: =KD28+1 -> 3 | KF28: =KE28+1 -> 4 | KG28: =KF28+1 -> 5 | KH28: =KG28+1 -> 6 | KI28: =KH28+1 -> 7 | KJ28: =KI28+1 -> 8 | KK28: =KJ28+1 -> 9 | KL28: =KK28+1 -> 10 | ... KO28: =KN28+1 -> 13 | KP28: X | KQ28: 1 | KR28: 2 | KS28: =KR28+1 -> 3 | KT28: =KS28+1 -> 4 | KU28: =KT28+1 -> 5 | KV28: =KU28+1 -> 6 | KW28: =KV28+1 -> 7 | KX28: =KW28+1 -> 8 | KY28: =KX28+1 -> 9 | KZ28: =KY28+1 -> 10 | ... LC28: =LB28+1 -> 13 | LD28: Total | LE28: Split Lot | LF28: 1 | LG28: 2 | LH28: =LG28+1 -> 3 | LI28: =LH28+1 -> 4 | LJ28: =LI28+1 -> 5 | LK28: =LJ28+1 -> 6 | LL28: =LK28+1 -> 7 | LM28: =LL28+1 -> 8 | LN28: =LM28+1 -> 9 | LO28: =LN28+1 -> 10 | ... LR28: =LQ28+1 -> 13 | LS28: X | LT28: 1 | LU28: 2 | LV28: =LU28+1 -> 3 | LW28: =LV28+1 -> 4 | LX28: =LW28+1 -> 5 | LY28: =LX28+1 -> 6 | LZ28: =LY28+1 -> 7 | MA28: =LZ28+1 -> 8 | MB28: =MA28+1 -> 9 | MC28: =MB28+1 -> 10 | ... MF28: =ME28+1 -> 13 | MG28: Total | MI28: PO number | MJ28: PO Date | MK28: OA | ML28: Payment | MM28: DD | MN28: Remarks | MO28: COO
A29: 1 | B29: LT01-289 | C29: 1096M130-001 | D29: - | E29: 410977392 | F29: DTRM F/ASSY | H29: EA | I29: 1 | J29: 1 | K29: 0 | L29: 0 | M29: 0 | N29: 0 | O29: 0 | P29: 1 | Q29: 0 | R29: 0 | S29: 0 | T29: 0 | U29: 0 | V29: 0 | W29: 0 | X29: 0 | Y29: 0 | Z29: 0 | AA29: 0 | AB29: 0 | AC29: 0 | AD29: 0 | AE29: 0 | AF29: 0 | AG29: 0 | AH29: =SUM(K29:AB29) -> 1 | AI29: =SUMPRODUCT(K29:AG29,$K$24:$AG$24) -> 35180 | AJ29: 1 | AK29: ASSY | AL29: ASSY | AV29: =MI29 -> 0 | AW29: =JB29 -> #NAME? | AY29: =JF29 -> #REF! | DD29: =SUM($AZ29,$BA29:BF29)-SUM($EU29:FA29) -> -180 | DE29: =SUM($AZ29,$BA29:BG29)-SUM($EU29:FB29) -> -1180 | DF29: =SUM($AZ29,$BA29:BH29)-SUM($EU29:FC29) -> -2180 | DG29: =SUM($AZ29,$BA29:BI29)-SUM($EU29:FD29) -> -3180 | DH29: =SUM($AZ29,$BA29:BJ29)-SUM($EU29:FE29) -> -4180 | DI29: =SUM($AZ29,$BA29:BK29)-SUM($EU29:FF29) -> -5180 | DJ29: =SUM($AZ29,$BA29:BL29)-SUM($EU29:FG29) -> -6180 | DK29: =SUM($AZ29,$BA29:BM29)-SUM($EU29:FH29) -> -7180 | ... EQ29: =SUM($AZ29,$BA29:CS29)-SUM($EU29:GN29) -> -35180 | EU29: {=SUMPRODUCT($K29:$AG29,TRANSPOSE(EU$5:EU$27))} -> 0 | EV29: {=SUMPRODUCT($K29:$AG29,TRANSPOSE(EV$5:EV$27))} -> 0 | EW29: {=SUMPRODUCT($K29:$AG29,TRANSPOSE(EW$5:EW$27))} -> 0 | EX29: {=SUMPRODUCT($K29:$AG29,TRANSPOSE(EX$5:EX$27))} -> 0 | EY29: {=SUMPRODUCT($K29:$AG29,TRANSPOSE(EY$5:EY$27))} -> 0 | EZ29: {=SUMPRODUCT($K29:$AG29,TRANSPOSE(EZ$5:EZ$27))} -> 0 | FA29: {=SUMPRODUCT($K29:$AG29,TRANSPOSE(FA$5:FA$27))} -> 180 | FB29: {=SUMPRODUCT($K29:$AG29,TRANSPOSE(FB$5:FB$27))} -> 1000 | ... GN29: {=SUMPRODUCT($K29:$AG29,TRANSPOSE(GN$5:GN$27))} -> 0 | IV29: ASSY | IW29: =C29 -> 1096M130-001 | IX29: =AL29 -> ASSY | IY29: =AP29 -> 0 | IZ29: =AQ29 -> 0 | JA29: =_xlfn.XLOOKUP(IZ29,IZ$21:IZ$24,JA$21:JA$24,0) -> #NAME? | JB29: =IY29*JA29 -> #NAME? | JC29: =AJ29 -> 1 | JD29: =AJ29 -> 1 | JF29: =MAX(JD29,CEILING(#REF!+JE29,JC29)) -> #REF! | JG29: =JF29*JB29 -> #REF! | JH29: =JF29-#REF! -> #REF! | JI29: =JH29*JB29 -> #REF! | JJ29: 45523 | JK29: Sagi | JL29: ASSY | JO29: {=SUMPRODUCT(#REF!,TRANSPOSE(JO$19:JO$22))} -> #REF! | JP29: {=SUMPRODUCT(#REF!,TRANSPOSE(JP$19:JP$22))} -> #REF! | JQ29: {=SUMPRODUCT(#REF!,TRANSPOSE(JQ$19:JQ$22))} -> #REF! | JR29: {=SUMPRODUCT(#REF!,TRANSPOSE(JR$19:JR$22))} -> #REF! | JS29: {=SUMPRODUCT(#REF!,TRANSPOSE(JS$19:JS$22))} -> #REF! | JT29: {=SUMPRODUCT(#REF!,TRANSPOSE(JT$19:JT$22))} -> #REF! | JU29: {=SUMPRODUCT(#REF!,TRANSPOSE(JU$19:JU$22))} -> #REF! | JV29: {=SUMPRODUCT(#REF!,TRANSPOSE(JV$19:JV$22))} -> #REF! | ... KA29: {=SUMPRODUCT(#REF!,TRANSPOSE(KA$19:KA$22))} -> #REF! | KC29: =CEILING(JO29,$JC29) -> #REF! | KD29: =CEILING(SUM($JO29:JP29)-SUM($KC29:KC29),$JC29) -> #REF! | KE29: =CEILING(SUM($JO29:JQ29)-SUM($KC29:KD29),$JC29) -> #REF! | KF29: =CEILING(SUM($JO29:JR29)-SUM($KC29:KE29),$JC29) -> #REF! | KG29: =CEILING(SUM($JO29:JS29)-SUM($KC29:KF29),$JC29) -> #REF! | KH29: =CEILING(SUM($JO29:JT29)-SUM($KC29:KG29),$JC29) -> #REF! | KI29: =CEILING(SUM($JO29:JU29)-SUM($KC29:KH29),$JC29) -> #REF! | KJ29: =CEILING(SUM($JO29:JV29)-SUM($KC29:KI29),$JC29) -> #REF! | KK29: =CEILING(SUM($JO29:JW29)-SUM($KC29:KJ29),$JC29) -> #REF! | ... KM29: =CEILING(SUM($JO29:JY29)-SUM($KC29:KL29),$JC29) -> #REF! | KN29: =JF29-SUM(KC29:KM29) -> #REF! | KO29: =JF29-SUM(KC29:KN29) -> #REF! | KQ29: =KC29*$JB29 -> #REF! | KR29: =KD29*$JB29 -> #REF! | KS29: =KE29*$JB29 -> #REF! | KT29: =KF29*$JB29 -> #REF! | KU29: =KG29*$JB29 -> #REF! | KV29: =KH29*$JB29 -> #REF! | KW29: =KI29*$JB29 -> #REF! | KX29: =KJ29*$JB29 -> #REF! | ... LC29: =KO29*$JB29 -> #REF! | LD29: =SUM(KQ29:LC29) -> #REF! | LR29: =KO29 -> #REF! | LT29: =LF29*$JB29 -> #NAME? | LU29: =LG29*$JB29 -> #NAME? | LV29: =LH29*$JB29 -> #NAME? | LW29: =LI29*$JB29 -> #NAME? | LX29: =LJ29*$JB29 -> #NAME? | LY29: =LK29*$JB29 -> #NAME? | LZ29: =LL29*$JB29 -> #NAME? | MA29: =LM29*$JB29 -> #NAME? | ... MF29: =LR29*$JB29 -> #REF! | MG29: =SUM(LT29:MF29) -> #NAME? | MH29: LT01-289
A30: 2 | B30: LT01-290 | C30: 1096M150-001 | D30: - | E30: 410977469 | F30: DRM F/ASSY | H30: EA | I30: 1 | J30: 1 | K30: 1 | L30: 0 | M30: 0 | N30: 0 | O30: 0 | P30: 0 | Q30: 0 | R30: 0 | S30: 0 | T30: 0 | U30: 0 | V30: 0 | W30: 0 | X30: 0 | Y30: 0 | Z30: 0 | AA30: 0 | AB30: 0 | AC30: 0 | AD30: 0 | AE30: 0 | AF30: 0 | AG30: 0 | AH30: =SUM(K30:AB30) -> 1 | AI30: =SUMPRODUCT(K30:AG30,$K$24:$AG$24) -> 34778 | AJ30: 1 | AK30: ASSY | AL30: ASSY | AV30: =MI30 -> 0 | AW30: =JB30 -> #NAME? | AY30: =JF30 -> #REF! | DD30: =SUM($AZ30,$BA30:BF30)-SUM($EU30:FA30) -> -180 | DE30: =SUM($AZ30,$BA30:BG30)-SUM($EU30:FB30) -> -778 | DF30: =SUM($AZ30,$BA30:BH30)-SUM($EU30:FC30) -> -1778 | DG30: =SUM($AZ30,$BA30:BI30)-SUM($EU30:FD30) -> -2778 | DH30: =SUM($AZ30,$BA30:BJ30)-SUM($EU30:FE30) -> -3778 | DI30: =SUM($AZ30,$BA30:BK30)-SUM($EU30:FF30) -> -4778 | DJ30: =SUM($AZ30,$BA30:BL30)-SUM($EU30:FG30) -> -5778 | DK30: =SUM($AZ30,$BA30:BM30)-SUM($EU30:FH30) -> -6778 | ... EQ30: =SUM($AZ30,$BA30:CS30)-SUM($EU30:GN30) -> -34778 | FA30: {=SUMPRODUCT($K30:$AG30,TRANSPOSE(FA$5:FA$27))} -> 180 | FB30: {=SUMPRODUCT($K30:$AG30,TRANSPOSE(FB$5:FB$27))} -> 598 | FC30: {=SUMPRODUCT($K30:$AG30,TRANSPOSE(FC$5:FC$27))} -> 1000 | FD30: {=SUMPRODUCT($K30:$AG30,TRANSPOSE(FD$5:FD$27))} -> 1000 | FE30: {=SUMPRODUCT($K30:$AG30,TRANSPOSE(FE$5:FE$27))} -> 1000 | FF30: {=SUMPRODUCT($K30:$AG30,TRANSPOSE(FF$5:FF$27))} -> 1000 | FG30: {=SUMPRODUCT($K30:$AG30,TRANSPOSE(FG$5:FG$27))} -> 1000 | FH30: {=SUMPRODUCT($K30:$AG30,TRANSPOSE(FH$5:FH$27))} -> 1000 | ... GN30: {=SUMPRODUCT($K30:$AG30,TRANSPOSE(GN$5:GN$27))} -> 0 | IV30: ASSY | IW30: =C30 -> 1096M150-001 | IX30: =AL30 -> ASSY | IY30: =AP30 -> 0 | IZ30: =AQ30 -> 0 | JA30: =_xlfn.XLOOKUP(IZ30,IZ$21:IZ$24,JA$21:JA$24,0) -> #NAME? | JB30: =IY30*JA30 -> #NAME? | JC30: =AJ30 -> 1 | JD30: =AJ30 -> 1 | JF30: =MAX(JD30,CEILING(#REF!+JE30,JC30)) -> #REF! | JG30: =JF30*JB30 -> #REF! | JH30: =JF30-#REF! -> #REF! | JI30: =JH30*JB30 -> #REF! | JJ30: 45523 | JK30: Sagi | JL30: ASSY | JO30: {=SUMPRODUCT(#REF!,TRANSPOSE(JO$19:JO$22))} -> #REF! | JP30: {=SUMPRODUCT(#REF!,TRANSPOSE(JP$19:JP$22))} -> #REF! | JQ30: {=SUMPRODUCT(#REF!,TRANSPOSE(JQ$19:JQ$22))} -> #REF! | JR30: {=SUMPRODUCT(#REF!,TRANSPOSE(JR$19:JR$22))} -> #REF! | JS30: {=SUMPRODUCT(#REF!,TRANSPOSE(JS$19:JS$22))} -> #REF! | JT30: {=SUMPRODUCT(#REF!,TRANSPOSE(JT$19:JT$22))} -> #REF! | JU30: {=SUMPRODUCT(#REF!,TRANSPOSE(JU$19:JU$22))} -> #REF! | JV30: {=SUMPRODUCT(#REF!,TRANSPOSE(JV$19:JV$22))} -> #REF! | ... KA30: {=SUMPRODUCT(#REF!,TRANSPOSE(KA$19:KA$22))} -> #REF! | KC30: =CEILING(JO30,$JC30) -> #REF! | KD30: =CEILING(SUM($JO30:JP30)-SUM($KC30:KC30),$JC30) -> #REF! | KE30: =CEILING(SUM($JO30:JQ30)-SUM($KC30:KD30),$JC30) -> #REF! | KF30: =CEILING(SUM($JO30:JR30)-SUM($KC30:KE30),$JC30) -> #REF! | KG30: =CEILING(SUM($JO30:JS30)-SUM($KC30:KF30),$JC30) -> #REF! | KH30: =CEILING(SUM($JO30:JT30)-SUM($KC30:KG30),$JC30) -> #REF! | KI30: =CEILING(SUM($JO30:JU30)-SUM($KC30:KH30),$JC30) -> #REF! | KJ30: =CEILING(SUM($JO30:JV30)-SUM($KC30:KI30),$JC30) -> #REF! | KK30: =CEILING(SUM($JO30:JW30)-SUM($KC30:KJ30),$JC30) -> #REF! | ... KM30: =CEILING(SUM($JO30:JY30)-SUM($KC30:KL30),$JC30) -> #REF! | KN30: =JF30-SUM(KC30:KM30) -> #REF! | KO30: =JF30-SUM(KC30:KN30) -> #REF! | KQ30: =KC30*$JB30 -> #REF! | KR30: =KD30*$JB30 -> #REF! | KS30: =KE30*$JB30 -> #REF! | KT30: =KF30*$JB30 -> #REF! | KU30: =KG30*$JB30 -> #REF! | KV30: =KH30*$JB30 -> #REF! | KW30: =KI30*$JB30 -> #REF! | KX30: =KJ30*$JB30 -> #REF! | ... LC30: =KO30*$JB30 -> #REF! | LD30: =SUM(KQ30:LC30) -> #REF! | LR30: =KO30 -> #REF! | LT30: =LF30*$JB30 -> #NAME? | LU30: =LG30*$JB30 -> #NAME? | LV30: =LH30*$JB30 -> #NAME? | LW30: =LI30*$JB30 -> #NAME? | LX30: =LJ30*$JB30 -> #NAME? | LY30: =LK30*$JB30 -> #NAME? | LZ30: =LL30*$JB30 -> #NAME? | MA30: =LM30*$JB30 -> #NAME? | ... MF30: =LR30*$JB30 -> #REF! | MG30: =SUM(LT30:MF30) -> #NAME? | MH30: LT01-290
A31: 3 | B31: LT01-274 | C31: 1096M170-001 | D31: - | E31: 410977542 | F31: D.A.D. F/ASSY | H31: EA | I31: 1 | J31: 1 | K31: 0 | L31: 0 | M31: 0 | N31: 0 | O31: 0 | P31: 0 | Q31: 0 | R31: 0 | S31: 0 | T31: 0 | U31: 0 | V31: 0 | W31: 0 | X31: 0 | Y31: 1 | Z31: 0 | AA31: 0 | AB31: 0 | AC31: 0 | AD31: 0 | AE31: 0 | AF31: 0 | AG31: 0 | AH31: =SUM(K31:AB31) -> 1 | AI31: =SUMPRODUCT(K31:AG31,$K$24:$AG$24) -> 631 | AJ31: 1 | AK31: ASSY | AL31: ASSY | AV31: =MI31 -> 0 | AW31: =JB31 -> #NAME? | AY31: =JF31 -> #REF! | DD31: =SUM($AZ31,$BA31:BF31)-SUM($EU31:FA31) -> -100 | DE31: =SUM($AZ31,$BA31:BG31)-SUM($EU31:FB31) -> -300 | DF31: =SUM($AZ31,$BA31:BH31)-SUM($EU31:FC31) -> -631 | DG31: =SUM($AZ31,$BA31:BI31)-SUM($EU31:FD31) -> -631 | DH31: =SUM($AZ31,$BA31:BJ31)-SUM($EU31:FE31) -> -631 | DI31: =SUM($AZ31,$BA31:BK31)-SUM($EU31:FF31) -> -631 | DJ31: =SUM($AZ31,$BA31:BL31)-SUM($EU31:FG31) -> -631 | DK31: =SUM($AZ31,$BA31:BM31)-SUM($EU31:FH31) -> -631 | ... EQ31: =SUM($AZ31,$BA31:CS31)-SUM($EU31:GN31) -> -631 | FA31: {=SUMPRODUCT($K31:$AG31,TRANSPOSE(FA$5:FA$27))} -> 100 | FB31: {=SUMPRODUCT($K31:$AG31,TRANSPOSE(FB$5:FB$27))} -> 200 | FC31: {=SUMPRODUCT($K31:$AG31,TRANSPOSE(FC$5:FC$27))} -> 331 | FD31: {=SUMPRODUCT($K31:$AG31,TRANSPOSE(FD$5:FD$27))} -> 0 | FE31: {=SUMPRODUCT($K31:$AG31,TRANSPOSE(FE$5:FE$27))} -> 0 | FF31: {=SUMPRODUCT($K31:$AG31,TRANSPOSE(FF$5:FF$27))} -> 0 | FG31: {=SUMPRODUCT($K31:$AG31,TRANSPOSE(FG$5:FG$27))} -> 0 | FH31: {=SUMPRODUCT($K31:$AG31,TRANSPOSE(FH$5:FH$27))} -> 0 | ... GN31: {=SUMPRODUCT($K31:$AG31,TRANSPOSE(GN$5:GN$27))} -> 0 | IV31: ASSY | IW31: =C31 -> 1096M170-001 | IX31: =AL31 -> ASSY | IY31: =AP31 -> 0 | IZ31: =AQ31 -> 0 | JA31: =_xlfn.XLOOKUP(IZ31,IZ$21:IZ$24,JA$21:JA$24,0) -> #NAME? | JB31: =IY31*JA31 -> #NAME? | JC31: =AJ31 -> 1 | JD31: =AJ31 -> 1 | JF31: =MAX(JD31,CEILING(#REF!+JE31,JC31)) -> #REF! | JG31: =JF31*JB31 -> #REF! | JH31: =JF31-#REF! -> #REF! | JI31: =JH31*JB31 -> #REF! | JJ31: 45523 | JK31: Sagi | JL31: ASSY | JO31: {=SUMPRODUCT(#REF!,TRANSPOSE(JO$19:JO$22))} -> #REF! | JP31: {=SUMPRODUCT(#REF!,TRANSPOSE(JP$19:JP$22))} -> #REF! | JQ31: {=SUMPRODUCT(#REF!,TRANSPOSE(JQ$19:JQ$22))} -> #REF! | JR31: {=SUMPRODUCT(#REF!,TRANSPOSE(JR$19:JR$22))} -> #REF! | JS31: {=SUMPRODUCT(#REF!,TRANSPOSE(JS$19:JS$22))} -> #REF! | JT31: {=SUMPRODUCT(#REF!,TRANSPOSE(JT$19:JT$22))} -> #REF! | JU31: {=SUMPRODUCT(#REF!,TRANSPOSE(JU$19:JU$22))} -> #REF! | JV31: {=SUMPRODUCT(#REF!,TRANSPOSE(JV$19:JV$22))} -> #REF! | ... KA31: {=SUMPRODUCT(#REF!,TRANSPOSE(KA$19:KA$22))} -> #REF! | KC31: =CEILING(JO31,$JC31) -> #REF! | KD31: =CEILING(SUM($JO31:JP31)-SUM($KC31:KC31),$JC31) -> #REF! | KE31: =CEILING(SUM($JO31:JQ31)-SUM($KC31:KD31),$JC31) -> #REF! | KF31: =CEILING(SUM($JO31:JR31)-SUM($KC31:KE31),$JC31) -> #REF! | KG31: =CEILING(SUM($JO31:JS31)-SUM($KC31:KF31),$JC31) -> #REF! | KH31: =CEILING(SUM($JO31:JT31)-SUM($KC31:KG31),$JC31) -> #REF! | KI31: =CEILING(SUM($JO31:JU31)-SUM($KC31:KH31),$JC31) -> #REF! | KJ31: =CEILING(SUM($JO31:JV31)-SUM($KC31:KI31),$JC31) -> #REF! | KK31: =CEILING(SUM($JO31:JW31)-SUM($KC31:KJ31),$JC31) -> #REF! | ... KM31: =CEILING(SUM($JO31:JY31)-SUM($KC31:KL31),$JC31) -> #REF! | KN31: =JF31-SUM(KC31:KM31) -> #REF! | KO31: =JF31-SUM(KC31:KN31) -> #REF! | KQ31: =KC31*$JB31 -> #REF! | KR31: =KD31*$JB31 -> #REF! | KS31: =KE31*$JB31 -> #REF! | KT31: =KF31*$JB31 -> #REF! | KU31: =KG31*$JB31 -> #REF! | KV31: =KH31*$JB31 -> #REF! | KW31: =KI31*$JB31 -> #REF! | KX31: =KJ31*$JB31 -> #REF! | ... LC31: =KO31*$JB31 -> #REF! | LD31: =SUM(KQ31:LC31) -> #REF! | LR31: =KO31 -> #REF! | LT31: =LF31*$JB31 -> #NAME? | LU31: =LG31*$JB31 -> #NAME? | LV31: =LH31*$JB31 -> #NAME? | LW31: =LI31*$JB31 -> #NAME? | LX31: =LJ31*$JB31 -> #NAME? | LY31: =LK31*$JB31 -> #NAME? | LZ31: =LL31*$JB31 -> #NAME? | MA31: =LM31*$JB31 -> #NAME? | ... MF31: =LR31*$JB31 -> #REF! | MG31: =SUM(LT31:MF31) -> #NAME? | MH31: LT01-274
A32: 4 | B32: LT01-003 | C32: 000800-0826 | D32: BUY1 | E32: 400550300 | F32: CONN RECT PCB R/A PLUG 42 BLADES 3 ROWS, | G32: 404421765 | H32: EA | I32: 2 | J32: 3 | K32: 0 | L32: 0 | M32: 0 | N32: 0 | O32: 1 | P32: 0 | Q32: 0 | R32: 0 | S32: 0 | T32: 0 | U32: 0 | V32: 0 | W32: 0 | X32: 1 | Y32: 0 | Z32: 0 | AA32: 0 | AB32: 0 | AC32: 0 | AD32: 0 | AE32: 0 | AF32: 0 | AG32: 1 | AH32: =SUM(K32:AB32) -> 2 | AI32: =SUMPRODUCT(K32:AG32,$K$24:$AG$24) -> 70589 | AJ32: 1 | AL32: DCX-CHOL Entr. Inc | AM32: Masterite | AP32: 23 | AQ32: USD | AR32: Elad Zafrir | AS32: elad.zafrir@emet.co.il | AU32: 972-54-302-7334 | AV32: =MI32 -> P0011 | AW32: =JB32 -> #NAME? | AY32: =JF32 -> #REF! | BG32: 3000 | DD32: =SUM($AZ32,$BA32:BF32)-SUM($EU32:FA32) -> -460 | DE32: =SUM($AZ32,$BA32:BG32)-SUM($EU32:FB32) -> 742 | DF32: =SUM($AZ32,$BA32:BH32)-SUM($EU32:FC32) -> -1589 | DG32: =SUM($AZ32,$BA32:BI32)-SUM($EU32:FD32) -> -3589 | DH32: =SUM($AZ32,$BA32:BJ32)-SUM($EU32:FE32) -> -5589 | DI32: =SUM($AZ32,$BA32:BK32)-SUM($EU32:FF32) -> -7589 | DJ32: =SUM($AZ32,$BA32:BL32)-SUM($EU32:FG32) -> -9589 | DK32: =SUM($AZ32,$BA32:BM32)-SUM($EU32:FH32) -> -11589 | ... EQ32: =SUM($AZ32,$BA32:CS32)-SUM($EU32:GN32) -> -67589 | FA32: {=SUMPRODUCT($K32:$AG32,TRANSPOSE(FA$5:FA$27))} -> 460 | FB32: {=SUMPRODUCT($K32:$AG32,TRANSPOSE(FB$5:FB$27))} -> 1798 | FC32: {=SUMPRODUCT($K32:$AG32,TRANSPOSE(FC$5:FC$27))} -> 2331 | FD32: {=SUMPRODUCT($K32:$AG32,TRANSPOSE(FD$5:FD$27))} -> 2000 | FE32: {=SUMPRODUCT($K32:$AG32,TRANSPOSE(FE$5:FE$27))} -> 2000 | FF32: {=SUMPRODUCT($K32:$AG32,TRANSPOSE(FF$5:FF$27))} -> 2000 | FG32: {=SUMPRODUCT($K32:$AG32,TRANSPOSE(FG$5:FG$27))} -> 2000 | FH32: {=SUMPRODUCT($K32:$AG32,TRANSPOSE(FH$5:FH$27))} -> 2000 | ... GN32: {=SUMPRODUCT($K32:$AG32,TRANSPOSE(GN$5:GN$27))} -> 0 | IV32: =AM32 -> Masterite | IW32: =C32 -> 000800-0826 | IX32: =AL32 -> DCX-CHOL Entr. Inc | IY32: =AP32 -> 23 | IZ32: =AQ32 -> USD | JA32: =_xlfn.XLOOKUP(IZ32,IZ$21:IZ$24,JA$21:JA$24,0) -> #NAME? | JB32: =IY32*JA32 -> #NAME? | JC32: =AJ32 -> 1 | JD32: =AJ32 -> 1 | JE32: 50 | JF32: =MAX(JD32,CEILING(#REF!+JE32,JC32)) -> #REF! | JG32: =JF32*JB32 -> #REF! | JH32: =JF32-#REF! -> #REF! | JI32: =JH32*JB32 -> #REF! | JJ32: 45523 | JK32: Sagi | JL32: Ordered | JM32: Y | JN32: RNSE | JO32: {=SUMPRODUCT(#REF!,TRANSPOSE(JO$19:JO$22))} -> #REF! | JP32: {=SUMPRODUCT(#REF!,TRANSPOSE(JP$19:JP$22))} -> #REF! | JQ32: {=SUMPRODUCT(#REF!,TRANSPOSE(JQ$19:JQ$22))} -> #REF! | JR32: {=SUMPRODUCT(#REF!,TRANSPOSE(JR$19:JR$22))} -> #REF! | JS32: {=SUMPRODUCT(#REF!,TRANSPOSE(JS$19:JS$22))} -> #REF! | JT32: {=SUMPRODUCT(#REF!,TRANSPOSE(JT$19:JT$22))} -> #REF! | JU32: {=SUMPRODUCT(#REF!,TRANSPOSE(JU$19:JU$22))} -> #REF! | JV32: {=SUMPRODUCT(#REF!,TRANSPOSE(JV$19:JV$22))} -> #REF! | ... KA32: {=SUMPRODUCT(#REF!,TRANSPOSE(KA$19:KA$22))} -> #REF! | KC32: =CEILING(JO32,$JC32) -> #REF! | KD32: =CEILING(SUM($JO32:JP32)-SUM($KC32:KC32),$JC32) -> #REF! | KE32: =CEILING(SUM($JO32:JQ32)-SUM($KC32:KD32),$JC32) -> #REF! | KF32: =CEILING(SUM($JO32:JR32)-SUM($KC32:KE32),$JC32) -> #REF! | KG32: =CEILING(SUM($JO32:JS32)-SUM($KC32:KF32),$JC32) -> #REF! | KH32: =CEILING(SUM($JO32:JT32)-SUM($KC32:KG32),$JC32) -> #REF! | KI32: =CEILING(SUM($JO32:JU32)-SUM($KC32:KH32),$JC32) -> #REF! | KJ32: =CEILING(SUM($JO32:JV32)-SUM($KC32:KI32),$JC32) -> #REF! | KK32: =CEILING(SUM($JO32:JW32)-SUM($KC32:KJ32),$JC32) -> #REF! | ... KM32: =CEILING(SUM($JO32:JY32)-SUM($KC32:KL32),$JC32) -> #REF! | KN32: =JF32-SUM(KC32:KM32) -> #REF! | KO32: =JF32-SUM(KC32:KN32) -> #REF! | KQ32: =KC32*$JB32 -> #REF! | KR32: =KD32*$JB32 -> #REF! | KS32: =KE32*$JB32 -> #REF! | KT32: =KF32*$JB32 -> #REF! | KU32: =KG32*$JB32 -> #REF! | KV32: =KH32*$JB32 -> #REF! | KW32: =KI32*$JB32 -> #REF! | KX32: =KJ32*$JB32 -> #REF! | ... LC32: =KO32*$JB32 -> #REF! | LD32: =SUM(KQ32:LC32) -> #REF! | LE32: 12 | LF32: =KC32 -> #REF! | LG32: =KD32 -> #REF! | LH32: =KE32 -> #REF! | LI32: =KF32 -> #REF! | LJ32: =KG32 -> #REF! | LK32: =KH32 -> #REF! | LL32: =KI32 -> #REF! | LM32: =KJ32 -> #REF! | ... LR32: =KO32 -> #REF! | LT32: =LF32*$JB32 -> #REF! | LU32: =LG32*$JB32 -> #REF! | LV32: =LH32*$JB32 -> #REF! | LW32: =LI32*$JB32 -> #REF! | LX32: =LJ32*$JB32 -> #REF! | LY32: =LK32*$JB32 -> #REF! | LZ32: =LL32*$JB32 -> #REF! | MA32: =LM32*$JB32 -> #REF! | ... MF32: =LR32*$JB32 -> #REF! | MG32: =SUM(LT32:MF32) -> #REF! | MH32: LT01-003 | MI32: P0011 | MJ32: 45523 | MK32: Yes | ML32: Yes | MM32: Yes
A33: 5 | B33: LT01-004 | C33: 04021J0R3PBSTR | D33: BUY1 | E33: 401238835 | F33: CHIP CAP 0.3PF +-.02PF 100V T&R | H33: EA | I33: 2 | J33: 6 | K33: 0 | L33: 0 | M33: 0 | N33: 2 | O33: 0 | P33: 0 | Q33: 0 | R33: 0 | S33: 2 | T33: 0 | U33: 0 | V33: 0 | W33: 0 | X33: 0 | Y33: 0 | Z33: 0 | AA33: 0 | AB33: 2 | AC33: 0 | AD33: 0 | AE33: 0 | AF33: 0 | AG33: 0 | AH33: =SUM(K33:AB33) -> 6 | AI33: =SUMPRODUCT(K33:AG33,$K$24:$AG$24) -> 141178 | AJ33: 10000 | AL33: AVX | AM33: SHIRTECH | AP33: 0.18 | AQ33: USD | AR33: LIZA COHEN | AS33: LIZA@SHIRTECH.CO.IL | AU33: 972-3-9516495 | AV33: =MI33 -> P0037 | AW33: =JB33 -> #NAME? | AX33: 14 | AY33: =JF33 -> #REF! | BF33: 80000 | BL33: 70000 | DD33: =SUM($AZ33,$BA33:BF33)-SUM($EU33:FA33) -> 79080 | DE33: =SUM($AZ33,$BA33:BG33)-SUM($EU33:FB33) -> 75484 | DF33: =SUM($AZ33,$BA33:BH33)-SUM($EU33:FC33) -> 70822 | DG33: =SUM($AZ33,$BA33:BI33)-SUM($EU33:FD33) -> 66822 | DH33: =SUM($AZ33,$BA33:BJ33)-SUM($EU33:FE33) -> 62822 | DI33: =SUM($AZ33,$BA33:BK33)-SUM($EU33:FF33) -> 58822 | DJ33: =SUM($AZ33,$BA33:BL33)-SUM($EU33:FG33) -> 124822 | DK33: =SUM($AZ33,$BA33:BM33)-SUM($EU33:FH33) -> 120822 | ... EQ33: =SUM($AZ33,$BA33:CS33)-SUM($EU33:GN33) -> 8822 | FA33: {=SUMPRODUCT($K33:$AG33,TRANSPOSE(FA$5:FA$27))} -> 920 | FB33: {=SUMPRODUCT($K33:$AG33,TRANSPOSE(FB$5:FB$27))} -> 3596 | FC33: {=SUMPRODUCT($K33:$AG33,TRANSPOSE(FC$5:FC$27))} -> 4662 | FD33: {=SUMPRODUCT($K33:$AG33,TRANSPOSE(FD$5:FD$27))} -> 4000 | FE33: {=SUMPRODUCT($K33:$AG33,TRANSPOSE(FE$5:FE$27))} -> 4000 | FF33: {=SUMPRODUCT($K33:$AG33,TRANSPOSE(FF$5:FF$27))} -> 4000 | FG33: {=SUMPRODUCT($K33:$AG33,TRANSPOSE(FG$5:FG$27))} -> 4000 | FH33: {=SUMPRODUCT($K33:$AG33,TRANSPOSE(FH$5:FH$27))} -> 4000 | ... GN33: {=SUMPRODUCT($K33:$AG33,TRANSPOSE(GN$5:GN$27))} -> 0 | IV33: PHONIX TECHNOLOGIES | IW33: =C33 -> 04021J0R3PBSTR | IX33: =AL33 -> AVX | IY33: 0.175 | IZ33: =AQ33 -> USD | JA33: =_xlfn.XLOOKUP(IZ33,IZ$21:IZ$24,JA$21:JA$24,0) -> #NAME? | JB33: =IY33*JA33 -> #NAME? | JC33: =AJ33 -> 10000 | JD33: =AJ33 -> 10000 | JF33: =MAX(JD33,CEILING(#REF!+JE33,JC33)) -> #REF! | JG33: =JF33*JB33 -> #REF! | JH33: =JF33-#REF! -> #REF! | JI33: =JH33*JB33 -> #REF! | JJ33: 45523 | JK33: Sagi | JL33: Ordered | JM33: Y | JN33: RNSE | JO33: {=SUMPRODUCT(#REF!,TRANSPOSE(JO$19:JO$22))} -> #REF! | JP33: {=SUMPRODUCT(#REF!,TRANSPOSE(JP$19:JP$22))} -> #REF! | JQ33: {=SUMPRODUCT(#REF!,TRANSPOSE(JQ$19:JQ$22))} -> #REF! | JR33: {=SUMPRODUCT(#REF!,TRANSPOSE(JR$19:JR$22))} -> #REF! | JS33: {=SUMPRODUCT(#REF!,TRANSPOSE(JS$19:JS$22))} -> #REF! | JT33: {=SUMPRODUCT(#REF!,TRANSPOSE(JT$19:JT$22))} -> #REF! | JU33: {=SUMPRODUCT(#REF!,TRANSPOSE(JU$19:JU$22))} -> #REF! | JV33: {=SUMPRODUCT(#REF!,TRANSPOSE(JV$19:JV$22))} -> #REF! | ... KA33: {=SUMPRODUCT(#REF!,TRANSPOSE(KA$19:KA$22))} -> #REF! | KC33: =CEILING(JO33,$JC33) -> #REF! | KD33: =CEILING(SUM($JO33:JP33)-SUM($KC33:KC33),$JC33) -> #REF! | KE33: =CEILING(SUM($JO33:JQ33)-SUM($KC33:KD33),$JC33) -> #REF! | KF33: =CEILING(SUM($JO33:JR33)-SUM($KC33:KE33),$JC33) -> #REF! | KG33: =CEILING(SUM($JO33:JS33)-SUM($KC33:KF33),$JC33) -> #REF! | KH33: =CEILING(SUM($JO33:JT33)-SUM($KC33:KG33),$JC33) -> #REF! | KI33: =CEILING(SUM($JO33:JU33)-SUM($KC33:KH33),$JC33) -> #REF! | KJ33: =CEILING(SUM($JO33:JV33)-SUM($KC33:KI33),$JC33) -> #REF! | KK33: =CEILING(SUM($JO33:JW33)-SUM($KC33:KJ33),$JC33) -> #REF! | ... KM33: =CEILING(SUM($JO33:JY33)-SUM($KC33:KL33),$JC33) -> #REF! | KN33: =JF33-SUM(KC33:KM33) -> #REF! | KO33: =JF33-SUM(KC33:KN33) -> #REF! | KQ33: =KC33*$JB33 -> #REF! | KR33: =KD33*$JB33 -> #REF! | KS33: =KE33*$JB33 -> #REF! | KT33: =KF33*$JB33 -> #REF! | KU33: =KG33*$JB33 -> #REF! | KV33: =KH33*$JB33 -> #REF! | KW33: =KI33*$JB33 -> #REF! | KX33: =KJ33*$JB33 -> #REF! | ... LC33: =KO33*$JB33 -> #REF! | LD33: =SUM(KQ33:LC33) -> #REF! | LE33: 2 | LF33: =SUM(KC33:KH33) -> #REF! | LL33: =SUM(KI33:KO33) -> #REF! | LT33: =LF33*$JB33 -> #REF! | LU33: =LG33*$JB33 -> #NAME? | LV33: =LH33*$JB33 -> #NAME? | LW33: =LI33*$JB33 -> #NAME? | LX33: =LJ33*$JB33 -> #NAME? | LY33: =LK33*$JB33 -> #NAME? | LZ33: =LL33*$JB33 -> #REF! | MA33: =LM33*$JB33 -> #NAME? | ... MF33: =LR33*$JB33 -> #NAME? | MG33: =SUM(LT33:MF33) -> #REF! | MH33: LT01-004 | MI33: P0037 | MJ33: 45526 | MK33: Yes | MM33: Yes | MO33: Israel
A34: 6 | B34: LT01-005 | C34: 0402CS-5N6XGRW | D34: BUY1 | E34: 408260904 | F34: INDUCTOR CHIP 5.6NH 2^ 0.76A 0402 T&R | H34: EA | I34: 1 | J34: 6 | K34: 0 | L34: 0 | M34: 0 | N34: 2 | O34: 0 | P34: 0 | Q34: 0 | R34: 0 | S34: 2 | T34: 0 | U34: 0 | V34: 0 | W34: 0 | X34: 0 | Y34: 0 | Z34: 0 | AA34: 0 | AB34: 2 | AC34: 0 | AD34: 0 | AE34: 0 | AF34: 0 | AG34: 0 | AH34: =SUM(K34:AB34) -> 6 | AI34: =SUMPRODUCT(K34:AG34,$K$24:$AG$24) -> 141178 | AJ34: 2000 | AL34: COILCRAFT INC. | AM34: ELINA | AP34: 0.072 | AQ34: USD | AR34: Avi Elia | AS34: avi@elina.co.il | AU34: 972.73.2224830 | AV34: =MI34 -> P0025 | AW34: =JB34 -> #NAME? | AX34: 7 | AY34: =JF34 -> #REF! | BE34: 142000 | DD34: =SUM($AZ34,$BA34:BF34)-SUM($EU34:FA34) -> 141080 | DE34: =SUM($AZ34,$BA34:BG34)-SUM($EU34:FB34) -> 137484 | DF34: =SUM($AZ34,$BA34:BH34)-SUM($EU34:FC34) -> 132822 | DG34: =SUM($AZ34,$BA34:BI34)-SUM($EU34:FD34) -> 128822 | DH34: =SUM($AZ34,$BA34:BJ34)-SUM($EU34:FE34) -> 124822 | DI34: =SUM($AZ34,$BA34:BK34)-SUM($EU34:FF34) -> 120822 | DJ34: =SUM($AZ34,$BA34:BL34)-SUM($EU34:FG34) -> 116822 | DK34: =SUM($AZ34,$BA34:BM34)-SUM($EU34:FH34) -> 112822 | ... EQ34: =SUM($AZ34,$BA34:CS34)-SUM($EU34:GN34) -> 822 | FA34: {=SUMPRODUCT($K34:$AG34,TRANSPOSE(FA$5:FA$27))} -> 920 | FB34: {=SUMPRODUCT($K34:$AG34,TRANSPOSE(FB$5:FB$27))} -> 3596 | FC34: {=SUMPRODUCT($K34:$AG34,TRANSPOSE(FC$5:FC$27))} -> 4662 | FD34: {=SUMPRODUCT($K34:$AG34,TRANSPOSE(FD$5:FD$27))} -> 4000 | FE34: {=SUMPRODUCT($K34:$AG34,TRANSPOSE(FE$5:FE$27))} -> 4000 | FF34: {=SUMPRODUCT($K34:$AG34,TRANSPOSE(FF$5:FF$27))} -> 4000 | FG34: {=SUMPRODUCT($K34:$AG34,TRANSPOSE(FG$5:FG$27))} -> 4000 | FH34: {=SUMPRODUCT($K34:$AG34,TRANSPOSE(FH$5:FH$27))} -> 4000 | ... GN34: {=SUMPRODUCT($K34:$AG34,TRANSPOSE(GN$5:GN$27))} -> 0 | IV34: coilcraft | IW34: =C34 -> 0402CS-5N6XGRW | IX34: =AL34 -> COILCRAFT INC. | IY34: =AP34 -> 0.072 | IZ34: =AQ34 -> USD | JA34: =_xlfn.XLOOKUP(IZ34,IZ$21:IZ$24,JA$21:JA$24,0) -> #NAME? | JB34: =IY34*JA34 -> #NAME? | JC34: =AJ34 -> 2000 | JD34: 10000 | JF34: =MAX(JD34,CEILING(#REF!+JE34,JC34)) -> #REF! | JG34: =JF34*JB34 -> #REF! | JH34: =JF34-#REF! -> #REF! | JI34: =JH34*JB34 -> #REF! | JJ34: 45523 | JK34: Sagi | JL34: Ordered | JM34: Y | JN34: RNSE | JO34: {=SUMPRODUCT(#REF!,TRANSPOSE(JO$19:JO$22))} -> #REF! | JP34: {=SUMPRODUCT(#REF!,TRANSPOSE(JP$19:JP$22))} -> #REF! | JQ34: {=SUMPRODUCT(#REF!,TRANSPOSE(JQ$19:JQ$22))} -> #REF! | JR34: {=SUMPRODUCT(#REF!,TRANSPOSE(JR$19:JR$22))} -> #REF! | JS34: {=SUMPRODUCT(#REF!,TRANSPOSE(JS$19:JS$22))} -> #REF! | JT34: {=SUMPRODUCT(#REF!,TRANSPOSE(JT$19:JT$22))} -> #REF! | JU34: {=SUMPRODUCT(#REF!,TRANSPOSE(JU$19:JU$22))} -> #REF! | JV34: {=SUMPRODUCT(#REF!,TRANSPOSE(JV$19:JV$22))} -> #REF! | ... KA34: {=SUMPRODUCT(#REF!,TRANSPOSE(KA$19:KA$22))} -> #REF! | KC34: =CEILING(JO34,$JC34) -> #REF! | KD34: =CEILING(SUM($JO34:JP34)-SUM($KC34:KC34),$JC34) -> #REF! | KE34: =CEILING(SUM($JO34:JQ34)-SUM($KC34:KD34),$JC34) -> #REF! | KF34: =CEILING(SUM($JO34:JR34)-SUM($KC34:KE34),$JC34) -> #REF! | KG34: =CEILING(SUM($JO34:JS34)-SUM($KC34:KF34),$JC34) -> #REF! | KH34: =CEILING(SUM($JO34:JT34)-SUM($KC34:KG34),$JC34) -> #REF! | KI34: =CEILING(SUM($JO34:JU34)-SUM($KC34:KH34),$JC34) -> #REF! | KJ34: =CEILING(SUM($JO34:JV34)-SUM($KC34:KI34),$JC34) -> #REF! | KK34: =CEILING(SUM($JO34:JW34)-SUM($KC34:KJ34),$JC34) -> #REF! | ... KM34: =CEILING(SUM($JO34:JY34)-SUM($KC34:KL34),$JC34) -> #REF! | KN34: =JF34-SUM(KC34:KM34) -> #REF! | KO34: =JF34-SUM(KC34:KN34) -> #REF! | KQ34: =KC34*$JB34 -> #REF! | KR34: =KD34*$JB34 -> #REF! | KS34: =KE34*$JB34 -> #REF! | KT34: =KF34*$JB34 -> #REF! | KU34: =KG34*$JB34 -> #REF! | KV34: =KH34*$JB34 -> #REF! | KW34: =KI34*$JB34 -> #REF! | KX34: =KJ34*$JB34 -> #REF! | ... LC34: =KO34*$JB34 -> #REF! | LD34: =SUM(KQ34:LC34) -> #REF! | LE34: 1 | LF34: =SUM(KC34:KO34) -> #REF! | LR34: =KO34 -> #REF! | LT34: =LF34*$JB34 -> #REF! | LU34: =LG34*$JB34 -> #NAME? | LV34: =LH34*$JB34 -> #NAME? | LW34: =LI34*$JB34 -> #NAME? | LX34: =LJ34*$JB34 -> #NAME? | LY34: =LK34*$JB34 -> #NAME? | LZ34: =LL34*$JB34 -> #NAME? | MA34: =LM34*$JB34 -> #NAME? | ... MF34: =LR34*$JB34 -> #REF! | MG34: =SUM(LT34:MF34) -> #REF! | MH34: LT01-005 | MI34: P0025 | MJ34: 45526 | MK34: Yes | ML34: Yes | MM34: Yes | MO34: Indonesia / Malaysia / Vietnam
A35: 7 | B35: LT01-006 | C35: 0603CS-15NXGRW | D35: BUY1 | E35: 407184523 | F35: CHIP INDUCTOR 15NH 2^ T&R | H35: EA | I35: 1 | J35: 16 | K35: 0 | L35: 0 | M35: 0 | N35: 4 | O35: 0 | P35: 0 | Q35: 0 | R35: 0 | S35: 6 | T35: 0 | U35: 0 | V35: 0 | W35: 0 | X35: 0 | Y35: 0 | Z35: 0 | AA35: 0 | AB35: 6 | AC35: 0 | AD35: 0 | AE35: 0 | AF35: 0 | AG35: 0 | AH35: =SUM(K35:AB35) -> 16 | AI35: =SUMPRODUCT(K35:AG35,$K$24:$AG$24) -> 353978 | AJ35: 2000 | AL35: COILCRAFT INC. | AM35: ELINA | AP35: 0.065 | AQ35: USD | AR35: Avi Elia | AS35: avi@elina.co.il | AU35: 972.73.2224830 | AV35: =MI35 -> P0025 | AW35: =JB35 -> #NAME? | AX35: 7 | AY35: =JF35 -> #REF! | BE35: 354000 | DD35: =SUM($AZ35,$BA35:BF35)-SUM($EU35:FA35) -> 351600 | DE35: =SUM($AZ35,$BA35:BG35)-SUM($EU35:FB35) -> 342008 | DF35: =SUM($AZ35,$BA35:BH35)-SUM($EU35:FC35) -> 330022 | DG35: =SUM($AZ35,$BA35:BI35)-SUM($EU35:FD35) -> 320022 | DH35: =SUM($AZ35,$BA35:BJ35)-SUM($EU35:FE35) -> 310022 | DI35: =SUM($AZ35,$BA35:BK35)-SUM($EU35:FF35) -> 300022 | DJ35: =SUM($AZ35,$BA35:BL35)-SUM($EU35:FG35) -> 290022 | DK35: =SUM($AZ35,$BA35:BM35)-SUM($EU35:FH35) -> 280022 | ... EQ35: =SUM($AZ35,$BA35:CS35)-SUM($EU35:GN35) -> 22 | FA35: {=SUMPRODUCT($K35:$AG35,TRANSPOSE(FA$5:FA$27))} -> 2400 | FB35: {=SUMPRODUCT($K35:$AG35,TRANSPOSE(FB$5:FB$27))} -> 9592 | FC35: {=SUMPRODUCT($K35:$AG35,TRANSPOSE(FC$5:FC$27))} -> 11986 | FD35: {=SUMPRODUCT($K35:$AG35,TRANSPOSE(FD$5:FD$27))} -> 10000 | FE35: {=SUMPRODUCT($K35:$AG35,TRANSPOSE(FE$5:FE$27))} -> 10000 | FF35: {=SUMPRODUCT($K35:$AG35,TRANSPOSE(FF$5:FF$27))} -> 10000 | FG35: {=SUMPRODUCT($K35:$AG35,TRANSPOSE(FG$5:FG$27))} -> 10000 | FH35: {=SUMPRODUCT($K35:$AG35,TRANSPOSE(FH$5:FH$27))} -> 10000 | ... GN35: {=SUMPRODUCT($K35:$AG35,TRANSPOSE(GN$5:GN$27))} -> 0 | IV35: coilcraft | IW35: =C35 -> 0603CS-15NXGRW | IX35: =AL35 -> COILCRAFT INC. | IY35: =AP35 -> 0.065 | IZ35: =AQ35 -> USD | JA35: =_xlfn.XLOOKUP(IZ35,IZ$21:IZ$24,JA$21:JA$24,0) -> #NAME? | JB35: =IY35*JA35 -> #NAME? | JC35: =AJ35 -> 2000 | JD35: 26000 | JF35: =MAX(JD35,CEILING(#REF!+JE35,JC35)) -> #REF! | JG35: =JF35*JB35 -> #REF! | JH35: =JF35-#REF! -> #REF! | JI35: =JH35*JB35 -> #REF! | JJ35: 45523 | JK35: Sagi | JL35: Ordered | JM35: Y | JN35: RNSE | JO35: {=SUMPRODUCT(#REF!,TRANSPOSE(JO$19:JO$22))} -> #REF! | JP35: {=SUMPRODUCT(#REF!,TRANSPOSE(JP$19:JP$22))} -> #REF! | JQ35: {=SUMPRODUCT(#REF!,TRANSPOSE(JQ$19:JQ$22))} -> #REF! | JR35: {=SUMPRODUCT(#REF!,TRANSPOSE(JR$19:JR$22))} -> #REF! | JS35: {=SUMPRODUCT(#REF!,TRANSPOSE(JS$19:JS$22))} -> #REF! | JT35: {=SUMPRODUCT(#REF!,TRANSPOSE(JT$19:JT$22))} -> #REF! | JU35: {=SUMPRODUCT(#REF!,TRANSPOSE(JU$19:JU$22))} -> #REF! | JV35: {=SUMPRODUCT(#REF!,TRANSPOSE(JV$19:JV$22))} -> #REF! | ... KA35: {=SUMPRODUCT(#REF!,TRANSPOSE(KA$19:KA$22))} -> #REF! | KC35: =CEILING(JO35,$JC35) -> #REF! | KD35: =CEILING(SUM($JO35:JP35)-SUM($KC35:KC35),$JC35) -> #REF! | KE35: =CEILING(SUM($JO35:JQ35)-SUM($KC35:KD35),$JC35) -> #REF! | KF35: =CEILING(SUM($JO35:JR35)-SUM($KC35:KE35),$JC35) -> #REF! | KG35: =CEILING(SUM($JO35:JS35)-SUM($KC35:KF35),$JC35) -> #REF! | KH35: =CEILING(SUM($JO35:JT35)-SUM($KC35:KG35),$JC35) -> #REF! | KI35: =CEILING(SUM($JO35:JU35)-SUM($KC35:KH35),$JC35) -> #REF! | KJ35: =CEILING(SUM($JO35:JV35)-SUM($KC35:KI35),$JC35) -> #REF! | KK35: =CEILING(SUM($JO35:JW35)-SUM($KC35:KJ35),$JC35) -> #REF! | ... KM35: =CEILING(SUM($JO35:JY35)-SUM($KC35:KL35),$JC35) -> #REF! | KN35: =JF35-SUM(KC35:KM35) -> #REF! | KO35: =JF35-SUM(KC35:KN35) -> #REF! | KQ35: =KC35*$JB35 -> #REF! | KR35: =KD35*$JB35 -> #REF! | KS35: =KE35*$JB35 -> #REF! | KT35: =KF35*$JB35 -> #REF! | KU35: =KG35*$JB35 -> #REF! | KV35: =KH35*$JB35 -> #REF! | KW35: =KI35*$JB35 -> #REF! | KX35: =KJ35*$JB35 -> #REF! | ... LC35: =KO35*$JB35 -> #REF! | LD35: =SUM(KQ35:LC35) -> #REF! | LE35: 2 | LF35: =SUM(KC35:KH35) -> #REF! | LL35: =SUM(KI35:KO35) -> #REF! | LT35: =LF35*$JB35 -> #REF! | LU35: =LG35*$JB35 -> #NAME? | LV35: =LH35*$JB35 -> #NAME? | LW35: =LI35*$JB35 -> #NAME? | LX35: =LJ35*$JB35 -> #NAME? | LY35: =LK35*$JB35 -> #NAME? | LZ35: =LL35*$JB35 -> #REF! | MA35: =LM35*$JB35 -> #NAME? | ... MF35: =LR35*$JB35 -> #NAME? | MG35: =SUM(LT35:MF35) -> #REF! | MH35: LT01-006 | MI35: P0025 | MJ35: 45526 | MK35: Yes | ML35: Yes | MM35: Yes | MO35: Indonesia / Malaysia / Vietnam
A36: 8 | B36: LT01-007 | C36: 0603CS-8N7XGLW | D36: BUY1 | E36: 400236023 | F36: CHIP INDUCTOR 8.7NH 2% T&R | H36: EA | I36: 2 | J36: 4 | K36: 0 | L36: 0 | M36: 0 | N36: 0 | O36: 0 | P36: 0 | Q36: 0 | R36: 0 | S36: 2 | T36: 0 | U36: 0 | V36: 0 | W36: 0 | X36: 0 | Y36: 0 | Z36: 0 | AA36: 0 | AB36: 2 | AC36: 0 | AD36: 0 | AE36: 0 | AF36: 0 | AG36: 0 | AH36: =SUM(K36:AB36) -> 4 | AI36: =SUMPRODUCT(K36:AG36,$K$24:$AG$24) -> 71622 | AJ36: 2000 | AL36: COILCRAFT INC. | AM36: ELINA | AP36: 0.072 | AQ36: USD | AR36: Avi Elia | AS36: avi@elina.co.il | AU36: 972.73.2224830 | AV36: =MI36 -> P0025 | AW36: =JB36 -> #NAME? | AX36: 7 | AY36: =JF36 -> #REF! | BE36: 72000 | DD36: =SUM($AZ36,$BA36:BF36)-SUM($EU36:FA36) -> 71440 | DE36: =SUM($AZ36,$BA36:BG36)-SUM($EU36:FB36) -> 69040 | DF36: =SUM($AZ36,$BA36:BH36)-SUM($EU36:FC36) -> 66378 | DG36: =SUM($AZ36,$BA36:BI36)-SUM($EU36:FD36) -> 64378 | DH36: =SUM($AZ36,$BA36:BJ36)-SUM($EU36:FE36) -> 62378 | DI36: =SUM($AZ36,$BA36:BK36)-SUM($EU36:FF36) -> 60378 | DJ36: =SUM($AZ36,$BA36:BL36)-SUM($EU36:FG36) -> 58378 | DK36: =SUM($AZ36,$BA36:BM36)-SUM($EU36:FH36) -> 56378 | ... EQ36: =SUM($AZ36,$BA36:CS36)-SUM($EU36:GN36) -> 378 | FA36: {=SUMPRODUCT($K36:$AG36,TRANSPOSE(FA$5:FA$27))} -> 560 | FB36: {=SUMPRODUCT($K36:$AG36,TRANSPOSE(FB$5:FB$27))} -> 2400 | FC36: {=SUMPRODUCT($K36:$AG36,TRANSPOSE(FC$5:FC$27))} -> 2662 | FD36: {=SUMPRODUCT($K36:$AG36,TRANSPOSE(FD$5:FD$27))} -> 2000 | FE36: {=SUMPRODUCT($K36:$AG36,TRANSPOSE(FE$5:FE$27))} -> 2000 | FF36: {=SUMPRODUCT($K36:$AG36,TRANSPOSE(FF$5:FF$27))} -> 2000 | FG36: {=SUMPRODUCT($K36:$AG36,TRANSPOSE(FG$5:FG$27))} -> 2000 | FH36: {=SUMPRODUCT($K36:$AG36,TRANSPOSE(FH$5:FH$27))} -> 2000 | ... GN36: {=SUMPRODUCT($K36:$AG36,TRANSPOSE(GN$5:GN$27))} -> 0 | IV36: coilcraft | IW36: =C36 -> 0603CS-8N7XGLW | IX36: =AL36 -> COILCRAFT INC. | IY36: =AP36 -> 0.072 | IZ36: =AQ36 -> USD | JA36: =_xlfn.XLOOKUP(IZ36,IZ$21:IZ$24,JA$21:JA$24,0) -> #NAME? | JB36: =IY36*JA36 -> #NAME? | JC36: =AJ36 -> 2000 | JD36: 6000 | JF36: =MAX(JD36,CEILING(#REF!+JE36,JC36)) -> #REF! | JG36: =JF36*JB36 -> #REF! | JH36: =JF36-#REF! -> #REF! | JI36: =JH36*JB36 -> #REF! | JJ36: 45523 | JK36: Sagi | JL36: Ordered | JM36: Y | JN36: RNSE | JO36: {=SUMPRODUCT(#REF!,TRANSPOSE(JO$19:JO$22))} -> #REF! | JP36: {=SUMPRODUCT(#REF!,TRANSPOSE(JP$19:JP$22))} -> #REF! | JQ36: {=SUMPRODUCT(#REF!,TRANSPOSE(JQ$19:JQ$22))} -> #REF! | JR36: {=SUMPRODUCT(#REF!,TRANSPOSE(JR$19:JR$22))} -> #REF! | JS36: {=SUMPRODUCT(#REF!,TRANSPOSE(JS$19:JS$22))} -> #REF! | JT36: {=SUMPRODUCT(#REF!,TRANSPOSE(JT$19:JT$22))} -> #REF! | JU36: {=SUMPRODUCT(#REF!,TRANSPOSE(JU$19:JU$22))} -> #REF! | JV36: {=SUMPRODUCT(#REF!,TRANSPOSE(JV$19:JV$22))} -> #REF! | ... KA36: {=SUMPRODUCT(#REF!,TRANSPOSE(KA$19:KA$22))} -> #REF! | KC36: =CEILING(JO36,$JC36) -> #REF! | KD36: =CEILING(SUM($JO36:JP36)-SUM($KC36:KC36),$JC36) -> #REF! | KE36: =CEILING(SUM($JO36:JQ36)-SUM($KC36:KD36),$JC36) -> #REF! | KF36: =CEILING(SUM($JO36:JR36)-SUM($KC36:KE36),$JC36) -> #REF! | KG36: =CEILING(SUM($JO36:JS36)-SUM($KC36:KF36),$JC36) -> #REF! | KH36: =CEILING(SUM($JO36:JT36)-SUM($KC36:KG36),$JC36) -> #REF! | KI36: =CEILING(SUM($JO36:JU36)-SUM($KC36:KH36),$JC36) -> #REF! | KJ36: =CEILING(SUM($JO36:JV36)-SUM($KC36:KI36),$JC36) -> #REF! | KK36: =CEILING(SUM($JO36:JW36)-SUM($KC36:KJ36),$JC36) -> #REF! | ... KM36: =CEILING(SUM($JO36:JY36)-SUM($KC36:KL36),$JC36) -> #REF! | KN36: =JF36-SUM(KC36:KM36) -> #REF! | KO36: =JF36-SUM(KC36:KN36) -> #REF! | KQ36: =KC36*$JB36 -> #REF! | KR36: =KD36*$JB36 -> #REF! | KS36: =KE36*$JB36 -> #REF! | KT36: =KF36*$JB36 -> #REF! | KU36: =KG36*$JB36 -> #REF! | KV36: =KH36*$JB36 -> #REF! | KW36: =KI36*$JB36 -> #REF! | KX36: =KJ36*$JB36 -> #REF! | ... LC36: =KO36*$JB36 -> #REF! | LD36: =SUM(KQ36:LC36) -> #REF! | LE36: 1 | LF36: =SUM(KC36:KO36) -> #REF! | LR36: =KO36 -> #REF! | LT36: =LF36*$JB36 -> #REF! | LU36: =LG36*$JB36 -> #NAME? | LV36: =LH36*$JB36 -> #NAME? | LW36: =LI36*$JB36 -> #NAME? | LX36: =LJ36*$JB36 -> #NAME? | LY36: =LK36*$JB36 -> #NAME? | LZ36: =LL36*$JB36 -> #NAME? | MA36: =LM36*$JB36 -> #NAME? | ... MF36: =LR36*$JB36 -> #REF! | MG36: =SUM(LT36:MF36) -> #REF! | MH36: LT01-007 | MI36: P0025 | MJ36: 45526 | MK36: Yes | ML36: Yes | MM36: Yes | MO36: Indonesia / Malaysia / Vietnam
