Workbook
Name ______DAT1: #REF!
Name ______DAT10: '[4]רכש 20 כרטיסים'!#REF!
Name ______DAT11: '[4]רכש 20 כרטיסים'!#REF!
Name ______DAT12: '[4]רכש 20 כרטיסים'!#REF!
Name ______DAT13: '[4]רכש 20 כרטיסים'!#REF!
Name ______DAT15: #REF!
Name ______DAT16: #REF!
Name ______DAT2: '[4]רכש 20 כרטיסים'!#REF!
Name ______DAT3: '[4]רכש 20 כרטיסים'!#REF!
Name ______DAT4: '[4]רכש 20 כרטיסים'!#REF!
Name ______DAT5: '[4]רכש 20 כרטיסים'!#REF!
Name ______DAT6: #REF!
Name ______DAT7: #REF!
Name ______DAT8: '[4]רכש 20 כרטיסים'!#REF!
Name ______DAT9: '[4]רכש 20 כרטיסים'!#REF!
Name ______USE2: #REF!
Name _____DAT1: #REF!
Name _____DAT10: '[4]רכש 20 כרטיסים'!#REF!
Name _____DAT11: '[4]רכש 20 כרטיסים'!#REF!
Name _____DAT12: '[4]רכש 20 כרטיסים'!#REF!
Name _____DAT13: '[4]רכש 20 כרטיסים'!#REF!
Name _____DAT14: '[4]רכש 20 כרטיסים'!#REF!
Name _____DAT15: #REF!
Name _____DAT16: #REF!
Name _____DAT2: '[4]רכש 20 כרטיסים'!#REF!
Name _____DAT3: '[4]רכש 20 כרטיסים'!#REF!
Name _____DAT4: '[4]רכש 20 כרטיסים'!#REF!
Name _____DAT5: '[4]רכש 20 כרטיסים'!#REF!
Name _____DAT6: #REF!
Name _____DAT7: #REF!
Name _____DAT8: '[4]רכש 20 כרטיסים'!#REF!
Name _____DAT9: '[4]רכש 20 כרטיסים'!#REF!
Name _____USE2: #REF!
Name ____DAT1: #REF!
Name ____DAT10: '[4]רכש 20 כרטיסים'!#REF!
Name ____DAT11: '[4]רכש 20 כרטיסים'!#REF!
Name ____DAT12: '[4]רכש 20 כרטיסים'!#REF!
Name ____DAT13: '[4]רכש 20 כרטיסים'!#REF!
Name ____DAT14: '[4]רכש 20 כרטיסים'!#REF!
Name ____DAT15: #REF!
Name ____DAT16: #REF!
Name ____DAT2: '[4]רכש 20 כרטיסים'!#REF!
Name ____DAT3: '[4]רכש 20 כרטיסים'!#REF!
Name ____DAT4: '[4]רכש 20 כרטיסים'!#REF!
Name ____DAT5: '[4]רכש 20 כרטיסים'!#REF!
Name ____DAT6: #REF!
Name ____DAT7: #REF!
Name ____DAT8: '[4]רכש 20 כרטיסים'!#REF!
Name ____DAT9: '[4]רכש 20 כרטיסים'!#REF!
Name ____USE2: #REF!
Name ___DAT1: #REF!
Name ___DAT10: '[4]רכש 20 כרטיסים'!#REF!
Name ___DAT11: '[4]רכש 20 כרטיסים'!#REF!
Name ___DAT12: '[4]רכש 20 כרטיסים'!#REF!
Name ___DAT13: '[4]רכש 20 כרטיסים'!#REF!
Name ___DAT14: '[4]רכש 20 כרטיסים'!#REF!
Name ___DAT15: #REF!
Name ___DAT16: #REF!
Name ___DAT2: '[4]רכש 20 כרטיסים'!#REF!
Name ___DAT3: '[4]רכש 20 כרטיסים'!#REF!

Sheet AVL
AI1: ETD | BC1: WORK PLAN | BY1: DEMAND
BC2: DRM F/ASSY | BD2: 0 | BE2: 1094T030-002 | BP2: 100 | BQ2: 150 | BR2: 250 | BS2: 220 | BT2: 200 | BU2: 150 | BV2: 240 | BW2: 240 | CI2: 100 | CJ2: 150 | CK2: 250 | CL2: 220 | CM2: 200 | CN2: 150 | CO2: 240 | CP2: 240
BC3: DRM F/ASSY | BD3: 1 | BE3: 1094T040-001 | BP3: 100 | BQ3: 150 | BR3: 250 | BS3: 220 | BT3: 200 | BU3: 150 | BV3: 240 | BW3: 240 | CI3: 100 | CJ3: 150 | CK3: 250 | CL3: 220 | CM3: 200 | CN3: 150 | CO3: 240 | CP3: 240
BC4: PS ASSY RX | BD4: 2 | BE4: 1094T050-002 | BO4: 100 | BP4: 150 | BQ4: 250 | BR4: 220 | BS4: 200 | BT4: 150 | BU4: 240 | BV4: 240 | CH4: 100 | CI4: 150 | CJ4: 250 | CK4: 220 | CL4: 200 | CM4: 150 | CN4: 240 | CO4: 240
BC5: RX ASSY | BD5: 3 | BE5: 1094T060-002 | BN5: 100 | BO5: 150 | BP5: 250 | BQ5: 220 | BR5: 200 | BS5: 150 | BT5: 240 | BU5: 240 | CG5: 100 | CH5: 150 | CI5: 250 | CJ5: 220 | CK5: 200 | CL5: 150 | CM5: 240 | CN5: 240
BC6: PC ASSY DRM CONTROLER NG 400 | BD6: 2 | BE6: 1094T037-001 | BN6: 100 | BO6: 150 | BP6: 250 | BQ6: 220 | BR6: 200 | BS6: 150 | BT6: 240 | BU6: 240 | CG6: 100 | CH6: 150 | CI6: 250 | CJ6: 220 | CK6: 200 | CL6: 150 | CM6: 240 | CN6: 240
BC7: DTRM F/ASSY | BD7: 0 | BE7: 1094N740-001 | BP7: 100 | BQ7: 150 | BR7: 250 | BS7: 200 | BT7: 200 | BU7: 200 | BV7: 300 | BW7: 260 | CI7: 100 | CJ7: 150 | CK7: 250 | CL7: 200 | CM7: 200 | CN7: 200 | CO7: 300 | CP7: 260
BC8: DTRM F/ASSY | BD8: 1 | BE8: 1094N750-003 | BP8: 100 | BQ8: 150 | BR8: 250 | BS8: 200 | BT8: 200 | BU8: 200 | BV8: 300 | BW8: 260 | CI8: 100 | CJ8: 150 | CK8: 250 | CL8: 200 | CM8: 200 | CN8: 200 | CO8: 300 | CP8: 260
BC9: POWER AMP ASSY | BD9: 2 | BE9: 1094N781-005 | BO9: 100 | BP9: 150 | BQ9: 250 | BR9: 200 | BS9: 200 | BT9: 200 | BU9: 300 | BV9: 260 | CH9: 100 | CI9: 150 | CJ9: 250 | CK9: 200 | CL9: 200 | CM9: 200 | CN9: 300 | CO9: 260
BC10: PC ASSY PA CR | BD10: 3 | BE10: 1094Y030-002 | BN10: 100 | BO10: 150 | BP10: 250 | BQ10: 200 | BR10: 200 | BS10: 200 | BT10: 300 | BU10: 260 | CG10: 100 | CH10: 150 | CI10: 250 | CJ10: 200 | CK10: 200 | CL10: 200 | CM10: 300 | CN10: 260
BC11: CAPASITORS CALIBRATION KIT | BD11: 4 | BE11: 1094Y038-001 | BN11: 100 | BO11: 150 | BP11: 250 | BQ11: 200 | BR11: 200 | BS11: 200 | BT11: 300 | BU11: 260 | CG11: 100 | CH11: 150 | CI11: 250 | CJ11: 200 | CK11: 200 | CL11: 200 | CM11: 300 | CN11: 260
BC12: BEND OF TRANSISTOR | BD12: 3 | BE12: 1094N754-001 | BN12: 100 | BO12: 150 | BP12: 250 | BQ12: 200 | BR12: 200 | BS12: 200 | BT12: 300 | BU12: 260 | CG12: 100 | CH12: 150 | CI12: 250 | CJ12: 200 | CK12: 200 | CL12: 200 | CM12: 300 | CN12: 260
H13: QTY | I13: 1550 | J13: 1550 | K13: 1550 | L13: 1550 | M13: 1550 | N13: 1660 | O13: 1660 | P13: 1660 | Q13: 1660 | R13: 1660 | S13: 1660 | T13: 1660 | U13: 1660 | V13: 1660 | BC13: EV CAP WITH BRACKET | BD13: 3 | BE13: 1093G277-001 | BN13: 100 | BO13: 150 | BP13: 250 | BQ13: 200 | BR13: 200 | BS13: 200 | BT13: 300 | BU13: 260 | CG13: 100 | CH13: 150 | CI13: 250 | CJ13: 200 | CK13: 200 | CL13: 200 | CM13: 300 | CN13: 260
A14: 34 | H14: DESC | I14: =VLOOKUP(I17,$B$18:$F$297,5,) -> DRM F/ASSY | J14: =VLOOKUP(J17,$B$18:$F$297,5,) -> DRM F/ASSY | K14: =VLOOKUP(K17,$B$18:$F$297,5,) -> PS ASSY RX | L14: =VLOOKUP(L17,$B$18:$F$297,5,) -> RX ASSY | M14: =VLOOKUP(M17,$B$18:$F$297,5,) -> PC ASSY DRM CONTROLER NG 400 | N14: =VLOOKUP(N17,$B$18:$F$297,5,) -> DTRM F/ASSY | O14: =VLOOKUP(O17,$B$18:$F$297,5,) -> DTRM F/ASSY | P14: =VLOOKUP(P17,$B$18:$F$297,5,) -> POWER AMP ASSY | ... V14: =VLOOKUP(V17,$B$18:$F$297,5,) -> PC ASSY CONTROLLER 400 | BC14: INSIDE COVER ASSY | BD14: 2 | BE14: 1093N746-001 | BO14: 100 | BP14: 150 | BQ14: 250 | BR14: 200 | BS14: 200 | BT14: 200 | BU14: 300 | BV14: 260 | CH14: 100 | CI14: 150 | CJ14: 250 | CK14: 200 | CL14: 200 | CM14: 200 | CN14: 300 | CO14: 260
A15: 1 | H15: COUNT | I15: =COUNTIF(I18:I293,">0") -> 3 | J15: =COUNTIF(J18:J293,">0") -> 32 | K15: =COUNTIF(K18:K293,">0") -> 13 | L15: =COUNTIF(L18:L293,">0") -> 47 | M15: =COUNTIF(M18:M293,">0") -> 97 | N15: =COUNTIF(N18:N293,">0") -> 4 | O15: =COUNTIF(O18:O293,">0") -> 34 | P15: =COUNTIF(P18:P293,">0") -> 30 | ... V15: =COUNTIF(V18:V293,">0") -> 98 | BC15: PC ASSY CONTROLLER 400 | BD15: 2 | BE15: 1094N790-003 | BO15: 100 | BP15: 150 | BQ15: 250 | BR15: 200 | BS15: 200 | BT15: 200 | BU15: 300 | BV15: 260 | CH15: 100 | CI15: 150 | CJ15: 250 | CK15: 200 | CL15: 200 | CM15: 200 | CN15: 300 | CO15: 260
H16: LEVEL | I16: =VLOOKUP(I17,'[1]הזנת נתונים'!$K$2:$L$50,2,) -> 0 | J16: =VLOOKUP(J17,'[1]הזנת נתונים'!$K$2:$L$50,2,) -> 1 | K16: =VLOOKUP(K17,'[1]הזנת נתונים'!$K$2:$L$50,2,) -> 2 | L16: =VLOOKUP(L17,'[1]הזנת נתונים'!$K$2:$L$50,2,) -> 3 | M16: =VLOOKUP(M17,'[1]הזנת נתונים'!$K$2:$L$50,2,) -> 2 | N16: =VLOOKUP(N17,'[1]הזנת נתונים'!$K$2:$L$50,2,) -> 0 | O16: =VLOOKUP(O17,'[1]הזנת נתונים'!$K$2:$L$50,2,) -> 1 | P16: =VLOOKUP(P17,'[1]הזנת נתונים'!$K$2:$L$50,2,) -> 2 | ... V16: =VLOOKUP(V17,'[1]הזנת נתונים'!$K$2:$L$50,2,) -> 2
A17: # | B17: PN_ID | C17: REV | D17: CATALOG | E17: FFF | F17: DESCRIPTION | G17: UOM | H17: ORIG_QTY | I17: 1094T030-002 | J17: 1094T040-001 | K17: 1094T050-002 | L17: 1094T060-002 | M17: 1094T037-001 | N17: 1094N740-001 | O17: 1094N750-003 | P17: 1094N781-005 | Q17: 1094Y030-002 | R17: 1094Y038-001 | S17: 1094N754-001 | T17: 1093G277-001 | U17: 1093N746-001 | V17: 1094N790-003 | W17: SUM | X17: TOTAL PRICE | Y17: manufacturer | Z17: MPQ | AA17: MOQ | AB17: TOATL QUANTITY TO BUY | AC17: TARGET PRICE | AD17: SUPPLIER | AE17: POC SUPPLIER | AF17: SUPPLIER MAIL | AG17: SUPPLIER PHONE | AH17: NOTES | AI17: 46174 | AJ17: 46204 | AK17: 46235 | AL17: 46266 | AM17: 46296 | AN17: 46327 | AO17: 46357 | AP17: 46388 | AQ17: 46419 | AR17: 46447 | AS17: 46478 | AT17: 46508 | AU17: 46539 | AV17: 46569 | AW17: 46600 | AX17: 46631 | AY17: 46661 | AZ17: 46692 | BA17: 46722 | BB17: STOCK | BC17: DESC | BD17: LEVEL | BE17: PN | BF17: 46174 | BG17: 46204 | BH17: 46235 | BI17: 46266 | BJ17: 46296 | BK17: 46327 | BL17: 46357 | BM17: 46388 | BN17: 46419 | BO17: 46447 | BP17: 46478 | BQ17: 46508 | BR17: 46539 | BS17: 46569 | BT17: 46600 | BU17: 46631 | BV17: 46661 | BW17: 46692 | BX17: 46722 | BY17: 46174 | BZ17: 46204 | CA17: 46235 | CB17: 46266 | CC17: 46296 | CD17: 46327 | CE17: 46357 | CF17: 46388 | CG17: 46419 | CH17: 46447 | CI17: 46478 | CJ17: 46508 | CK17: 46539 | CL17: 46569 | CM17: 46600 | CN17: 46631 | CO17: 46661 | CP17: 46692 | CQ17: 46722
A18: 1 | B18: 1094N740-001 | C18: D | D18: 409547026 | F18: DTRM F/ASSY | G18: EA | H18: 1 | I18: 0 | J18: 0 | K18: 0 | L18: 0 | M18: 0 | N18: 1 | O18: 0 | P18: 0 | Q18: 0 | R18: 0 | S18: 0 | T18: 0 | U18: 0 | V18: 0 | W18: =SUMPRODUCT(I18:V18,$I$13:$V$13) -> 1660 | X18: =SUM(I18:V18)*AC18 -> 0 | Y18: ASSY | Z18: ASSY | AA18: ASSY | AB18: ASSY | AC18: 0 | AD18: ASSY | AE18: ASSY | AF18: ASSY | AG18: ASSY | BG18: =SUM($BB18,$AI18:AI18)-SUM($BY18:BZ18) -> 0 | BH18: =SUM($BB18,$AI18:AJ18)-SUM($BY18:CA18) -> 0 | BI18: =SUM($BB18,$AI18:AK18)-SUM($BY18:CB18) -> 0 | BJ18: =SUM($BB18,$AI18:AL18)-SUM($BY18:CC18) -> 0 | BK18: =SUM($BB18,$AI18:AM18)-SUM($BY18:CD18) -> 0 | BL18: =SUM($BB18,$AI18:AN18)-SUM($BY18:CE18) -> 0 | BM18: =SUM($BB18,$AI18:AO18)-SUM($BY18:CF18) -> 0 | BN18: =SUM($BB18,$AI18:AP18)-SUM($BY18:CG18) -> 0 | ... BX18: =SUM($BB18,$AI18:AZ18)-SUM($BY18:CQ18) -> -1660 | BY18: {=SUMPRODUCT(TRANSPOSE(BY$2:BY$15),$I18:$V18)} -> 0 | BZ18: {=SUMPRODUCT(TRANSPOSE(BZ$2:BZ$15),$I18:$V18)} -> 0 | CA18: {=SUMPRODUCT(TRANSPOSE(CA$2:CA$15),$I18:$V18)} -> 0 | CB18: {=SUMPRODUCT(TRANSPOSE(CB$2:CB$15),$I18:$V18)} -> 0 | CC18: {=SUMPRODUCT(TRANSPOSE(CC$2:CC$15),$I18:$V18)} -> 0 | CD18: {=SUMPRODUCT(TRANSPOSE(CD$2:CD$15),$I18:$V18)} -> 0 | CE18: {=SUMPRODUCT(TRANSPOSE(CE$2:CE$15),$I18:$V18)} -> 0 | CF18: {=SUMPRODUCT(TRANSPOSE(CF$2:CF$15),$I18:$V18)} -> 0 | ... CQ18: {=SUMPRODUCT(TRANSPOSE(CQ$2:CQ$15),$I18:$V18)} -> 0
A19: 2 | B19: 1094T030-002 | C19: B | D19: 421530806 | F19: DRM F/ASSY | G19: EA | H19: 1 | I19: 1 | J19: 0 | K19: 0 | L19: 0 | M19: 0 | N19: 0 | O19: 0 | P19: 0 | Q19: 0 | R19: 0 | S19: 0 | T19: 0 | U19: 0 | V19: 0 | W19: =SUMPRODUCT(I19:V19,$I$13:$V$13) -> 1550 | X19: =SUM(I19:V19)*AC19 -> 0 | Y19: ASSY | Z19: ASSY | AA19: ASSY | AB19: ASSY | AC19: 0 | AD19: ASSY | AE19: ASSY | AF19: ASSY | AG19: ASSY | BG19: =SUM($BB19,$AI19:AI19)-SUM($BY19:BZ19) -> 0 | BH19: =SUM($BB19,$AI19:AJ19)-SUM($BY19:CA19) -> 0 | BI19: =SUM($BB19,$AI19:AK19)-SUM($BY19:CB19) -> 0 | BJ19: =SUM($BB19,$AI19:AL19)-SUM($BY19:CC19) -> 0 | BK19: =SUM($BB19,$AI19:AM19)-SUM($BY19:CD19) -> 0 | BL19: =SUM($BB19,$AI19:AN19)-SUM($BY19:CE19) -> 0 | BM19: =SUM($BB19,$AI19:AO19)-SUM($BY19:CF19) -> 0 | BN19: =SUM($BB19,$AI19:AP19)-SUM($BY19:CG19) -> 0 | ... BX19: =SUM($BB19,$AI19:AZ19)-SUM($BY19:CQ19) -> -1550 | BY19: {=SUMPRODUCT(TRANSPOSE(BY$2:BY$15),$I19:$V19)} -> 0 | BZ19: {=SUMPRODUCT(TRANSPOSE(BZ$2:BZ$15),$I19:$V19)} -> 0 | CA19: {=SUMPRODUCT(TRANSPOSE(CA$2:CA$15),$I19:$V19)} -> 0 | CB19: {=SUMPRODUCT(TRANSPOSE(CB$2:CB$15),$I19:$V19)} -> 0 | CC19: {=SUMPRODUCT(TRANSPOSE(CC$2:CC$15),$I19:$V19)} -> 0 | CD19: {=SUMPRODUCT(TRANSPOSE(CD$2:CD$15),$I19:$V19)} -> 0 | CE19: {=SUMPRODUCT(TRANSPOSE(CE$2:CE$15),$I19:$V19)} -> 0 | CF19: {=SUMPRODUCT(TRANSPOSE(CF$2:CF$15),$I19:$V19)} -> 0 | ... CQ19: {=SUMPRODUCT(TRANSPOSE(CQ$2:CQ$15),$I19:$V19)} -> 0
A20: 60 | B20: 1094T060-002 | C20: D | D20: 411235298 | F20: RX ASSY | G20: EA | H20: 1 | I20: 0 | J20: 0 | K20: 1 | L20: 0 | M20: 0 | N20: 0 | O20: 0 | P20: 0 | Q20: 0 | R20: 0 | S20: 0 | T20: 0 | U20: 0 | V20: 0 | W20: =SUMPRODUCT(I20:V20,$I$13:$V$13) -> 1550 | X20: =SUM(I20:V20)*AC20 -> 0 | Y20: ASSY | Z20: ASSY | AA20: ASSY | AB20: ASSY | AC20: 0 | AD20: ASSY | AE20: ASSY | AF20: ASSY | AG20: ASSY | BG20: =SUM($BB20,$AI20:AI20)-SUM($BY20:BZ20) -> 0 | BH20: =SUM($BB20,$AI20:AJ20)-SUM($BY20:CA20) -> 0 | BI20: =SUM($BB20,$AI20:AK20)-SUM($BY20:CB20) -> 0 | BJ20: =SUM($BB20,$AI20:AL20)-SUM($BY20:CC20) -> 0 | BK20: =SUM($BB20,$AI20:AM20)-SUM($BY20:CD20) -> 0 | BL20: =SUM($BB20,$AI20:AN20)-SUM($BY20:CE20) -> 0 | BM20: =SUM($BB20,$AI20:AO20)-SUM($BY20:CF20) -> 0 | BN20: =SUM($BB20,$AI20:AP20)-SUM($BY20:CG20) -> 0 | ... BX20: =SUM($BB20,$AI20:AZ20)-SUM($BY20:CQ20) -> -1550 | BY20: {=SUMPRODUCT(TRANSPOSE(BY$2:BY$15),$I20:$V20)} -> 0 | BZ20: {=SUMPRODUCT(TRANSPOSE(BZ$2:BZ$15),$I20:$V20)} -> 0 | CA20: {=SUMPRODUCT(TRANSPOSE(CA$2:CA$15),$I20:$V20)} -> 0 | CB20: {=SUMPRODUCT(TRANSPOSE(CB$2:CB$15),$I20:$V20)} -> 0 | CC20: {=SUMPRODUCT(TRANSPOSE(CC$2:CC$15),$I20:$V20)} -> 0 | CD20: {=SUMPRODUCT(TRANSPOSE(CD$2:CD$15),$I20:$V20)} -> 0 | CE20: {=SUMPRODUCT(TRANSPOSE(CE$2:CE$15),$I20:$V20)} -> 0 | CF20: {=SUMPRODUCT(TRANSPOSE(CF$2:CF$15),$I20:$V20)} -> 0 | ... CQ20: {=SUMPRODUCT(TRANSPOSE(CQ$2:CQ$15),$I20:$V20)} -> 0
A21: 66 | B21: 1097U145-001 | C21: A | D21: 412594024 | F21: S-BAND MFC F/ASSY | G21: EA | H21: 2 | I21: 0 | J21: 0 | K21: 0 | L21: 0 | M21: 0 | N21: 0 | O21: 0 | P21: 0 | Q21: 2 | R21: 0 | S21: 0 | T21: 0 | U21: 0 | V21: 0 | W21: =SUMPRODUCT(I21:V21,$I$13:$V$13) -> 3320 | X21: =SUM(I21:V21)*AC21 -> 1258 | Y21: =VLOOKUP(D21,[1]PARTS!$A$1:$G$65536,7,0) | AA21: 3280 | AB21: 3208 | AC21: =620+9 -> 629 | BG21: =SUM($BB21,$AI21:AI21)-SUM($BY21:BZ21) -> 0 | BH21: =SUM($BB21,$AI21:AJ21)-SUM($BY21:CA21) -> 0 | BI21: =SUM($BB21,$AI21:AK21)-SUM($BY21:CB21) -> 0 | BJ21: =SUM($BB21,$AI21:AL21)-SUM($BY21:CC21) -> 0 | BK21: =SUM($BB21,$AI21:AM21)-SUM($BY21:CD21) -> 0 | BL21: =SUM($BB21,$AI21:AN21)-SUM($BY21:CE21) -> 0 | BM21: =SUM($BB21,$AI21:AO21)-SUM($BY21:CF21) -> 0 | BN21: =SUM($BB21,$AI21:AP21)-SUM($BY21:CG21) -> -200 | ... BX21: =SUM($BB21,$AI21:AZ21)-SUM($BY21:CQ21) -> -3320 | BY21: {=SUMPRODUCT(TRANSPOSE(BY$2:BY$15),$I21:$V21)} -> 0 | BZ21: {=SUMPRODUCT(TRANSPOSE(BZ$2:BZ$15),$I21:$V21)} -> 0 | CA21: {=SUMPRODUCT(TRANSPOSE(CA$2:CA$15),$I21:$V21)} -> 0 | CB21: {=SUMPRODUCT(TRANSPOSE(CB$2:CB$15),$I21:$V21)} -> 0 | CC21: {=SUMPRODUCT(TRANSPOSE(CC$2:CC$15),$I21:$V21)} -> 0 | CD21: {=SUMPRODUCT(TRANSPOSE(CD$2:CD$15),$I21:$V21)} -> 0 | CE21: {=SUMPRODUCT(TRANSPOSE(CE$2:CE$15),$I21:$V21)} -> 0 | CF21: {=SUMPRODUCT(TRANSPOSE(CF$2:CF$15),$I21:$V21)} -> 0 | ... CQ21: {=SUMPRODUCT(TRANSPOSE(CQ$2:CQ$15),$I21:$V21)} -> 0
A22: 68 | B22: 1097U147-001 | C22: A | D22: 412594026 | F22: S-BAND DPS LS F/ASSY | G22: EA | H22: 2 | I22: 0 | J22: 0 | K22: 0 | L22: 0 | M22: 0 | N22: 0 | O22: 0 | P22: 0 | Q22: 2 | R22: 0 | S22: 0 | T22: 0 | U22: 0 | V22: 0 | W22: =SUMPRODUCT(I22:V22,$I$13:$V$13) -> 3320 | X22: =SUM(I22:V22)*AC22 -> 1180 | Y22: =VLOOKUP(D22,[1]PARTS!$A$1:$G$65536,7,0) | AA22: 3280 | AB22: 3208 | AC22: =551.59+38.41 -> 590 | BG22: =SUM($BB22,$AI22:AI22)-SUM($BY22:BZ22) -> 0 | BH22: =SUM($BB22,$AI22:AJ22)-SUM($BY22:CA22) -> 0 | BI22: =SUM($BB22,$AI22:AK22)-SUM($BY22:CB22) -> 0 | BJ22: =SUM($BB22,$AI22:AL22)-SUM($BY22:CC22) -> 0 | BK22: =SUM($BB22,$AI22:AM22)-SUM($BY22:CD22) -> 0 | BL22: =SUM($BB22,$AI22:AN22)-SUM($BY22:CE22) -> 0 | BM22: =SUM($BB22,$AI22:AO22)-SUM($BY22:CF22) -> 0 | BN22: =SUM($BB22,$AI22:AP22)-SUM($BY22:CG22) -> -200 | ... BX22: =SUM($BB22,$AI22:AZ22)-SUM($BY22:CQ22) -> -3320 | BY22: {=SUMPRODUCT(TRANSPOSE(BY$2:BY$15),$I22:$V22)} -> 0 | BZ22: {=SUMPRODUCT(TRANSPOSE(BZ$2:BZ$15),$I22:$V22)} -> 0 | CA22: {=SUMPRODUCT(TRANSPOSE(CA$2:CA$15),$I22:$V22)} -> 0 | CB22: {=SUMPRODUCT(TRANSPOSE(CB$2:CB$15),$I22:$V22)} -> 0 | CC22: {=SUMPRODUCT(TRANSPOSE(CC$2:CC$15),$I22:$V22)} -> 0 | CD22: {=SUMPRODUCT(TRANSPOSE(CD$2:CD$15),$I22:$V22)} -> 0 | CE22: {=SUMPRODUCT(TRANSPOSE(CE$2:CE$15),$I22:$V22)} -> 0 | CF22: {=SUMPRODUCT(TRANSPOSE(CF$2:CF$15),$I22:$V22)} -> 0 | ... CQ22: {=SUMPRODUCT(TRANSPOSE(CQ$2:CQ$15),$I22:$V22)} -> 0
A23: 47 | B23: 1094N782-003 | C23: A | D23: 414338971 | F23: PC BLANK MASTER DWG. MMR-40 Z5 | G23: EA | H23: 1 | I23: 0 | J23: 0 | K23: 0 | L23: 0 | M23: 0 | N23: 0 | O23: 0 | P23: 0 | Q23: 1 | R23: 0 | S23: 0 | T23: 0 | U23: 0 | V23: 0 | W23: =SUMPRODUCT(I23:V23,$I$13:$V$13) -> 1660 | X23: =SUM(I23:V23)*AC23 -> 200 | Y23: =VLOOKUP(D23,[1]PARTS!$A$1:$G$65536,7,0) | Z23: 1 | AA23: 1640 | AB23: =CEILING(W23,Z23) -> 1660 | AC23: 200 | AD23: SANMINA/MICROPACK/CPC | AE23: SANMINA/MICROPACK/CPC | AF23: SANMINA/MICROPACK/CPC | AG23: SANMINA/MICROPACK/CPC | AH23: SANMINA/MICROPACK/CPC | BG23: =SUM($BB23,$AI23:AI23)-SUM($BY23:BZ23) -> 0 | BH23: =SUM($BB23,$AI23:AJ23)-SUM($BY23:CA23) -> 0 | BI23: =SUM($BB23,$AI23:AK23)-SUM($BY23:CB23) -> 0 | BJ23: =SUM($BB23,$AI23:AL23)-SUM($BY23:CC23) -> 0 | BK23: =SUM($BB23,$AI23:AM23)-SUM($BY23:CD23) -> 0 | BL23: =SUM($BB23,$AI23:AN23)-SUM($BY23:CE23) -> 0 | BM23: =SUM($BB23,$AI23:AO23)-SUM($BY23:CF23) -> 0 | BN23: =SUM($BB23,$AI23:AP23)-SUM($BY23:CG23) -> -100 | ... BX23: =SUM($BB23,$AI23:AZ23)-SUM($BY23:CQ23) -> -1660 | BY23: {=SUMPRODUCT(TRANSPOSE(BY$2:BY$15),$I23:$V23)} -> 0 | BZ23: {=SUMPRODUCT(TRANSPOSE(BZ$2:BZ$15),$I23:$V23)} -> 0 | CA23: {=SUMPRODUCT(TRANSPOSE(CA$2:CA$15),$I23:$V23)} -> 0 | CB23: {=SUMPRODUCT(TRANSPOSE(CB$2:CB$15),$I23:$V23)} -> 0 | CC23: {=SUMPRODUCT(TRANSPOSE(CC$2:CC$15),$I23:$V23)} -> 0 | CD23: {=SUMPRODUCT(TRANSPOSE(CD$2:CD$15),$I23:$V23)} -> 0 | CE23: {=SUMPRODUCT(TRANSPOSE(CE$2:CE$15),$I23:$V23)} -> 0 | CF23: {=SUMPRODUCT(TRANSPOSE(CF$2:CF$15),$I23:$V23)} -> 0 | ... CQ23: {=SUMPRODUCT(TRANSPOSE(CQ$2:CQ$15),$I23:$V23)} -> 0
A24: 137 | B24: CGHV35400F1 | C24: BUY1 | D24: 402803473 | F24: AMPL RF GAN 400W 2.9-3.5GHZ 11DB SMT | G24: EA | H24: 2 | I24: 0 | J24: 0 | K24: 0 | L24: 0 | M24: 0 | N24: 0 | O24: 0 | P24: 2 | Q24: 0 | R24: 0 | S24: 0 | T24: 0 | U24: 0 | V24: 0 | W24: =SUMPRODUCT(I24:V24,$I$13:$V$13) -> 3320 | X24: =SUM(I24:V24)*AC24 -> 428 | Y24: =VLOOKUP(D24,[1]PARTS!$A$1:$G$65536,7,0) -> Wolfspeed | Z24: 50 | AA24: 3280 | AB24: =CEILING(W24,Z24) -> 3350 | AC24: 214 | AD24: MACOM | AE24: DANIELA PINHAS | AF24: Daniela@nisko.com | AG24: 972-54-2007783 | BG24: =SUM($BB24,$AI24:AI24)-SUM($BY24:BZ24) -> 0 | BH24: =SUM($BB24,$AI24:AJ24)-SUM($BY24:CA24) -> 0 | BI24: =SUM($BB24,$AI24:AK24)-SUM($BY24:CB24) -> 0 | BJ24: =SUM($BB24,$AI24:AL24)-SUM($BY24:CC24) -> 0 | BK24: =SUM($BB24,$AI24:AM24)-SUM($BY24:CD24) -> 0 | BL24: =SUM($BB24,$AI24:AN24)-SUM($BY24:CE24) -> 0 | BM24: =SUM($BB24,$AI24:AO24)-SUM($BY24:CF24) -> 0 | BN24: =SUM($BB24,$AI24:AP24)-SUM($BY24:CG24) -> 0 | ... BX24: =SUM($BB24,$AI24:AZ24)-SUM($BY24:CQ24) -> -3320 | BY24: {=SUMPRODUCT(TRANSPOSE(BY$2:BY$15),$I24:$V24)} -> 0 | BZ24: {=SUMPRODUCT(TRANSPOSE(BZ$2:BZ$15),$I24:$V24)} -> 0 | CA24: {=SUMPRODUCT(TRANSPOSE(CA$2:CA$15),$I24:$V24)} -> 0 | CB24: {=SUMPRODUCT(TRANSPOSE(CB$2:CB$15),$I24:$V24)} -> 0 | CC24: {=SUMPRODUCT(TRANSPOSE(CC$2:CC$15),$I24:$V24)} -> 0 | CD24: {=SUMPRODUCT(TRANSPOSE(CD$2:CD$15),$I24:$V24)} -> 0 | CE24: {=SUMPRODUCT(TRANSPOSE(CE$2:CE$15),$I24:$V24)} -> 0 | CF24: {=SUMPRODUCT(TRANSPOSE(CF$2:CF$15),$I24:$V24)} -> 0 | ... CQ24: {=SUMPRODUCT(TRANSPOSE(CQ$2:CQ$15),$I24:$V24)} -> 0
A25: 70 | B25: 1097U217-001 | C25: A | D25: 412779594 | F25: F/ASSY LNA DCA | G25: EA | H25: 2 | I25: 0 | J25: 0 | K25: 0 | L25: 2 | M25: 0 | N25: 0 | O25: 0 | P25: 0 | Q25: 0 | R25: 0 | S25: 0 | T25: 0 | U25: 0 | V25: 0 | W25: =SUMPRODUCT(I25:V25,$I$13:$V$13) -> 3100 | X25: =SUM(I25:V25)*AC25 -> 654 | Y25: =VLOOKUP(D25,[1]PARTS!$A$1:$G$65536,7,0) | AA25: 3060 | AB25: 3060 | AC25: =310+17 -> 327 | BG25: =SUM($BB25,$AI25:AI25)-SUM($BY25:BZ25) -> 0 | BH25: =SUM($BB25,$AI25:AJ25)-SUM($BY25:CA25) -> 0 | BI25: =SUM($BB25,$AI25:AK25)-SUM($BY25:CB25) -> 0 | BJ25: =SUM($BB25,$AI25:AL25)-SUM($BY25:CC25) -> 0 | BK25: =SUM($BB25,$AI25:AM25)-SUM($BY25:CD25) -> 0 | BL25: =SUM($BB25,$AI25:AN25)-SUM($BY25:CE25) -> 0 | BM25: =SUM($BB25,$AI25:AO25)-SUM($BY25:CF25) -> 0 | BN25: =SUM($BB25,$AI25:AP25)-SUM($BY25:CG25) -> -200 | ... BX25: =SUM($BB25,$AI25:AZ25)-SUM($BY25:CQ25) -> -3100 | BY25: {=SUMPRODUCT(TRANSPOSE(BY$2:BY$15),$I25:$V25)} -> 0 | BZ25: {=SUMPRODUCT(TRANSPOSE(BZ$2:BZ$15),$I25:$V25)} -> 0 | CA25: {=SUMPRODUCT(TRANSPOSE(CA$2:CA$15),$I25:$V25)} -> 0 | CB25: {=SUMPRODUCT(TRANSPOSE(CB$2:CB$15),$I25:$V25)} -> 0 | CC25: {=SUMPRODUCT(TRANSPOSE(CC$2:CC$15),$I25:$V25)} -> 0 | CD25: {=SUMPRODUCT(TRANSPOSE(CD$2:CD$15),$I25:$V25)} -> 0 | CE25: {=SUMPRODUCT(TRANSPOSE(CE$2:CE$15),$I25:$V25)} -> 0 | CF25: {=SUMPRODUCT(TRANSPOSE(CF$2:CF$15),$I25:$V25)} -> 0 | ... CQ25: {=SUMPRODUCT(TRANSPOSE(CQ$2:CQ$15),$I25:$V25)} -> 0
A26: 72 | B26: 1097U219-001 | C26: A | D26: 412779595 | F26: F/ASSY PH/SH | G26: EA | H26: 2 | I26: 0 | J26: 0 | K26: 0 | L26: 2 | M26: 0 | N26: 0 | O26: 0 | P26: 0 | Q26: 0 | R26: 0 | S26: 0 | T26: 0 | U26: 0 | V26: 0 | W26: =SUMPRODUCT(I26:V26,$I$13:$V$13) -> 3100 | X26: =SUM(I26:V26)*AC26 -> 626 | Y26: =VLOOKUP(D26,[1]PARTS!$A$1:$G$65536,7,0) | AA26: 3060 | AB26: 3060 | AC26: =296+17 -> 313 | BG26: =SUM($BB26,$AI26:AI26)-SUM($BY26:BZ26) -> 0 | BH26: =SUM($BB26,$AI26:AJ26)-SUM($BY26:CA26) -> 0 | BI26: =SUM($BB26,$AI26:AK26)-SUM($BY26:CB26) -> 0 | BJ26: =SUM($BB26,$AI26:AL26)-SUM($BY26:CC26) -> 0 | BK26: =SUM($BB26,$AI26:AM26)-SUM($BY26:CD26) -> 0 | BL26: =SUM($BB26,$AI26:AN26)-SUM($BY26:CE26) -> 0 | BM26: =SUM($BB26,$AI26:AO26)-SUM($BY26:CF26) -> 0 | BN26: =SUM($BB26,$AI26:AP26)-SUM($BY26:CG26) -> -200 | ... BX26: =SUM($BB26,$AI26:AZ26)-SUM($BY26:CQ26) -> -3100 | BY26: {=SUMPRODUCT(TRANSPOSE(BY$2:BY$15),$I26:$V26)} -> 0 | BZ26: {=SUMPRODUCT(TRANSPOSE(BZ$2:BZ$15),$I26:$V26)} -> 0 | CA26: {=SUMPRODUCT(TRANSPOSE(CA$2:CA$15),$I26:$V26)} -> 0 | CB26: {=SUMPRODUCT(TRANSPOSE(CB$2:CB$15),$I26:$V26)} -> 0 | CC26: {=SUMPRODUCT(TRANSPOSE(CC$2:CC$15),$I26:$V26)} -> 0 | CD26: {=SUMPRODUCT(TRANSPOSE(CD$2:CD$15),$I26:$V26)} -> 0 | CE26: {=SUMPRODUCT(TRANSPOSE(CE$2:CE$15),$I26:$V26)} -> 0 | CF26: {=SUMPRODUCT(TRANSPOSE(CF$2:CF$15),$I26:$V26)} -> 0 | ... CQ26: {=SUMPRODUCT(TRANSPOSE(CQ$2:CQ$15),$I26:$V26)} -> 0
A27: 225 | B27: IHQ2063942 | C27: BUY1 | D27: 411346444 | F27: HYBRID CAPACITOR 63V 9400UF | G27: EA | H27: 1 | I27: 0 | J27: 0 | K27: 0 | L27: 0 | M27: 0 | N27: 0 | O27: 0 | P27: 0 | Q27: 0 | R27: 0 | S27: 0 | T27: 1 | U27: 0 | V27: 0 | W27: =SUMPRODUCT(I27:V27,$I$13:$V$13) -> 1660 | X27: =SUM(I27:V27)*AC27 -> 298 | Y27: =VLOOKUP(D27,[1]PARTS!$A$1:$G$65536,7,0) -> EVANS CAPACITOR COMPANY | Z27: 1 | AA27: 1640 | AB27: =CEILING(W27,Z27) -> 1660 | AC27: =VLOOKUP(D27,[2]pareto!$D$12:$AX$306,47,0) -> 298 | AD27: EVANS | AE27: Haim Koren | AF27: Haimk@militram.com | AG27: 972-547709603 | BG27: =SUM($BB27,$AI27:AI27)-SUM($BY27:BZ27) -> 0 | BH27: =SUM($BB27,$AI27:AJ27)-SUM($BY27:CA27) -> 0 | BI27: =SUM($BB27,$AI27:AK27)-SUM($BY27:CB27) -> 0 | BJ27: =SUM($BB27,$AI27:AL27)-SUM($BY27:CC27) -> 0 | BK27: =SUM($BB27,$AI27:AM27)-SUM($BY27:CD27) -> 0 | BL27: =SUM($BB27,$AI27:AN27)-SUM($BY27:CE27) -> 0 | BM27: =SUM($BB27,$AI27:AO27)-SUM($BY27:CF27) -> 0 | BN27: =SUM($BB27,$AI27:AP27)-SUM($BY27:CG27) -> -100 | ... BX27: =SUM($BB27,$AI27:AZ27)-SUM($BY27:CQ27) -> -1660 | BY27: {=SUMPRODUCT(TRANSPOSE(BY$2:BY$15),$I27:$V27)} -> 0 | BZ27: {=SUMPRODUCT(TRANSPOSE(BZ$2:BZ$15),$I27:$V27)} -> 0 | CA27: {=SUMPRODUCT(TRANSPOSE(CA$2:CA$15),$I27:$V27)} -> 0 | CB27: {=SUMPRODUCT(TRANSPOSE(CB$2:CB$15),$I27:$V27)} -> 0 | CC27: {=SUMPRODUCT(TRANSPOSE(CC$2:CC$15),$I27:$V27)} -> 0 | CD27: {=SUMPRODUCT(TRANSPOSE(CD$2:CD$15),$I27:$V27)} -> 0 | CE27: {=SUMPRODUCT(TRANSPOSE(CE$2:CE$15),$I27:$V27)} -> 0 | CF27: {=SUMPRODUCT(TRANSPOSE(CF$2:CF$15),$I27:$V27)} -> 0 | ... CQ27: {=SUMPRODUCT(TRANSPOSE(CQ$2:CQ$15),$I27:$V27)} -> 0
A28: 61 | B28: 1094T062-002 | C28: -1 | D28: 411235297 | F28: PC BLANK MASTER DRAWING MMR-41 Z2 | G28: EA | H28: 1 | I28: 0 | J28: 0 | K28: 0 | L28: 1 | M28: 0 | N28: 0 | O28: 0 | P28: 0 | Q28: 0 | R28: 0 | S28: 0 | T28: 0 | U28: 0 | V28: 0 | W28: =SUMPRODUCT(I28:V28,$I$13:$V$13) -> 1550 | X28: =SUM(I28:V28)*AC28 -> 68 | Y28: =VLOOKUP(D28,[1]PARTS!$A$1:$G$65536,7,0) | Z28: 1 | AA28: 1530 | AB28: =CEILING(W28,Z28) -> 1550 | AC28: 68 | AD28: SANMINA/MICROPACK/CPC | AE28: SANMINA/MICROPACK/CPC | AF28: SANMINA/MICROPACK/CPC | AG28: SANMINA/MICROPACK/CPC | AH28: SANMINA/MICROPACK/CPC | BG28: =SUM($BB28,$AI28:AI28)-SUM($BY28:BZ28) -> 0 | BH28: =SUM($BB28,$AI28:AJ28)-SUM($BY28:CA28) -> 0 | BI28: =SUM($BB28,$AI28:AK28)-SUM($BY28:CB28) -> 0 | BJ28: =SUM($BB28,$AI28:AL28)-SUM($BY28:CC28) -> 0 | BK28: =SUM($BB28,$AI28:AM28)-SUM($BY28:CD28) -> 0 | BL28: =SUM($BB28,$AI28:AN28)-SUM($BY28:CE28) -> 0 | BM28: =SUM($BB28,$AI28:AO28)-SUM($BY28:CF28) -> 0 | BN28: =SUM($BB28,$AI28:AP28)-SUM($BY28:CG28) -> -100 | ... BX28: =SUM($BB28,$AI28:AZ28)-SUM($BY28:CQ28) -> -1550 | BY28: {=SUMPRODUCT(TRANSPOSE(BY$2:BY$15),$I28:$V28)} -> 0 | BZ28: {=SUMPRODUCT(TRANSPOSE(BZ$2:BZ$15),$I28:$V28)} -> 0 | CA28: {=SUMPRODUCT(TRANSPOSE(CA$2:CA$15),$I28:$V28)} -> 0 | CB28: {=SUMPRODUCT(TRANSPOSE(CB$2:CB$15),$I28:$V28)} -> 0 | CC28: {=SUMPRODUCT(TRANSPOSE(CC$2:CC$15),$I28:$V28)} -> 0 | CD28: {=SUMPRODUCT(TRANSPOSE(CD$2:CD$15),$I28:$V28)} -> 0 | CE28: {=SUMPRODUCT(TRANSPOSE(CE$2:CE$15),$I28:$V28)} -> 0 | CF28: {=SUMPRODUCT(TRANSPOSE(CF$2:CF$15),$I28:$V28)} -> 0 | ... CQ28: {=SUMPRODUCT(TRANSPOSE(CQ$2:CQ$15),$I28:$V28)} -> 0
A29: 35 | B29: 1094N761-002 | C29: - | D29: 411160563 | F29: BOX MACHINING | G29: EA | H29: 2 | I29: 0 | J29: 0 | K29: 1 | L29: 0 | M29: 0 | N29: 0 | O29: 0 | P29: 1 | Q29: 0 | R29: 0 | S29: 0 | T29: 0 | U29: 0 | V29: 0 | W29: =SUMPRODUCT(I29:V29,$I$13:$V$13) -> 3210 | X29: =SUM(I29:V29)*AC29 -> 94.3 | Y29: =VLOOKUP(D29,[1]PARTS!$A$1:$G$65536,7,0) | Z29: 1 | AA29: 3170 | AB29: =CEILING(W29,Z29) -> 3210 | AC29: =VLOOKUP(D29,[2]pareto!$D$12:$AX$306,47,0) -> 47.15 | AD29: WAVE MECHANICS | AE29: WAVE MECHANICS | AF29: =VLOOKUP(D29,[2]pareto!$D$11:$BD$306,52,0) -> tnp@wave-mechanics.com | AG29: =VLOOKUP(D29,[2]pareto!$D$11:$BD$306,51) -> #REF! | BG29: =SUM($BB29,$AI29:AI29)-SUM($BY29:BZ29) -> 0 | BH29: =SUM($BB29,$AI29:AJ29)-SUM($BY29:CA29) -> 0 | BI29: =SUM($BB29,$AI29:AK29)-SUM($BY29:CB29) -> 0 | BJ29: =SUM($BB29,$AI29:AL29)-SUM($BY29:CC29) -> 0 | BK29: =SUM($BB29,$AI29:AM29)-SUM($BY29:CD29) -> 0 | BL29: =SUM($BB29,$AI29:AN29)-SUM($BY29:CE29) -> 0 | BM29: =SUM($BB29,$AI29:AO29)-SUM($BY29:CF29) -> 0 | BN29: =SUM($BB29,$AI29:AP29)-SUM($BY29:CG29) -> 0 | ... BX29: =SUM($BB29,$AI29:AZ29)-SUM($BY29:CQ29) -> -3210 | BY29: {=SUMPRODUCT(TRANSPOSE(BY$2:BY$15),$I29:$V29)} -> 0 | BZ29: {=SUMPRODUCT(TRANSPOSE(BZ$2:BZ$15),$I29:$V29)} -> 0 | CA29: {=SUMPRODUCT(TRANSPOSE(CA$2:CA$15),$I29:$V29)} -> 0 | CB29: {=SUMPRODUCT(TRANSPOSE(CB$2:CB$15),$I29:$V29)} -> 0 | CC29: {=SUMPRODUCT(TRANSPOSE(CC$2:CC$15),$I29:$V29)} -> 0 | CD29: {=SUMPRODUCT(TRANSPOSE(CD$2:CD$15),$I29:$V29)} -> 0 | CE29: {=SUMPRODUCT(TRANSPOSE(CE$2:CE$15),$I29:$V29)} -> 0 | CF29: {=SUMPRODUCT(TRANSPOSE(CF$2:CF$15),$I29:$V29)} -> 0 | ... CQ29: {=SUMPRODUCT(TRANSPOSE(CQ$2:CQ$15),$I29:$V29)} -> 0
A30: 46 | B30: 1094N781-005 | C30: A03 | D30: 405170958 | F30: POWER AMP ASSY | G30: EA | H30: 1 | I30: 0 | J30: 0 | K30: 0 | L30: 0 | M30: 0 | N30: 0 | O30: 1 | P30: 0 | Q30: 0 | R30: 0 | S30: 0 | T30: 0 | U30: 0 | V30: 0 | W30: =SUMPRODUCT(I30:V30,$I$13:$V$13) -> 1660 | X30: =SUM(I30:V30)*AC30 -> 0 | Y30: ASSY | Z30: ASSY | AA30: ASSY | AB30: ASSY | AC30: 0 | AD30: ASSY | AE30: ASSY | AF30: ASSY | AG30: ASSY | BG30: =SUM($BB30,$AI30:AI30)-SUM($BY30:BZ30) -> 0 | BH30: =SUM($BB30,$AI30:AJ30)-SUM($BY30:CA30) -> 0 | BI30: =SUM($BB30,$AI30:AK30)-SUM($BY30:CB30) -> 0 | BJ30: =SUM($BB30,$AI30:AL30)-SUM($BY30:CC30) -> 0 | BK30: =SUM($BB30,$AI30:AM30)-SUM($BY30:CD30) -> 0 | BL30: =SUM($BB30,$AI30:AN30)-SUM($BY30:CE30) -> 0 | BM30: =SUM($BB30,$AI30:AO30)-SUM($BY30:CF30) -> 0 | BN30: =SUM($BB30,$AI30:AP30)-SUM($BY30:CG30) -> 0 | ... BX30: =SUM($BB30,$AI30:AZ30)-SUM($BY30:CQ30) -> -1660 | BY30: {=SUMPRODUCT(TRANSPOSE(BY$2:BY$15),$I30:$V30)} -> 0 | BZ30: {=SUMPRODUCT(TRANSPOSE(BZ$2:BZ$15),$I30:$V30)} -> 0 | CA30: {=SUMPRODUCT(TRANSPOSE(CA$2:CA$15),$I30:$V30)} -> 0 | CB30: {=SUMPRODUCT(TRANSPOSE(CB$2:CB$15),$I30:$V30)} -> 0 | CC30: {=SUMPRODUCT(TRANSPOSE(CC$2:CC$15),$I30:$V30)} -> 0 | CD30: {=SUMPRODUCT(TRANSPOSE(CD$2:CD$15),$I30:$V30)} -> 0 | CE30: {=SUMPRODUCT(TRANSPOSE(CE$2:CE$15),$I30:$V30)} -> 0 | CF30: {=SUMPRODUCT(TRANSPOSE(CF$2:CF$15),$I30:$V30)} -> 0 | ... CQ30: {=SUMPRODUCT(TRANSPOSE(CQ$2:CQ$15),$I30:$V30)} -> 0
A31: 22 | B31: 1093N721-001 | C31: - | D31: 417083200 | F31: COVER | G31: EA | H31: 2 | I31: 0 | J31: 1 | K31: 0 | L31: 0 | M31: 0 | N31: 0 | O31: 1 | P31: 0 | Q31: 0 | R31: 0 | S31: 0 | T31: 0 | U31: 0 | V31: 0 | W31: =SUMPRODUCT(I31:V31,$I$13:$V$13) -> 3210 | X31: =SUM(I31:V31)*AC31 -> 75.9 | Y31: =VLOOKUP(D31,[1]PARTS!$A$1:$G$65536,7,0) | Z31: 1 | AA31: 3170 | AB31: =CEILING(W31,Z31) -> 3210 | AC31: =VLOOKUP(D31,[2]pareto!$D$12:$AX$306,47,0) -> 37.95 | AD31: WAVE MECHANICS | AE31: WAVE MECHANICS | AF31: =VLOOKUP(D31,[2]pareto!$D$11:$BD$306,52,0) -> tnp@wave-mechanics.com | AG31: =VLOOKUP(D31,[2]pareto!$D$11:$BD$306,51) -> #REF! | BG31: =SUM($BB31,$AI31:AI31)-SUM($BY31:BZ31) -> 0 | BH31: =SUM($BB31,$AI31:AJ31)-SUM($BY31:CA31) -> 0 | BI31: =SUM($BB31,$AI31:AK31)-SUM($BY31:CB31) -> 0 | BJ31: =SUM($BB31,$AI31:AL31)-SUM($BY31:CC31) -> 0 | BK31: =SUM($BB31,$AI31:AM31)-SUM($BY31:CD31) -> 0 | BL31: =SUM($BB31,$AI31:AN31)-SUM($BY31:CE31) -> 0 | BM31: =SUM($BB31,$AI31:AO31)-SUM($BY31:CF31) -> 0 | BN31: =SUM($BB31,$AI31:AP31)-SUM($BY31:CG31) -> 0 | ... BX31: =SUM($BB31,$AI31:AZ31)-SUM($BY31:CQ31) -> -3210 | BY31: {=SUMPRODUCT(TRANSPOSE(BY$2:BY$15),$I31:$V31)} -> 0 | BZ31: {=SUMPRODUCT(TRANSPOSE(BZ$2:BZ$15),$I31:$V31)} -> 0 | CA31: {=SUMPRODUCT(TRANSPOSE(CA$2:CA$15),$I31:$V31)} -> 0 | CB31: {=SUMPRODUCT(TRANSPOSE(CB$2:CB$15),$I31:$V31)} -> 0 | CC31: {=SUMPRODUCT(TRANSPOSE(CC$2:CC$15),$I31:$V31)} -> 0 | CD31: {=SUMPRODUCT(TRANSPOSE(CD$2:CD$15),$I31:$V31)} -> 0 | CE31: {=SUMPRODUCT(TRANSPOSE(CE$2:CE$15),$I31:$V31)} -> 0 | CF31: {=SUMPRODUCT(TRANSPOSE(CF$2:CF$15),$I31:$V31)} -> 0 | ... CQ31: {=SUMPRODUCT(TRANSPOSE(CQ$2:CQ$15),$I31:$V31)} -> 0
A32: 64 | B32: 1094Y030-002 | C32: -1 | D32: 418707643 | F32: PC ASSY PA CR | G32: EA | H32: 1 | I32: 0 | J32: 0 | K32: 0 | L32: 0 | M32: 0 | N32: 0 | O32: 0 | P32: 1 | Q32: 0 | R32: 0 | S32: 0 | T32: 0 | U32: 0 | V32: 0 | W32: =SUMPRODUCT(I32:V32,$I$13:$V$13) -> 1660 | X32: =SUM(I32:V32)*AC32 -> 0 | Y32: ASSY | Z32: ASSY | AA32: ASSY | AB32: ASSY | AC32: 0 | AD32: ASSY | AE32: ASSY | AF32: ASSY | AG32: ASSY | BG32: =SUM($BB32,$AI32:AI32)-SUM($BY32:BZ32) -> 0 | BH32: =SUM($BB32,$AI32:AJ32)-SUM($BY32:CA32) -> 0 | BI32: =SUM($BB32,$AI32:AK32)-SUM($BY32:CB32) -> 0 | BJ32: =SUM($BB32,$AI32:AL32)-SUM($BY32:CC32) -> 0 | BK32: =SUM($BB32,$AI32:AM32)-SUM($BY32:CD32) -> 0 | BL32: =SUM($BB32,$AI32:AN32)-SUM($BY32:CE32) -> 0 | BM32: =SUM($BB32,$AI32:AO32)-SUM($BY32:CF32) -> 0 | BN32: =SUM($BB32,$AI32:AP32)-SUM($BY32:CG32) -> 0 | ... BX32: =SUM($BB32,$AI32:AZ32)-SUM($BY32:CQ32) -> -1660 | BY32: {=SUMPRODUCT(TRANSPOSE(BY$2:BY$15),$I32:$V32)} -> 0 | BZ32: {=SUMPRODUCT(TRANSPOSE(BZ$2:BZ$15),$I32:$V32)} -> 0 | CA32: {=SUMPRODUCT(TRANSPOSE(CA$2:CA$15),$I32:$V32)} -> 0 | CB32: {=SUMPRODUCT(TRANSPOSE(CB$2:CB$15),$I32:$V32)} -> 0 | CC32: {=SUMPRODUCT(TRANSPOSE(CC$2:CC$15),$I32:$V32)} -> 0 | CD32: {=SUMPRODUCT(TRANSPOSE(CD$2:CD$15),$I32:$V32)} -> 0 | CE32: {=SUMPRODUCT(TRANSPOSE(CE$2:CE$15),$I32:$V32)} -> 0 | CF32: {=SUMPRODUCT(TRANSPOSE(CF$2:CF$15),$I32:$V32)} -> 0 | ... CQ32: {=SUMPRODUCT(TRANSPOSE(CQ$2:CQ$15),$I32:$V32)} -> 0
A33: 308 | B33: TGL2927-SM | C33: BUY1 | D33: 409604724 | F33: VPIN LIMITER 200W 2-4GHZ | G33: EA | H33: 4 | I33: 0 | J33: 0 | K33: 0 | L33: 2 | M33: 0 | N33: 0 | O33: 0 | P33: 0 | Q33: 2 | R33: 0 | S33: 0 | T33: 0 | U33: 0 | V33: 0 | W33: =SUMPRODUCT(I33:V33,$I$13:$V$13) -> 6420 | X33: =SUM(I33:V33)*AC33 -> 64 | Y33: =VLOOKUP(D33,[1]PARTS!$A$1:$G$65536,7,0) -> QORVO US, INC | Z33: 500 | AA33: =VLOOKUP(D33,[2]pareto!$D$12:$AX$306,45,0) -> 5500 | AB33: =CEILING(W33,Z33) -> 6500 | AC33: =VLOOKUP(D33,[2]pareto!$D$12:$AX$306,47,0) -> 16 | AD33: QURVO | AE33: Shuli Ronin | AF33: =VLOOKUP(D33,[2]pareto!$D$11:$BD$306,52,0) -> shuli.ronin@qorvo.com | AG33: 972 - 9-7926694 | BG33: =SUM($BB33,$AI33:AI33)-SUM($BY33:BZ33) -> 0 | BH33: =SUM($BB33,$AI33:AJ33)-SUM($BY33:CA33) -> 0 | BI33: =SUM($BB33,$AI33:AK33)-SUM($BY33:CB33) -> 0 | BJ33: =SUM($BB33,$AI33:AL33)-SUM($BY33:CC33) -> 0 | BK33: =SUM($BB33,$AI33:AM33)-SUM($BY33:CD33) -> 0 | BL33: =SUM($BB33,$AI33:AN33)-SUM($BY33:CE33) -> 0 | BM33: =SUM($BB33,$AI33:AO33)-SUM($BY33:CF33) -> 0 | BN33: =SUM($BB33,$AI33:AP33)-SUM($BY33:CG33) -> -400 | ... BX33: =SUM($BB33,$AI33:AZ33)-SUM($BY33:CQ33) -> -6420 | BY33: {=SUMPRODUCT(TRANSPOSE(BY$2:BY$15),$I33:$V33)} -> 0 | BZ33: {=SUMPRODUCT(TRANSPOSE(BZ$2:BZ$15),$I33:$V33)} -> 0 | CA33: {=SUMPRODUCT(TRANSPOSE(CA$2:CA$15),$I33:$V33)} -> 0 | CB33: {=SUMPRODUCT(TRANSPOSE(CB$2:CB$15),$I33:$V33)} -> 0 | CC33: {=SUMPRODUCT(TRANSPOSE(CC$2:CC$15),$I33:$V33)} -> 0 | CD33: {=SUMPRODUCT(TRANSPOSE(CD$2:CD$15),$I33:$V33)} -> 0 | CE33: {=SUMPRODUCT(TRANSPOSE(CE$2:CE$15),$I33:$V33)} -> 0 | CF33: {=SUMPRODUCT(TRANSPOSE(CF$2:CF$15),$I33:$V33)} -> 0 | ... CQ33: {=SUMPRODUCT(TRANSPOSE(CQ$2:CQ$15),$I33:$V33)} -> 0
A34: 41 | B34: 1094N771-001 | C34: - | D34: 410773154 | F34: SPACER DIAM 4X2 | G34: EA | H34: 9 | I34: 0 | J34: 0 | K34: 5 | L34: 0 | M34: 0 | N34: 0 | O34: 0 | P34: 4 | Q34: 0 | R34: 0 | S34: 0 | T34: 0 | U34: 0 | V34: 0 | W34: =SUMPRODUCT(I34:V34,$I$13:$V$13) -> 14390 | X34: =SUM(I34:V34)*AC34 -> 4.59 | Y34: =VLOOKUP(D34,[1]PARTS!$A$1:$G$65536,7,0) | Z34: 1 | AA34: 14210 | AB34: =CEILING(W34,Z34) -> 14390 | AC34: =VLOOKUP(D34,[2]pareto!$D$12:$AX$306,47,0) -> 0.51 | AD34: WAVE MECHANICS | AE34: WAVE MECHANICS | AF34: =VLOOKUP(D34,[2]pareto!$D$11:$BD$306,52,0) -> tnp@wave-mechanics.com | AG34: =VLOOKUP(D34,[2]pareto!$D$11:$BD$306,51) -> #REF! | BG34: =SUM($BB34,$AI34:AI34)-SUM($BY34:BZ34) -> 0 | BH34: =SUM($BB34,$AI34:AJ34)-SUM($BY34:CA34) -> 0 | BI34: =SUM($BB34,$AI34:AK34)-SUM($BY34:CB34) -> 0 | BJ34: =SUM($BB34,$AI34:AL34)-SUM($BY34:CC34) -> 0 | BK34: =SUM($BB34,$AI34:AM34)-SUM($BY34:CD34) -> 0 | BL34: =SUM($BB34,$AI34:AN34)-SUM($BY34:CE34) -> 0 | BM34: =SUM($BB34,$AI34:AO34)-SUM($BY34:CF34) -> 0 | BN34: =SUM($BB34,$AI34:AP34)-SUM($BY34:CG34) -> 0 | ... BX34: =SUM($BB34,$AI34:AZ34)-SUM($BY34:CQ34) -> -14390 | BY34: {=SUMPRODUCT(TRANSPOSE(BY$2:BY$15),$I34:$V34)} -> 0 | BZ34: {=SUMPRODUCT(TRANSPOSE(BZ$2:BZ$15),$I34:$V34)} -> 0 | CA34: {=SUMPRODUCT(TRANSPOSE(CA$2:CA$15),$I34:$V34)} -> 0 | CB34: {=SUMPRODUCT(TRANSPOSE(CB$2:CB$15),$I34:$V34)} -> 0 | CC34: {=SUMPRODUCT(TRANSPOSE(CC$2:CC$15),$I34:$V34)} -> 0 | CD34: {=SUMPRODUCT(TRANSPOSE(CD$2:CD$15),$I34:$V34)} -> 0 | CE34: {=SUMPRODUCT(TRANSPOSE(CE$2:CE$15),$I34:$V34)} -> 0 | CF34: {=SUMPRODUCT(TRANSPOSE(CF$2:CF$15),$I34:$V34)} -> 0 | ... CQ34: {=SUMPRODUCT(TRANSPOSE(CQ$2:CQ$15),$I34:$V34)} -> 0
A35: 211 | B35: FM25V20A-DG | C35: BUY1 | D35: 405043942 | E35: =VLOOKUP(D35,FFF!$A$2:$B$674,2,) -> 405046714 | F35: IC 2MB SERIAL F-RAM MEMORY | G35: EA | H35: 4 | I35: 0 | J35: 0 | K35: 0 | L35: 0 | M35: 2 | N35: 0 | O35: 0 | P35: 0 | Q35: 0 | R35: 0 | S35: 0 | T35: 0 | U35: 0 | V35: 2 | W35: =SUMPRODUCT(I35:V35,$I$13:$V$13) -> 6420 | X35: =SUM(I35:V35)*AC35 -> 57.36 | Y35: =VLOOKUP(D35,[1]PARTS!$A$1:$G$65536,7,0) -> INFINEON TECHNOLOGIES AG | Z35: 74 | AA35: 6340 | AB35: 6660 | AC35: 14.34 | AD35: ARROW | AE35: ALON SAGIV | AF35: alon.sagiv@arrow.com | AG35: 972 537704117 | BG35: =SUM($BB35,$AI35:AI35)-SUM($BY35:BZ35) -> 0 | BH35: =SUM($BB35,$AI35:AJ35)-SUM($BY35:CA35) -> 0 | BI35: =SUM($BB35,$AI35:AK35)-SUM($BY35:CB35) -> 0 | BJ35: =SUM($BB35,$AI35:AL35)-SUM($BY35:CC35) -> 0 | BK35: =SUM($BB35,$AI35:AM35)-SUM($BY35:CD35) -> 0 | BL35: =SUM($BB35,$AI35:AN35)-SUM($BY35:CE35) -> 0 | BM35: =SUM($BB35,$AI35:AO35)-SUM($BY35:CF35) -> 0 | BN35: =SUM($BB35,$AI35:AP35)-SUM($BY35:CG35) -> -200 | ... BX35: =SUM($BB35,$AI35:AZ35)-SUM($BY35:CQ35) -> -6420 | BY35: {=SUMPRODUCT(TRANSPOSE(BY$2:BY$15),$I35:$V35)} -> 0 | BZ35: {=SUMPRODUCT(TRANSPOSE(BZ$2:BZ$15),$I35:$V35)} -> 0 | CA35: {=SUMPRODUCT(TRANSPOSE(CA$2:CA$15),$I35:$V35)} -> 0 | CB35: {=SUMPRODUCT(TRANSPOSE(CB$2:CB$15),$I35:$V35)} -> 0 | CC35: {=SUMPRODUCT(TRANSPOSE(CC$2:CC$15),$I35:$V35)} -> 0 | CD35: {=SUMPRODUCT(TRANSPOSE(CD$2:CD$15),$I35:$V35)} -> 0 | CE35: {=SUMPRODUCT(TRANSPOSE(CE$2:CE$15),$I35:$V35)} -> 0 | CF35: {=SUMPRODUCT(TRANSPOSE(CF$2:CF$15),$I35:$V35)} -> 0 | ... CQ35: {=SUMPRODUCT(TRANSPOSE(CQ$2:CQ$15),$I35:$V35)} -> 0
A36: 3 | B36: 000800-0826 | C36: BUY1 | D36: 400550300 | F36: CONN RECT PCB R/A PLUG 42 BLADES 3 ROWS, | G36: EA | H36: 2 | I36: 0 | J36: 0 | K36: 0 | L36: 0 | M36: 1 | N36: 0 | O36: 0 | P36: 0 | Q36: 0 | R36: 0 | S36: 0 | T36: 0 | U36: 0 | V36: 1 | W36: =SUMPRODUCT(I36:V36,$I$13:$V$13) -> 3210 | X36: =SUM(I36:V36)*AC36 -> 54 | Y36: =VLOOKUP(D36,[1]PARTS!$A$1:$G$65536,7,0) -> DCX-CHOL Entr. Inc | Z36: 1 | AA36: 3170 | AB36: =CEILING(W36,Z36) -> 3210 | AC36: =VLOOKUP(D36,[2]pareto!$D$12:$AX$306,47,0) -> 27 | AD36: Emet | AE36: Elad Zafrir | AF36: elad.zafrir@emet.co.il | AG36: 972 - 523326582 | BG36: =SUM($BB36,$AI36:AI36)-SUM($BY36:BZ36) -> 0 | BH36: =SUM($BB36,$AI36:AJ36)-SUM($BY36:CA36) -> 0 | BI36: =SUM($BB36,$AI36:AK36)-SUM($BY36:CB36) -> 0 | BJ36: =SUM($BB36,$AI36:AL36)-SUM($BY36:CC36) -> 0 | BK36: =SUM($BB36,$AI36:AM36)-SUM($BY36:CD36) -> 0 | BL36: =SUM($BB36,$AI36:AN36)-SUM($BY36:CE36) -> 0 | BM36: =SUM($BB36,$AI36:AO36)-SUM($BY36:CF36) -> 0 | BN36: =SUM($BB36,$AI36:AP36)-SUM($BY36:CG36) -> -100 | ... BX36: =SUM($BB36,$AI36:AZ36)-SUM($BY36:CQ36) -> -3210 | BY36: {=SUMPRODUCT(TRANSPOSE(BY$2:BY$15),$I36:$V36)} -> 0 | BZ36: {=SUMPRODUCT(TRANSPOSE(BZ$2:BZ$15),$I36:$V36)} -> 0 | CA36: {=SUMPRODUCT(TRANSPOSE(CA$2:CA$15),$I36:$V36)} -> 0 | CB36: {=SUMPRODUCT(TRANSPOSE(CB$2:CB$15),$I36:$V36)} -> 0 | CC36: {=SUMPRODUCT(TRANSPOSE(CC$2:CC$15),$I36:$V36)} -> 0 | CD36: {=SUMPRODUCT(TRANSPOSE(CD$2:CD$15),$I36:$V36)} -> 0 | CE36: {=SUMPRODUCT(TRANSPOSE(CE$2:CE$15),$I36:$V36)} -> 0 | CF36: {=SUMPRODUCT(TRANSPOSE(CF$2:CF$15),$I36:$V36)} -> 0 | ... CQ36: {=SUMPRODUCT(TRANSPOSE(CQ$2:CQ$15),$I36:$V36)} -> 0
A37: 62 | B37: LTM8049IY | C37: BUY1 | D37: 409704332 | F37: CONVERTER DC/DC 2.6-20VIN 2.5-24VOUT 1A | G37: EA | H37: 2 | I37: 0 | J37: 0 | K37: 0 | L37: 0 | M37: 1 | N37: 0 | O37: 0 | P37: 0 | Q37: 0 | R37: 0 | S37: 0 | T37: 0 | U37: 0 | V37: 1 | W37: =SUMPRODUCT(I37:V37,$I$13:$V$13) -> 3210 | X37: =SUM(I37:V37)*AC37 -> 0 | Y37: =VLOOKUP(D37,[1]PARTS!$A$1:$G$65536,7,0) -> #N/A | Z37: 1 | AA37: 3170 | AB37: 3170 | BG37: =SUM($BB37,$AI37:AI37)-SUM($BY37:BZ37) -> 0 | BH37: =SUM($BB37,$AI37:AJ37)-SUM($BY37:CA37) -> 0 | BI37: =SUM($BB37,$AI37:AK37)-SUM($BY37:CB37) -> 0 | BJ37: =SUM($BB37,$AI37:AL37)-SUM($BY37:CC37) -> 0 | BK37: =SUM($BB37,$AI37:AM37)-SUM($BY37:CD37) -> 0 | BL37: =SUM($BB37,$AI37:AN37)-SUM($BY37:CE37) -> 0 | BM37: =SUM($BB37,$AI37:AO37)-SUM($BY37:CF37) -> 0 | BN37: =SUM($BB37,$AI37:AP37)-SUM($BY37:CG37) -> -100 | ... BX37: =SUM($BB37,$AI37:AZ37)-SUM($BY37:CQ37) -> -3210 | BY37: {=SUMPRODUCT(TRANSPOSE(BY$2:BY$15),$I37:$V37)} -> 0 | BZ37: {=SUMPRODUCT(TRANSPOSE(BZ$2:BZ$15),$I37:$V37)} -> 0 | CA37: {=SUMPRODUCT(TRANSPOSE(CA$2:CA$15),$I37:$V37)} -> 0 | CB37: {=SUMPRODUCT(TRANSPOSE(CB$2:CB$15),$I37:$V37)} -> 0 | CC37: {=SUMPRODUCT(TRANSPOSE(CC$2:CC$15),$I37:$V37)} -> 0 | CD37: {=SUMPRODUCT(TRANSPOSE(CD$2:CD$15),$I37:$V37)} -> 0 | CE37: {=SUMPRODUCT(TRANSPOSE(CE$2:CE$15),$I37:$V37)} -> 0 | CF37: {=SUMPRODUCT(TRANSPOSE(CF$2:CF$15),$I37:$V37)} -> 0 | ... CQ37: {=SUMPRODUCT(TRANSPOSE(CQ$2:CQ$15),$I37:$V37)} -> 0
A38: 92 | B38: 5CEFA4U19I7 | C38: BUY1 | D38: 421375236 | F38: IC CYCLONE V FPGA | G38: EA | H38: 2 | I38: 0 | J38: 0 | K38: 0 | L38: 0 | M38: 1 | N38: 0 | O38: 0 | P38: 0 | Q38: 0 | R38: 0 | S38: 0 | T38: 0 | U38: 0 | V38: 1 | W38: =SUMPRODUCT(I38:V38,$I$13:$V$13) -> 3210 | X38: =SUM(I38:V38)*AC38 -> 50.6 | Y38: =VLOOKUP(D38,[1]PARTS!$A$1:$G$65536,7,0) -> Intel Prgrammable SolutionsGroup(AL | Z38: 240 | AA38: 3170 | AB38: =CEILING(W38,Z38) -> 3360 | AC38: =VLOOKUP(D38,[2]pareto!$D$12:$AX$306,47,0) -> 25.3 | AD38: ALTERA | AE38: SHLOMI BIGI | AF38: =VLOOKUP(D38,[2]pareto!$D$11:$BD$306,52,0) -> Shlomi.bigi@easx.co.il | AG38: 972 - 505252790 | BG38: =SUM($BB38,$AI38:AI38)-SUM($BY38:BZ38) -> 0 | BH38: =SUM($BB38,$AI38:AJ38)-SUM($BY38:CA38) -> 0 | BI38: =SUM($BB38,$AI38:AK38)-SUM($BY38:CB38) -> 0 | BJ38: =SUM($BB38,$AI38:AL38)-SUM($BY38:CC38) -> 0 | BK38: =SUM($BB38,$AI38:AM38)-SUM($BY38:CD38) -> 0 | BL38: =SUM($BB38,$AI38:AN38)-SUM($BY38:CE38) -> 0 | BM38: =SUM($BB38,$AI38:AO38)-SUM($BY38:CF38) -> 0 | BN38: =SUM($BB38,$AI38:AP38)-SUM($BY38:CG38) -> -100 | ... BX38: =SUM($BB38,$AI38:AZ38)-SUM($BY38:CQ38) -> -3210 | BY38: {=SUMPRODUCT(TRANSPOSE(BY$2:BY$15),$I38:$V38)} -> 0 | BZ38: {=SUMPRODUCT(TRANSPOSE(BZ$2:BZ$15),$I38:$V38)} -> 0 | CA38: {=SUMPRODUCT(TRANSPOSE(CA$2:CA$15),$I38:$V38)} -> 0 | CB38: {=SUMPRODUCT(TRANSPOSE(CB$2:CB$15),$I38:$V38)} -> 0 | CC38: {=SUMPRODUCT(TRANSPOSE(CC$2:CC$15),$I38:$V38)} -> 0 | CD38: {=SUMPRODUCT(TRANSPOSE(CD$2:CD$15),$I38:$V38)} -> 0 | CE38: {=SUMPRODUCT(TRANSPOSE(CE$2:CE$15),$I38:$V38)} -> 0 | CF38: {=SUMPRODUCT(TRANSPOSE(CF$2:CF$15),$I38:$V38)} -> 0 | ... CQ38: {=SUMPRODUCT(TRANSPOSE(CQ$2:CQ$15),$I38:$V38)} -> 0
A39: 43 | B39: 1094N773-003 | C39: -1 | D39: 417679932 | F39: INSIDE COVER | G39: EA | H39: 2 | I39: 0 | J39: 1 | K39: 0 | L39: 0 | M39: 0 | N39: 0 | O39: 0 | P39: 0 | Q39: 0 | R39: 0 | S39: 0 | T39: 0 | U39: 1 | V39: 0 | W39: =SUMPRODUCT(I39:V39,$I$13:$V$13) -> 3210 | X39: =SUM(I39:V39)*AC39 -> 49.2 | Y39: =VLOOKUP(D39,[1]PARTS!$A$1:$G$65536,7,0) | Z39: 1 | AA39: 3170 | AB39: =CEILING(W39,Z39) -> 3210 | AC39: =VLOOKUP(D39,[2]pareto!$D$12:$AX$306,47,0) -> 24.6 | AD39: WAVE MECHANICS | AE39: WAVE MECHANICS | AF39: =VLOOKUP(D39,[2]pareto!$D$11:$BD$306,52,0) -> tnp@wave-mechanics.com | AG39: =VLOOKUP(D39,[2]pareto!$D$11:$BD$306,51) -> #REF! | BG39: =SUM($BB39,$AI39:AI39)-SUM($BY39:BZ39) -> 0 | BH39: =SUM($BB39,$AI39:AJ39)-SUM($BY39:CA39) -> 0 | BI39: =SUM($BB39,$AI39:AK39)-SUM($BY39:CB39) -> 0 | BJ39: =SUM($BB39,$AI39:AL39)-SUM($BY39:CC39) -> 0 | BK39: =SUM($BB39,$AI39:AM39)-SUM($BY39:CD39) -> 0 | BL39: =SUM($BB39,$AI39:AN39)-SUM($BY39:CE39) -> 0 | BM39: =SUM($BB39,$AI39:AO39)-SUM($BY39:CF39) -> 0 | BN39: =SUM($BB39,$AI39:AP39)-SUM($BY39:CG39) -> 0 | ... BX39: =SUM($BB39,$AI39:AZ39)-SUM($BY39:CQ39) -> -3210 | BY39: {=SUMPRODUCT(TRANSPOSE(BY$2:BY$15),$I39:$V39)} -> 0 | BZ39: {=SUMPRODUCT(TRANSPOSE(BZ$2:BZ$15),$I39:$V39)} -> 0 | CA39: {=SUMPRODUCT(TRANSPOSE(CA$2:CA$15),$I39:$V39)} -> 0 | CB39: {=SUMPRODUCT(TRANSPOSE(CB$2:CB$15),$I39:$V39)} -> 0 | CC39: {=SUMPRODUCT(TRANSPOSE(CC$2:CC$15),$I39:$V39)} -> 0 | CD39: {=SUMPRODUCT(TRANSPOSE(CD$2:CD$15),$I39:$V39)} -> 0 | CE39: {=SUMPRODUCT(TRANSPOSE(CE$2:CE$15),$I39:$V39)} -> 0 | CF39: {=SUMPRODUCT(TRANSPOSE(CF$2:CF$15),$I39:$V39)} -> 0 | ... CQ39: {=SUMPRODUCT(TRANSPOSE(CQ$2:CQ$15),$I39:$V39)} -> 0
A40: 236 | B40: LT1764EQ#TRPBF | C40: BUY3 | D40: 401359639 | E40: =VLOOKUP(D40,FFF!$A$2:$B$674,2,) -> 400510825 | F40: IC VOL. REG. ADJ. T&R | G40: EA | H40: 8 | I40: 0 | J40: 0 | K40: 0 | L40: 0 | M40: 4 | N40: 0 | O40: 0 | P40: 0 | Q40: 0 | R40: 0 | S40: 0 | T40: 0 | U40: 0 | V40: 4 | W40: =SUMPRODUCT(I40:V40,$I$13:$V$13) -> 12840 | X40: =SUM(I40:V40)*AC40 -> 28.84 | Y40: =VLOOKUP(D40,[1]PARTS!$A$1:$G$65536,7,0) -> ANALOG DEVICES | Z40: 750 | AA40: =VLOOKUP(D40,[2]pareto!$D$12:$AX$306,45,0) -> 50 | AB40: =CEILING(W40,Z40) -> 13500 | AC40: =VLOOKUP(D40,[2]pareto!$D$12:$AX$306,47,0) -> 3.605 | AD40: Elbatech | AE40: Anat Eylon | AF40: anat@elbatech.co.il | AG40: 972 - 88516111 | BG40: =SUM($BB40,$AI40:AI40)-SUM($BY40:BZ40) -> 0 | BH40: =SUM($BB40,$AI40:AJ40)-SUM($BY40:CA40) -> 0 | BI40: =SUM($BB40,$AI40:AK40)-SUM($BY40:CB40) -> 0 | BJ40: =SUM($BB40,$AI40:AL40)-SUM($BY40:CC40) -> 0 | BK40: =SUM($BB40,$AI40:AM40)-SUM($BY40:CD40) -> 0 | BL40: =SUM($BB40,$AI40:AN40)-SUM($BY40:CE40) -> 0 | BM40: =SUM($BB40,$AI40:AO40)-SUM($BY40:CF40) -> 0 | BN40: =SUM($BB40,$AI40:AP40)-SUM($BY40:CG40) -> -400 | ... BX40: =SUM($BB40,$AI40:AZ40)-SUM($BY40:CQ40) -> -12840 | BY40: {=SUMPRODUCT(TRANSPOSE(BY$2:BY$15),$I40:$V40)} -> 0 | BZ40: {=SUMPRODUCT(TRANSPOSE(BZ$2:BZ$15),$I40:$V40)} -> 0 | CA40: {=SUMPRODUCT(TRANSPOSE(CA$2:CA$15),$I40:$V40)} -> 0 | CB40: {=SUMPRODUCT(TRANSPOSE(CB$2:CB$15),$I40:$V40)} -> 0 | CC40: {=SUMPRODUCT(TRANSPOSE(CC$2:CC$15),$I40:$V40)} -> 0 | CD40: {=SUMPRODUCT(TRANSPOSE(CD$2:CD$15),$I40:$V40)} -> 0 | CE40: {=SUMPRODUCT(TRANSPOSE(CE$2:CE$15),$I40:$V40)} -> 0 | CF40: {=SUMPRODUCT(TRANSPOSE(CF$2:CF$15),$I40:$V40)} -> 0 | ... CQ40: {=SUMPRODUCT(TRANSPOSE(CQ$2:CQ$15),$I40:$V40)} -> 0
...

Sheet FFF
A1: CN | B1: FFF | C1: DESC | D1: MPN | E1: PRIMARY
A2: 400263993 | B2: 400005121 | C2: CHIP RESIS 2KOHM 1% .063W T&R | D2: CRCW04022K00FKTD | E2: CRCW04022K00FKED
A3: 400658323 | B3: 400005121 | C3: CHIP RESIS 2 KOHM 1% PB-FREE T&R | D3: CRCW04022K00FKED | E3: V
A4: 411170089 | B4: 400005121 | C4: CHIP RESIS 2KOHM 1% .063W T&R | D4: CR0402-FX-2001GLF | E4: CRCW04022K00FKED
A5: 414865984 | B5: 400005121 | C5: CHIP RESIS 2KOHM 1% .0625W T&R | D5: RC0402FR-072KL | E5: CRCW04022K00FKED
A6: N62061551 | B6: 400005121 | C6: CHIP RESIS 2KOHM 1% .063WATT 1X0.5MM | D6: D101002K001%P0 | E6: CRCW04022K00FKED
A7: N62061791 | B7: 400005121 | C7: CHIP RESIS 2KOHM 1% .063WATT 1X0.5MM | D7: D10100002K1%P0 | E7: CRCW04022K00FKED
A8: N62079751 | B8: 400005121 | C8: CHIP RESIS 2KOHM 1% 0.063WATT 1X0.5M | D8: D101002001FP0 | E8: CRCW04022K00FKED
A9: N62080684 | B9: 400005121 | C9: CHIP RESIS 2KOHM 1% 0.063WATT 1X0.5M | D9: CRCW04022001FRT7 | E9: CRCW04022K00FKED
A10: 400908745 | B10: 400007534 | C10: CHIP RESIS 732 OHM 1% .063W T&R | D10: CRCW0402732RFKTD | E10: CRCW0402732RFKED
A11: 425994123 | B11: 400007534 | C11: CHIP RESIS 732 OHM 1% .063W T&R | D11: CRCW0402732RFKED | E11: V
A12: 400306768 | B12: 400095447 | C12: CHIP CAP 1UF 10% 25V X7R T&R | D12: C1206C105K3RALTM | E12: CL31B105KAHNNNE
A13: 400333655 | B13: 400095447 | C13: CHIP CAP 1UF 10% 25V X7R T&R | D13: C1206C105K3RALTU | E13: CL31B105KAHNNNE
A14: 400550612 | B14: 400095447 | C14: CHIP CAP 1UF 10% 25V X7R T&R | D14: C1206C105K3RACTM | E14: CL31B105KAHNNNE
A15: 400551283 | B15: 400095447 | C15: CHIP CAP 1UF 10% 25V X7R T&R | D15: C1206C105K3RACTU | E15: CL31B105KAHNNNE
A16: 400604068 | B16: 400095447 | C16: CHIP CAP 1UF 10% 25VOLT X7R T&R | D16: C1206C105K3RAL7025 | E16: CL31B105KAHNNNE
A17: 400607521 | B17: 400095447 | C17: CHIP CAP 1UF 10% 25V X7R T&R | D17: C1206C105K3RAL7800 | E17: CL31B105KAHNNNE
A18: 402020886 | B18: 400095447 | C18: CHIP CAP 1UF 10% 25V X7R T&R | D18: C1206C105K3RAC7025 | E18: CL31B105KAHNNNE
A19: 417983138 | B19: 400095447 | C19: CHIP CAP 1UF 10% 25V X7R T&R | D19: CL31B105KAHNNNE | E19: V
A20: N62169016 | B20: 400095447 | C20: CHIP CAP 1UF 10% 25VOLT 126X63 X7R N | D20: C1206C105K3RAC | E20: CL31B105KAHNNNE
A21: N62175468 | B21: 400095447 | C21: CHIP CAP 1UF +80-20% 25VOLT 125X63 Y | D21: C1206C105Z3VAC | E21: CL31B105KAHNNNE
A22: N62175682 | B22: 400095447 | C22: CHIP CAP 1UF 10% 25VOLT 126X63 X7R N | D22: C1206C105K3RAC/TR | E22: CL31B105KAHNNNE
A23: 400017449 | B23: 400095450 | C23: CHIP JUMPER 1X0.5MM T&R | D23: D101000R0P0 | E23: CRCW04020000Z0ED
A24: 400249752 | B24: 400095450 | C24: CHIP JUMPER T&R | D24: CRCW04020000ZSTD | E24: CRCW04020000Z0ED
A25: 400709578 | B25: 400095450 | C25: CHIP RESIS 0 OHM 0% .063W T&R | D25: CRCW04020000ZSED | E25: CRCW04020000Z0ED
A26: 401197118 | B26: 400095450 | C26: CHIP JUMPER T&R | D26: CRCW04020000Z0ED | E26: V
A27: 411170044 | B27: 400095450 | C27: CHIP JUMPER T&R | D27: CR0402-J/-000GLF | E27: CRCW04020000Z0ED
A28: N62067962 | B28: 400095450 | C28: CHIP RESIS 0 OHM 5% .063WATT 1.0X0.5 | D28: MCR01MZSJ000 | E28: CRCW04020000Z0ED
A29: N62079132 | B29: 400095450 | C29: CHIP RESIS 0 OHM 0% .063W T&R | D29: CRCW0402000ZZRT7 | E29: CRCW04020000Z0ED
A30: N62081245 | B30: 400095450 | C30: CHIP JUMPER .063WATT 1X0.5MM TAPE/R | D30: D10100000ZZP0 | E30: CRCW04020000Z0ED
A31: N62087572 | B31: 400095450 | C31: CHIP JUMPER 1X0.5MM TAPE/REEL | D31: D101000000ZP0 | E31: CRCW04020000Z0ED
A32: N62884978 | B32: 400095450 | C32: CHIP JUMPER 39X20 10000EA/RL | D32: CJ05-000-H | E32: CRCW04020000Z0ED
A33: N63031009 | B33: 400095450 | C33: CHIP JUMPER 1X0.5MM TAPE/REEL | D33: D10100000R1%P0 | E33: CRCW04020000Z0ED
A34: 400272334 | B34: 400274911 | C34: CHIP RESIS 53.6KOHM 1% .1W T&R | D34: CRCW060353K6FKTA | E34: CRCW060353K6FKEA
A35: 413012036 | B35: 400274911 | C35: CHIP RESIS 53.6KOHM 1% .1W T&R | D35: CRCW060353K6FKEA | E35: V
A36: N62051883 | B36: 400274911 | C36: CHIP RESIS 53.6KOHM 1% .1WATT 1.55X0 | D36: D1110053K61%P5 | E36: CRCW060353K6FKEA
A37: 400263980 | B37: 400275213 | C37: CHIP RESIS 100KOHM 1% .063WtT&R | D37: CRCW0402100KFKTD | E37: CRCW0402100KFKED
A38: 400656752 | B38: 400275213 | C38: CHIP RESIS 100 KOHM 1% T&R | D38: CRCW0402100KFKED | E38: V
A39: 411170045 | B39: 400275213 | C39: CHIP RESIS 100KOHM 1% .063WtT&R | D39: CR0402-FX-1003GLF | E39: CRCW0402100KFKED
A40: 414865977 | B40: 400275213 | C40: CHIP RESIS 100KOHM 1% .0625W T&R | D40: RC0402FR-07100KL | E40: CRCW0402100KFKED
...
